module,execution_time (sec),success,timestamp,error,error_short
cowidev.vax.batch.argentina,3.49,True,2022-11-14T07:00:14,,
cowidev.vax.batch.australia,,,2022-11-14T07:00:10,,
cowidev.vax.batch.austria,1.71,True,2022-11-14T07:00:12,,
cowidev.vax.batch.belgium,1.95,True,2022-11-14T07:00:12,,
cowidev.vax.batch.bolivia,2.28,True,2022-11-14T07:00:13,,
cowidev.vax.batch.canada,10.57,False,2022-11-14T15:18:43,"Traceback (most recent call last):
  File ""/home/lucas/repos/covid-19-data/scripts/src/cowidev/cmd/commons/get.py"", line 46, in run
    module.main()
  File ""/home/lucas/repos/covid-19-data/scripts/src/cowidev/vax/batch/canada.py"", line 284, in main
    Canada().export()
  File ""/home/lucas/repos/covid-19-data/scripts/src/cowidev/vax/batch/canada.py"", line 268, in export
    df, df_age, df_man = self.read(), self.read_age(), self.read_manufacturer()
  File ""/home/lucas/repos/covid-19-data/scripts/src/cowidev/vax/batch/canada.py"", line 99, in read_age
    check_known_columns(
  File ""/home/lucas/repos/covid-19-data/scripts/src/cowidev/utils/utils.py"", line 168, in check_known_columns
    raise Exception(f""Previous column(s) missing: {missing_cols}"")
Exception: Previous column(s) missing: {'Unnamed: 21', 'Unnamed: 22', 'Unnamed: 20', 'Unnamed: 19', 'Unnamed: 23', 'Unnamed: 18'}
","Previous column(s) missing: {'Unnamed: 21', 'Unnamed: 22', 'Unnamed: 20', 'Unnamed: 19', 'Unnamed: 23', 'Unnamed: 18'}"
cowidev.vax.batch.chile,0.76,True,2022-11-14T07:00:13,,
cowidev.vax.batch.czechia,3.63,True,2022-11-14T07:00:16,,
cowidev.vax.batch.denmark,4.06,True,2022-11-14T07:00:17,,
cowidev.vax.batch.ecdc,33.44,True,2022-11-14T15:18:04,,
cowidev.vax.batch.ecuador,1.91,True,2022-11-14T07:00:16,,
cowidev.vax.batch.estonia,0.67,True,2022-11-14T07:00:16,,
cowidev.vax.batch.france,0.56,True,2022-11-14T07:00:17,,
cowidev.vax.batch.germany,3.08,True,2022-11-14T07:00:20,,
cowidev.vax.batch.greece,2.85,True,2022-11-14T07:00:19,,
cowidev.vax.batch.hong_kong,7.7,True,2022-11-14T07:00:24,,
cowidev.vax.batch.indonesia,,,2022-11-14T07:00:17,,
cowidev.vax.batch.ireland,0.2,True,2022-11-14T07:00:17,,
cowidev.vax.batch.israel,5.72,True,2022-11-14T07:00:23,,
cowidev.vax.batch.italy,12.29,True,2022-11-14T07:00:32,,
cowidev.vax.batch.japan,28.57,True,2022-11-14T15:17:59,,
cowidev.vax.batch.jersey,0.89,True,2022-11-14T07:00:24,,
cowidev.vax.batch.latvia,25.85,True,2022-11-14T07:00:50,,
cowidev.vax.batch.lithuania,1.96,True,2022-11-14T07:00:26,,
cowidev.vax.batch.luxembourg,7.5,True,2022-11-14T07:00:32,,
cowidev.vax.batch.malaysia,2.02,True,2022-11-14T07:00:28,,
cowidev.vax.batch.malta,1.25,True,2022-11-14T07:00:30,,
cowidev.vax.batch.netherlands,,,2022-11-14T07:00:30,,
cowidev.vax.batch.new_zealand,7.91,True,2022-11-14T07:00:38,,
cowidev.vax.batch.norway,0.34,True,2022-11-14T07:00:32,,
cowidev.vax.batch.peru,3.99,True,2022-11-14T07:00:36,,
cowidev.vax.batch.portugal,,,2022-11-14T07:00:32,,
cowidev.vax.batch.romania,8.63,True,2022-11-14T07:00:41,,
cowidev.vax.batch.saudi_arabia,5.77,True,2022-11-14T07:00:42,,
cowidev.vax.batch.singapore,1.23,False,2022-11-14T15:18:44,"Traceback (most recent call last):
  File ""/home/lucas/repos/covid-19-data/scripts/src/cowidev/cmd/commons/get.py"", line 46, in run
    module.main()
  File ""/home/lucas/repos/covid-19-data/scripts/src/cowidev/vax/batch/singapore.py"", line 120, in main
    Singapore().export()
  File ""/home/lucas/repos/covid-19-data/scripts/src/cowidev/vax/batch/singapore.py"", line 115, in export
    df = self.read().pipe(self.pipeline)
  File ""/home/lucas/repos/covid-19-data/scripts/src/cowidev/vax/batch/singapore.py"", line 46, in read
    df_boosters = pd.read_csv(os.path.join(tf, ""progress-of-vaccine-booster-programme.csv""))
  File ""/home/lucas/repos/covid-19-data/venv/lib/python3.10/site-packages/pandas/util/_decorators.py"", line 311, in wrapper
    return func(*args, **kwargs)
  File ""/home/lucas/repos/covid-19-data/venv/lib/python3.10/site-packages/pandas/io/parsers/readers.py"", line 586, in read_csv
    return _read(filepath_or_buffer, kwds)
  File ""/home/lucas/repos/covid-19-data/venv/lib/python3.10/site-packages/pandas/io/parsers/readers.py"", line 482, in _read
    parser = TextFileReader(filepath_or_buffer, **kwds)
  File ""/home/lucas/repos/covid-19-data/venv/lib/python3.10/site-packages/pandas/io/parsers/readers.py"", line 811, in __init__
    self._engine = self._make_engine(self.engine)
  File ""/home/lucas/repos/covid-19-data/venv/lib/python3.10/site-packages/pandas/io/parsers/readers.py"", line 1040, in _make_engine
    return mapping[engine](self.f, **self.options)  # type: ignore[call-arg]
  File ""/home/lucas/repos/covid-19-data/venv/lib/python3.10/site-packages/pandas/io/parsers/c_parser_wrapper.py"", line 51, in __init__
    self._open_handles(src, kwds)
  File ""/home/lucas/repos/covid-19-data/venv/lib/python3.10/site-packages/pandas/io/parsers/base_parser.py"", line 222, in _open_handles
    self.handles = get_handle(
  File ""/home/lucas/repos/covid-19-data/venv/lib/python3.10/site-packages/pandas/io/common.py"", line 702, in get_handle
    handle = open(
FileNotFoundError: [Errno 2] No such file or directory: '/tmp/tmp6a0v1y1m/progress-of-vaccine-booster-programme.csv'
",[Errno 2] No such file or directory: '/tmp/tmp6a0v1y1m/progress-of-vaccine-booster-programme.csv'
cowidev.vax.batch.slovakia,46.92,True,2022-11-14T07:01:28,,
cowidev.vax.batch.slovenia,1.43,True,2022-11-14T07:00:42,,
cowidev.vax.batch.south_korea,47.49,True,2022-11-14T07:01:29,,
cowidev.vax.batch.spc,16.36,True,2022-11-14T07:00:59,,
cowidev.vax.batch.sweden,,,2022-11-14T15:17:31,,
cowidev.vax.batch.switzerland,32.97,True,2022-11-14T07:01:32,,
cowidev.vax.batch.trinidad_and_tobago,2.13,True,2022-11-14T07:01:16,,
cowidev.vax.batch.ukraine,,,2022-11-14T07:01:16,,
cowidev.vax.batch.united_kingdom,11.5,True,2022-11-14T07:01:27,,
cowidev.vax.batch.united_states,16.87,True,2022-11-14T07:01:37,,
cowidev.vax.batch.uruguay,1.11,True,2022-11-14T07:01:28,,
cowidev.vax.batch.zimbabwe,0.9,True,2022-11-14T07:01:29,,
cowidev.vax.incremental.africacdc,,,2022-11-14T07:01:28,,
cowidev.vax.incremental.antigua_barbuda,,,2022-11-14T07:01:28,,
cowidev.vax.incremental.aruba,1.29,True,2022-11-14T07:01:30,,
cowidev.vax.incremental.azerbaijan,,,2022-11-14T07:01:29,,
cowidev.vax.incremental.bahrain,1.37,True,2022-11-14T07:01:30,,
cowidev.vax.incremental.bangladesh,22.96,True,2022-11-14T07:01:52,,
cowidev.vax.incremental.barbados,,,2022-11-14T07:01:30,,
cowidev.vax.incremental.brazil,0.26,True,2022-11-14T07:01:30,,
cowidev.vax.incremental.bulgaria,1.26,True,2022-11-14T07:01:31,,
cowidev.vax.incremental.china,40.08,True,2022-11-14T07:02:10,,
cowidev.vax.incremental.costa_rica,,,2022-11-14T07:01:31,,
cowidev.vax.incremental.croatia,0.33,True,2022-11-14T07:01:31,,
cowidev.vax.incremental.cuba,2.34,True,2022-11-14T07:01:34,,
cowidev.vax.incremental.curacao,0.39,True,2022-11-14T07:01:32,,
cowidev.vax.incremental.cyprus,0.92,True,2022-11-14T15:17:32,,
cowidev.vax.incremental.dominican_republic,8.05,True,2022-11-14T07:01:42,,
cowidev.vax.incremental.el_salvador,3.38,True,2022-11-14T07:01:41,,
cowidev.vax.incremental.faeroe_islands,0.25,True,2022-11-14T07:01:39,,
cowidev.vax.incremental.fiji,0.0,True,2022-11-14T07:01:39,,
cowidev.vax.incremental.finland,0.21,True,2022-11-14T07:01:39,,
cowidev.vax.incremental.gabon,,,2022-11-14T07:01:39,,
cowidev.vax.incremental.georgia,0.6,True,2022-11-14T07:01:40,,
cowidev.vax.incremental.greenland,0.87,False,2022-11-14T07:05:00,"Traceback (most recent call last):
  File ""/mnt/owid_live_covid/covid-19-data/scripts/src/cowidev/cmd/commons/get.py"", line 46, in run
    module.main()
  File ""/mnt/owid_live_covid/covid-19-data/scripts/src/cowidev/vax/incremental/greenland.py"", line 74, in main
    Greenland().export()
  File ""/mnt/owid_live_covid/covid-19-data/scripts/src/cowidev/vax/incremental/greenland.py"", line 61, in export
    data = self.read().pipe(self.pipeline)
  File ""/mnt/owid_live_covid/covid-19-data/scripts/src/cowidev/vax/incremental/greenland.py"", line 18, in read
    data = self._parse_data(soup)
  File ""/mnt/owid_live_covid/covid-19-data/scripts/src/cowidev/vax/incremental/greenland.py"", line 22, in _parse_data
    return {**self._parse_data_metrics(soup), **self._parse_data_date(soup)}
  File ""/mnt/owid_live_covid/covid-19-data/scripts/src/cowidev/vax/incremental/greenland.py"", line 26, in _parse_data_metrics
    dose_1 = clean_count(re.search(r""Innuttaasut ([\d\.]+)"", counters[1].parent.find_all(""dd"")[-1].text).group(1))
IndexError: list index out of range
",list index out of range
cowidev.vax.incremental.guatemala,,,2022-11-14T07:01:41,,
cowidev.vax.incremental.guernsey,0.22,False,2022-11-14T07:05:00,"Traceback (most recent call last):
  File ""/mnt/owid_live_covid/covid-19-data/scripts/src/cowidev/cmd/commons/get.py"", line 46, in run
    module.main()
  File ""/mnt/owid_live_covid/covid-19-data/scripts/src/cowidev/vax/incremental/guernsey.py"", line 61, in main
    Guernsey().export()
  File ""/mnt/owid_live_covid/covid-19-data/scripts/src/cowidev/vax/incremental/guernsey.py"", line 50, in export
    data = self.read().pipe(self.pipeline)
  File ""/mnt/owid_live_covid/covid-19-data/scripts/src/cowidev/vax/incremental/guernsey.py"", line 15, in read
    df = self.parse_data(soup)
  File ""/mnt/owid_live_covid/covid-19-data/scripts/src/cowidev/vax/incremental/guernsey.py"", line 31, in parse_data
    ds.loc[ds[0] == ""Total doses"", 1].values[0].replace(""*"", """"),
IndexError: index 0 is out of bounds for axis 0 with size 0
",index 0 is out of bounds for axis 0 with size 0
cowidev.vax.incremental.hungary,1.12,True,2022-11-14T07:01:42,,
cowidev.vax.incremental.iceland,0.7,True,2022-11-14T07:01:42,,
cowidev.vax.incremental.india,0.89,True,2022-11-14T07:01:43,,
cowidev.vax.incremental.iran,,,2022-11-14T07:01:42,,
cowidev.vax.incremental.isle_of_man,0.91,True,2022-11-14T07:01:43,,
cowidev.vax.incremental.jamaica,1.51,True,2022-11-14T07:01:44,,
cowidev.vax.incremental.kazakhstan,14.57,True,2022-11-14T07:01:57,,
cowidev.vax.incremental.kosovo,1.85,True,2022-11-14T07:01:45,,
cowidev.vax.incremental.kyrgyzstan,1.58,True,2022-11-14T07:01:45,,
cowidev.vax.incremental.laos,2.08,True,2022-11-14T07:01:47,,
cowidev.vax.incremental.macao,30.2,False,2022-11-14T07:05:30,"Traceback (most recent call last):
  File ""/mnt/owid_live_covid/covid-19-data/scripts/src/cowidev/cmd/commons/get.py"", line 46, in run
    module.main()
  File ""/mnt/owid_live_covid/covid-19-data/scripts/src/cowidev/vax/incremental/macao.py"", line 86, in main
    Macao().export()
  File ""/mnt/owid_live_covid/covid-19-data/scripts/src/cowidev/vax/incremental/macao.py"", line 72, in export
    data = self.read()
  File ""/mnt/owid_live_covid/covid-19-data/scripts/src/cowidev/vax/incremental/macao.py"", line 22, in read
    data = self._parse_data(elem)
  File ""/mnt/owid_live_covid/covid-19-data/scripts/src/cowidev/vax/incremental/macao.py"", line 50, in _parse_data
    df = self._parse_pdf_table(url)
  File ""/mnt/owid_live_covid/covid-19-data/scripts/src/cowidev/vax/incremental/macao.py"", line 33, in _parse_pdf_table
    raise ValueError(""New columns added!"")
ValueError: New columns added!
",New columns added!
cowidev.vax.incremental.moldova,,,2022-11-14T07:01:47,,
cowidev.vax.incremental.monaco,33.32,True,2022-11-14T07:02:20,,
cowidev.vax.incremental.mongolia,0.7,True,2022-11-14T07:01:53,,
cowidev.vax.incremental.montenegro,0.11,True,2022-11-14T07:01:53,,
cowidev.vax.incremental.morocco,,,2022-11-14T07:01:53,,
cowidev.vax.incremental.myanmar,,,2022-11-14T07:01:53,,
cowidev.vax.incremental.nepal,,,2022-11-14T07:01:53,,
cowidev.vax.incremental.north_macedonia,,,2022-11-14T07:01:53,,
cowidev.vax.incremental.northern_cyprus,0.7,True,2022-11-14T07:01:54,,
cowidev.vax.incremental.paho,61.6,True,2022-11-14T15:18:32,,
cowidev.vax.incremental.pakistan,1.48,True,2022-11-14T07:01:59,,
cowidev.vax.incremental.philippines,,,2022-11-14T07:01:59,,
cowidev.vax.incremental.playground_mojmir,5.73,True,2022-11-14T07:02:04,,
cowidev.vax.incremental.poland,0.31,True,2022-11-14T07:02:05,,
cowidev.vax.incremental.qatar,,,2022-11-14T07:02:05,,
cowidev.vax.incremental.russia,1.28,True,2022-11-14T15:17:32,,
cowidev.vax.incremental.saint_lucia,,,2022-11-14T07:02:05,,
cowidev.vax.incremental.serbia,6.1,True,2022-11-14T07:02:11,,
cowidev.vax.incremental.south_africa,6.5,True,2022-11-14T07:02:17,,
cowidev.vax.incremental.spain,12.5,True,2022-11-14T07:02:24,,
cowidev.vax.incremental.sri_lanka,,,2022-11-14T07:02:17,,
cowidev.vax.incremental.suriname,14.3,True,2022-11-14T07:02:31,,
cowidev.vax.incremental.taiwan,5.15,True,2022-11-14T07:02:22,,
cowidev.vax.incremental.thailand,3.82,True,2022-11-14T07:02:24,,
cowidev.vax.incremental.turkey,40.34,False,2022-11-14T15:19:24,"Traceback (most recent call last):
  File ""/home/lucas/repos/covid-19-data/venv/lib/python3.10/site-packages/urllib3/connection.py"", line 174, in _new_conn
    conn = connection.create_connection(
  File ""/home/lucas/repos/covid-19-data/venv/lib/python3.10/site-packages/urllib3/util/connection.py"", line 95, in create_connection
    raise err
  File ""/home/lucas/repos/covid-19-data/venv/lib/python3.10/site-packages/urllib3/util/connection.py"", line 85, in create_connection
    sock.connect(sa)
TimeoutError: timed out

During handling of the above exception, another exception occurred:

Traceback (most recent call last):
  File ""/home/lucas/repos/covid-19-data/venv/lib/python3.10/site-packages/urllib3/connectionpool.py"", line 703, in urlopen
    httplib_response = self._make_request(
  File ""/home/lucas/repos/covid-19-data/venv/lib/python3.10/site-packages/urllib3/connectionpool.py"", line 386, in _make_request
    self._validate_conn(conn)
  File ""/home/lucas/repos/covid-19-data/venv/lib/python3.10/site-packages/urllib3/connectionpool.py"", line 1040, in _validate_conn
    conn.connect()
  File ""/home/lucas/repos/covid-19-data/venv/lib/python3.10/site-packages/urllib3/connection.py"", line 358, in connect
    conn = self._new_conn()
  File ""/home/lucas/repos/covid-19-data/venv/lib/python3.10/site-packages/urllib3/connection.py"", line 179, in _new_conn
    raise ConnectTimeoutError(
urllib3.exceptions.ConnectTimeoutError: (<urllib3.connection.HTTPSConnection object at 0x7f81de4513c0>, 'Connection to covid19asi.saglik.gov.tr timed out. (connect timeout=20)')

During handling of the above exception, another exception occurred:

Traceback (most recent call last):
  File ""/home/lucas/repos/covid-19-data/venv/lib/python3.10/site-packages/requests/adapters.py"", line 440, in send
    resp = conn.urlopen(
  File ""/home/lucas/repos/covid-19-data/venv/lib/python3.10/site-packages/urllib3/connectionpool.py"", line 785, in urlopen
    retries = retries.increment(
  File ""/home/lucas/repos/covid-19-data/venv/lib/python3.10/site-packages/urllib3/util/retry.py"", line 592, in increment
    raise MaxRetryError(_pool, url, error or ResponseError(cause))
urllib3.exceptions.MaxRetryError: HTTPSConnectionPool(host='covid19asi.saglik.gov.tr', port=443): Max retries exceeded with url: / (Caused by ConnectTimeoutError(<urllib3.connection.HTTPSConnection object at 0x7f81de4513c0>, 'Connection to covid19asi.saglik.gov.tr timed out. (connect timeout=20)'))

During handling of the above exception, another exception occurred:

Traceback (most recent call last):
  File ""/home/lucas/repos/covid-19-data/scripts/src/cowidev/cmd/commons/get.py"", line 46, in run
    module.main()
  File ""/home/lucas/repos/covid-19-data/scripts/src/cowidev/vax/incremental/turkey.py"", line 60, in main
    data = read(source).pipe(pipeline)
  File ""/home/lucas/repos/covid-19-data/scripts/src/cowidev/vax/incremental/turkey.py"", line 19, in read
    soup = get_soup(source)
  File ""/home/lucas/repos/covid-19-data/scripts/src/cowidev/utils/web/scraping.py"", line 83, in get_soup
    response = get_response(source, request_method, use_proxy, **kwargs)
  File ""/home/lucas/repos/covid-19-data/scripts/src/cowidev/utils/web/scraping.py"", line 49, in get_response
    raise err
  File ""/home/lucas/repos/covid-19-data/scripts/src/cowidev/utils/web/scraping.py"", line 43, in get_response
    response = requests.get(source, **kwargs)
  File ""/home/lucas/repos/covid-19-data/venv/lib/python3.10/site-packages/requests/api.py"", line 75, in get
    return request('get', url, params=params, **kwargs)
  File ""/home/lucas/repos/covid-19-data/venv/lib/python3.10/site-packages/requests/api.py"", line 61, in request
    return session.request(method=method, url=url, **kwargs)
  File ""/home/lucas/repos/covid-19-data/venv/lib/python3.10/site-packages/requests/sessions.py"", line 529, in request
    resp = self.send(prep, **send_kwargs)
  File ""/home/lucas/repos/covid-19-data/venv/lib/python3.10/site-packages/requests/sessions.py"", line 645, in send
    r = adapter.send(request, **kwargs)
  File ""/home/lucas/repos/covid-19-data/venv/lib/python3.10/site-packages/requests/adapters.py"", line 507, in send
    raise ConnectTimeout(e, request=request)
requests.exceptions.ConnectTimeout: HTTPSConnectionPool(host='covid19asi.saglik.gov.tr', port=443): Max retries exceeded with url: / (Caused by ConnectTimeoutError(<urllib3.connection.HTTPSConnection object at 0x7f81de4513c0>, 'Connection to covid19asi.saglik.gov.tr timed out. (connect timeout=20)'))
","HTTPSConnectionPool(host='covid19asi.saglik.gov.tr', port=443): Max retries exceeded with url: / (Caused by ConnectTimeoutError(<urllib3.connection.HTTPSConnection object at 0x7f81de4513c0>, 'Connection to covid19asi.saglik.gov.tr timed out. (connect timeout=20)'))"
cowidev.vax.incremental.united_arab_emirates,,,2022-11-14T07:02:24,,
cowidev.vax.incremental.vietnam,,,2022-11-14T07:02:24,,
cowidev.vax.incremental.who,4.53,True,2022-11-14T07:02:28,,
cowidev.vax.incremental.zambia,1.32,True,2022-11-14T07:02:25,,
