module,execution_time (sec),success,timestamp,error,error_short
cowidev.vax.batch.argentina,15.73,True,2022-12-24T07:00:20,,
cowidev.vax.batch.australia,124.72,True,2022-12-24T07:02:09,,
cowidev.vax.batch.austria,15.06,True,2022-12-24T07:00:20,,
cowidev.vax.batch.belgium,17.52,True,2022-12-24T07:00:22,,
cowidev.vax.batch.bolivia,5.12,True,2022-12-24T07:00:10,,
cowidev.vax.batch.canada,30.07,True,2022-12-24T07:00:35,,
cowidev.vax.batch.chile,1.06,True,2022-12-24T07:00:06,,
cowidev.vax.batch.czechia,47.13,True,2022-12-24T07:00:52,,
cowidev.vax.batch.denmark,126.66,True,2022-12-24T07:02:11,,
cowidev.vax.batch.ecdc,132.08,True,2022-12-24T07:02:17,,
cowidev.vax.batch.ecuador,,,2022-12-24T07:00:05,,
cowidev.vax.batch.estonia,0.59,True,2022-12-24T07:00:05,,
cowidev.vax.batch.france,1.09,False,2022-12-24T07:03:48,"Traceback (most recent call last):
  File ""/home/owid/covid-19-data/scripts/src/cowidev/cmd/commons/get.py"", line 46, in run
    module.main()
  File ""/home/owid/covid-19-data/scripts/src/cowidev/vax/batch/france.py"", line 120, in main
    France().export()
  File ""/home/owid/covid-19-data/scripts/src/cowidev/vax/batch/france.py"", line 69, in export
    raise ValueError(
ValueError: Unknown vaccine value: {10}.
See https://www.data.gouv.fr/fr/datasets/donnees-relatives-aux-personnes-vaccinees-contre-la-covid-19-1/ to find the vaccine's name.
","Unknown vaccine value: {10}.
See https://www.data.gouv.fr/fr/datasets/donnees-relatives-aux-personnes-vaccinees-contre-la-covid-19-1/ to find the vaccine's name."
cowidev.vax.batch.germany,0.13,True,2022-12-24T07:00:05,,
cowidev.vax.batch.greece,15.54,True,2022-12-24T07:00:20,,
cowidev.vax.batch.hong_kong,20.2,True,2022-12-24T07:00:25,,
cowidev.vax.batch.indonesia,,,2022-12-24T07:00:05,,
cowidev.vax.batch.ireland,5.08,True,2022-12-24T07:00:10,,
cowidev.vax.batch.israel,14.47,True,2022-12-24T07:00:19,,
cowidev.vax.batch.italy,6.48,True,2022-12-24T07:00:11,,
cowidev.vax.batch.japan,58.35,True,2022-12-24T07:01:03,,
cowidev.vax.batch.jersey,5.41,True,2022-12-24T07:00:10,,
cowidev.vax.batch.latvia,68.92,True,2022-12-24T07:01:14,,
cowidev.vax.batch.lithuania,4.78,True,2022-12-24T07:00:10,,
cowidev.vax.batch.luxembourg,4.04,True,2022-12-24T07:00:09,,
cowidev.vax.batch.malaysia,0.77,True,2022-12-24T07:00:06,,
cowidev.vax.batch.malta,1.29,True,2022-12-24T07:00:06,,
cowidev.vax.batch.netherlands,,,2022-12-24T07:00:05,,
cowidev.vax.batch.new_zealand,14.99,True,2022-12-24T07:00:20,,
cowidev.vax.batch.norway,0.98,True,2022-12-24T07:00:06,,
cowidev.vax.batch.peru,5.11,True,2022-12-24T07:00:10,,
cowidev.vax.batch.portugal,,,2022-12-24T07:00:05,,
cowidev.vax.batch.romania,58.68,True,2022-12-24T07:01:03,,
cowidev.vax.batch.saudi_arabia,9.01,True,2022-12-24T07:00:14,,
cowidev.vax.batch.singapore,5.88,True,2022-12-24T07:00:11,,
cowidev.vax.batch.slovakia,108.22,True,2022-12-24T07:01:53,,
cowidev.vax.batch.slovenia,3.99,True,2022-12-24T07:00:09,,
cowidev.vax.batch.south_korea,115.33,True,2022-12-24T07:02:01,,
cowidev.vax.batch.spc,28.33,True,2022-12-24T07:00:34,,
cowidev.vax.batch.sweden,18.51,True,2022-12-24T07:00:24,,
cowidev.vax.batch.switzerland,129.55,True,2022-12-24T07:02:16,,
cowidev.vax.batch.trinidad_and_tobago,2.85,True,2022-12-24T07:00:12,,
cowidev.vax.batch.ukraine,,,2022-12-24T07:00:09,,
cowidev.vax.batch.united_kingdom,17.38,True,2022-12-24T07:00:27,,
cowidev.vax.batch.united_states,128.0,True,2022-12-24T07:02:18,,
cowidev.vax.batch.uruguay,6.96,True,2022-12-24T07:00:17,,
cowidev.vax.batch.zimbabwe,1.86,True,2022-12-24T07:00:12,,
cowidev.vax.incremental.africacdc,,,2022-12-24T07:00:10,,
cowidev.vax.incremental.antigua_barbuda,,,2022-12-24T07:00:10,,
cowidev.vax.incremental.aruba,1.02,True,2022-12-24T07:00:11,,
cowidev.vax.incremental.azerbaijan,,,2022-12-24T07:00:10,,
cowidev.vax.incremental.bahrain,,,2022-12-24T07:00:10,,
cowidev.vax.incremental.bangladesh,37.21,True,2022-12-24T07:00:47,,
cowidev.vax.incremental.barbados,,,2022-12-24T07:00:11,,
cowidev.vax.incremental.brazil,0.46,True,2022-12-24T07:00:11,,
cowidev.vax.incremental.bulgaria,11.86,True,2022-12-24T07:00:23,,
cowidev.vax.incremental.china,30.86,True,2022-12-24T07:00:42,,
cowidev.vax.incremental.costa_rica,,,2022-12-24T07:00:11,,
cowidev.vax.incremental.croatia,0.64,True,2022-12-24T07:00:12,,
cowidev.vax.incremental.cuba,25.08,True,2022-12-24T07:00:36,,
cowidev.vax.incremental.curacao,1.84,True,2022-12-24T07:00:13,,
cowidev.vax.incremental.cyprus,3.72,True,2022-12-24T07:00:15,,
cowidev.vax.incremental.dominican_republic,22.8,False,2022-12-24T07:04:11,"Traceback (most recent call last):
  File ""/home/owid/covid-19-data/scripts/src/cowidev/cmd/commons/get.py"", line 46, in run
    module.main()
  File ""/home/owid/covid-19-data/scripts/src/cowidev/vax/incremental/dominican_republic.py"", line 113, in main
    DominicanRepublic().export()
  File ""/home/owid/covid-19-data/scripts/src/cowidev/vax/incremental/dominican_republic.py"", line 68, in export
    data = self.read().pipe(self.pipeline)
  File ""/home/owid/covid-19-data/scripts/src/cowidev/vax/incremental/dominican_republic.py"", line 26, in read
    metrics = self._parse_metrics(driver)
  File ""/home/owid/covid-19-data/scripts/src/cowidev/vax/incremental/dominican_republic.py"", line 35, in _parse_metrics
    metric_candidates = _find_potential_metrics(driver)
  File ""/home/owid/covid-19-data/scripts/src/cowidev/vax/incremental/dominican_republic.py"", line 92, in _find_potential_metrics
    h3 = _find_h3(driver)
  File ""/home/owid/covid-19-data/scripts/src/cowidev/vax/incremental/dominican_republic.py"", line 82, in _find_h3
    raise ValueError(""More than one element found!"")
ValueError: More than one element found!
",More than one element found!
cowidev.vax.incremental.el_salvador,14.36,True,2022-12-24T07:00:28,,
cowidev.vax.incremental.faeroe_islands,1.51,True,2022-12-24T07:00:15,,
cowidev.vax.incremental.fiji,0.0,True,2022-12-24T07:00:15,,
cowidev.vax.incremental.finland,0.93,True,2022-12-24T07:00:16,,
cowidev.vax.incremental.gabon,,,2022-12-24T07:00:15,,
cowidev.vax.incremental.georgia,11.55,True,2022-12-24T07:00:27,,
cowidev.vax.incremental.greenland,6.01,True,2022-12-24T07:00:22,,
cowidev.vax.incremental.guatemala,,,2022-12-24T07:00:17,,
cowidev.vax.incremental.guernsey,12.0,True,2022-12-24T07:00:29,,
cowidev.vax.incremental.hungary,7.25,True,2022-12-24T07:00:26,,
cowidev.vax.incremental.iceland,4.86,True,2022-12-24T07:00:25,,
cowidev.vax.incremental.india,3.08,True,2022-12-24T07:00:23,,
cowidev.vax.incremental.iran,,,2022-12-24T07:00:20,,
cowidev.vax.incremental.isle_of_man,2.52,True,2022-12-24T07:00:23,,
cowidev.vax.incremental.jamaica,10.09,True,2022-12-24T07:00:31,,
cowidev.vax.incremental.kazakhstan,7.47,True,2022-12-24T07:00:30,,
cowidev.vax.incremental.kosovo,7.33,False,2022-12-24T07:04:18,"Traceback (most recent call last):
  File ""/home/owid/covid-19-data/scripts/src/cowidev/cmd/commons/get.py"", line 46, in run
    module.main()
  File ""/home/owid/covid-19-data/scripts/src/cowidev/vax/incremental/kosovo.py"", line 82, in main
    Kosovo().export()
  File ""/home/owid/covid-19-data/scripts/src/cowidev/vax/incremental/kosovo.py"", line 77, in export
    df = self.read().pipe(self.pipeline)
  File ""/home/owid/covid-19-data/scripts/src/cowidev/vax/incremental/kosovo.py"", line 23, in read
    df = self._parse_data(soup)
  File ""/home/owid/covid-19-data/scripts/src/cowidev/vax/incremental/kosovo.py"", line 32, in _parse_data
    soup = get_soup(link, verify=False)
  File ""/home/owid/covid-19-data/scripts/src/cowidev/utils/web/scraping.py"", line 83, in get_soup
    response = get_response(source, request_method, use_proxy, **kwargs)
  File ""/home/owid/covid-19-data/scripts/src/cowidev/utils/web/scraping.py"", line 52, in get_response
    raise ValueError(
ValueError: Source https://msh.rks-gov.net/10.230.0.57+9000/coviddashboard.html not reached! Error code 404 Not Found
",Source https://msh.rks-gov.net/10.230.0.57+9000/coviddashboard.html not reached! Error code 404 Not Found
cowidev.vax.incremental.kyrgyzstan,7.12,True,2022-12-24T07:00:30,,
cowidev.vax.incremental.laos,7.55,True,2022-12-24T07:00:30,,
cowidev.vax.incremental.macao,24.48,True,2022-12-24T07:00:47,,
cowidev.vax.incremental.moldova,,,2022-12-24T07:00:24,,
cowidev.vax.incremental.monaco,118.36,True,2022-12-24T07:02:23,,
cowidev.vax.incremental.mongolia,1.37,True,2022-12-24T07:00:26,,
cowidev.vax.incremental.montenegro,0.97,True,2022-12-24T07:00:26,,
cowidev.vax.incremental.morocco,,,2022-12-24T07:00:26,,
cowidev.vax.incremental.myanmar,,,2022-12-24T07:00:26,,
cowidev.vax.incremental.nepal,,,2022-12-24T07:00:26,,
cowidev.vax.incremental.north_macedonia,,,2022-12-24T07:00:26,,
cowidev.vax.incremental.northern_cyprus,4.97,True,2022-12-24T07:00:31,,
cowidev.vax.incremental.paho,138.66,False,2022-12-24T07:06:37,"Traceback (most recent call last):
  File ""/home/owid/covid-19-data/scripts/src/cowidev/cmd/commons/get.py"", line 46, in run
    module.main()
  File ""/home/owid/covid-19-data/scripts/src/cowidev/vax/incremental/paho.py"", line 195, in main
    PAHO().export()
  File ""/home/owid/covid-19-data/scripts/src/cowidev/vax/incremental/paho.py"", line 190, in export
    df = self.read().pipe(self.pipeline)
  File ""/home/owid/covid-19-data/scripts/src/cowidev/vax/incremental/paho.py"", line 37, in read
    df = self._parse_data(url)
  File ""/home/owid/covid-19-data/scripts/src/cowidev/vax/incremental/paho.py"", line 64, in _parse_data
    filename = self._get_downloaded_filename()
  File ""/home/owid/covid-19-data/scripts/src/cowidev/vax/incremental/paho.py"", line 116, in _get_downloaded_filename
    return max(files, key=os.path.getctime)
ValueError: max() arg is an empty sequence
",max() arg is an empty sequence
cowidev.vax.incremental.pakistan,5.85,False,2022-12-24T07:06:42,"Traceback (most recent call last):
  File ""/home/owid/covid-19-data/scripts/venv/lib/python3.10/site-packages/urllib3/connectionpool.py"", line 703, in urlopen
    httplib_response = self._make_request(
  File ""/home/owid/covid-19-data/scripts/venv/lib/python3.10/site-packages/urllib3/connectionpool.py"", line 386, in _make_request
    self._validate_conn(conn)
  File ""/home/owid/covid-19-data/scripts/venv/lib/python3.10/site-packages/urllib3/connectionpool.py"", line 1042, in _validate_conn
    conn.connect()
  File ""/home/owid/covid-19-data/scripts/venv/lib/python3.10/site-packages/urllib3/connection.py"", line 414, in connect
    self.sock = ssl_wrap_socket(
  File ""/home/owid/covid-19-data/scripts/venv/lib/python3.10/site-packages/urllib3/util/ssl_.py"", line 449, in ssl_wrap_socket
    ssl_sock = _ssl_wrap_socket_impl(
  File ""/home/owid/covid-19-data/scripts/venv/lib/python3.10/site-packages/urllib3/util/ssl_.py"", line 493, in _ssl_wrap_socket_impl
    return ssl_context.wrap_socket(sock, server_hostname=server_hostname)
  File ""/usr/lib/python3.10/ssl.py"", line 513, in wrap_socket
    return self.sslsocket_class._create(
  File ""/usr/lib/python3.10/ssl.py"", line 1071, in _create
    self.do_handshake()
  File ""/usr/lib/python3.10/ssl.py"", line 1342, in do_handshake
    self._sslobj.do_handshake()
ssl.SSLCertVerificationError: [SSL: CERTIFICATE_VERIFY_FAILED] certificate verify failed: certificate has expired (_ssl.c:997)

During handling of the above exception, another exception occurred:

Traceback (most recent call last):
  File ""/home/owid/covid-19-data/scripts/venv/lib/python3.10/site-packages/requests/adapters.py"", line 440, in send
    resp = conn.urlopen(
  File ""/home/owid/covid-19-data/scripts/venv/lib/python3.10/site-packages/urllib3/connectionpool.py"", line 787, in urlopen
    retries = retries.increment(
  File ""/home/owid/covid-19-data/scripts/venv/lib/python3.10/site-packages/urllib3/util/retry.py"", line 592, in increment
    raise MaxRetryError(_pool, url, error or ResponseError(cause))
urllib3.exceptions.MaxRetryError: HTTPSConnectionPool(host='covid.gov.pk', port=443): Max retries exceeded with url: /vaccine-details (Caused by SSLError(SSLCertVerificationError(1, '[SSL: CERTIFICATE_VERIFY_FAILED] certificate verify failed: certificate has expired (_ssl.c:997)')))

During handling of the above exception, another exception occurred:

Traceback (most recent call last):
  File ""/home/owid/covid-19-data/scripts/src/cowidev/cmd/commons/get.py"", line 46, in run
    module.main()
  File ""/home/owid/covid-19-data/scripts/src/cowidev/vax/incremental/pakistan.py"", line 58, in main
    Pakistan().export()
  File ""/home/owid/covid-19-data/scripts/src/cowidev/vax/incremental/pakistan.py"", line 53, in export
    data = self.read().pipe(self.pipeline)
  File ""/home/owid/covid-19-data/scripts/src/cowidev/vax/incremental/pakistan.py"", line 17, in read
    soup = get_soup(self.source_url)
  File ""/home/owid/covid-19-data/scripts/src/cowidev/utils/web/scraping.py"", line 83, in get_soup
    response = get_response(source, request_method, use_proxy, **kwargs)
  File ""/home/owid/covid-19-data/scripts/src/cowidev/utils/web/scraping.py"", line 49, in get_response
    raise err
  File ""/home/owid/covid-19-data/scripts/src/cowidev/utils/web/scraping.py"", line 43, in get_response
    response = requests.get(source, **kwargs)
  File ""/home/owid/covid-19-data/scripts/venv/lib/python3.10/site-packages/requests/api.py"", line 75, in get
    return request('get', url, params=params, **kwargs)
  File ""/home/owid/covid-19-data/scripts/venv/lib/python3.10/site-packages/requests/api.py"", line 61, in request
    return session.request(method=method, url=url, **kwargs)
  File ""/home/owid/covid-19-data/scripts/venv/lib/python3.10/site-packages/requests/sessions.py"", line 529, in request
    resp = self.send(prep, **send_kwargs)
  File ""/home/owid/covid-19-data/scripts/venv/lib/python3.10/site-packages/requests/sessions.py"", line 645, in send
    r = adapter.send(request, **kwargs)
  File ""/home/owid/covid-19-data/scripts/venv/lib/python3.10/site-packages/requests/adapters.py"", line 517, in send
    raise SSLError(e, request=request)
requests.exceptions.SSLError: HTTPSConnectionPool(host='covid.gov.pk', port=443): Max retries exceeded with url: /vaccine-details (Caused by SSLError(SSLCertVerificationError(1, '[SSL: CERTIFICATE_VERIFY_FAILED] certificate verify failed: certificate has expired (_ssl.c:997)')))
","HTTPSConnectionPool(host='covid.gov.pk', port=443): Max retries exceeded with url: /vaccine-details (Caused by SSLError(SSLCertVerificationError(1, '[SSL: CERTIFICATE_VERIFY_FAILED] certificate verify failed: certificate has expired (_ssl.c:997)')))"
cowidev.vax.incremental.philippines,,,2022-12-24T07:00:27,,
cowidev.vax.incremental.poland,1.99,True,2022-12-24T07:00:29,,
cowidev.vax.incremental.qatar,,,2022-12-24T07:00:27,,
cowidev.vax.incremental.russia,26.97,True,2022-12-24T07:00:54,,
cowidev.vax.incremental.saint_lucia,,,2022-12-24T07:00:28,,
cowidev.vax.incremental.serbia,0.42,False,2022-12-24T07:06:43,"Traceback (most recent call last):
  File ""/home/owid/covid-19-data/scripts/src/cowidev/cmd/commons/get.py"", line 46, in run
    module.main()
  File ""/home/owid/covid-19-data/scripts/src/cowidev/vax/incremental/serbia.py"", line 88, in main
    Serbia().export()
  File ""/home/owid/covid-19-data/scripts/src/cowidev/vax/incremental/serbia.py"", line 74, in export
    data = self.read().pipe(self.pipeline)
  File ""/home/owid/covid-19-data/scripts/src/cowidev/vax/incremental/serbia.py"", line 23, in read
    soup = get_soup(self.source_url)
  File ""/home/owid/covid-19-data/scripts/src/cowidev/utils/web/scraping.py"", line 83, in get_soup
    response = get_response(source, request_method, use_proxy, **kwargs)
  File ""/home/owid/covid-19-data/scripts/src/cowidev/utils/web/scraping.py"", line 52, in get_response
    raise ValueError(
ValueError: Source https://vakcinacija.gov.rs/ not reached! Error code 503 Service Unavailable
",Source https://vakcinacija.gov.rs/ not reached! Error code 503 Service Unavailable
cowidev.vax.incremental.south_africa,9.24,True,2022-12-24T07:00:37,,
cowidev.vax.incremental.spain,28.15,True,2022-12-24T07:00:57,,
cowidev.vax.incremental.sri_lanka,,,2022-12-24T07:00:29,,
cowidev.vax.incremental.suriname,16.23,True,2022-12-24T07:00:45,,
cowidev.vax.incremental.taiwan,30.58,True,2022-12-24T07:01:00,,
cowidev.vax.incremental.thailand,8.36,True,2022-12-24T07:00:38,,
cowidev.vax.incremental.turkey,40.05,False,2022-12-24T07:07:23,"Traceback (most recent call last):
  File ""/home/owid/covid-19-data/scripts/venv/lib/python3.10/site-packages/urllib3/connection.py"", line 174, in _new_conn
    conn = connection.create_connection(
  File ""/home/owid/covid-19-data/scripts/venv/lib/python3.10/site-packages/urllib3/util/connection.py"", line 95, in create_connection
    raise err
  File ""/home/owid/covid-19-data/scripts/venv/lib/python3.10/site-packages/urllib3/util/connection.py"", line 85, in create_connection
    sock.connect(sa)
TimeoutError: timed out

During handling of the above exception, another exception occurred:

Traceback (most recent call last):
  File ""/home/owid/covid-19-data/scripts/venv/lib/python3.10/site-packages/urllib3/connectionpool.py"", line 703, in urlopen
    httplib_response = self._make_request(
  File ""/home/owid/covid-19-data/scripts/venv/lib/python3.10/site-packages/urllib3/connectionpool.py"", line 386, in _make_request
    self._validate_conn(conn)
  File ""/home/owid/covid-19-data/scripts/venv/lib/python3.10/site-packages/urllib3/connectionpool.py"", line 1042, in _validate_conn
    conn.connect()
  File ""/home/owid/covid-19-data/scripts/venv/lib/python3.10/site-packages/urllib3/connection.py"", line 358, in connect
    self.sock = conn = self._new_conn()
  File ""/home/owid/covid-19-data/scripts/venv/lib/python3.10/site-packages/urllib3/connection.py"", line 179, in _new_conn
    raise ConnectTimeoutError(
urllib3.exceptions.ConnectTimeoutError: (<urllib3.connection.HTTPSConnection object at 0x7f8a9c1ac460>, 'Connection to covid19asi.saglik.gov.tr timed out. (connect timeout=20)')

During handling of the above exception, another exception occurred:

Traceback (most recent call last):
  File ""/home/owid/covid-19-data/scripts/venv/lib/python3.10/site-packages/requests/adapters.py"", line 440, in send
    resp = conn.urlopen(
  File ""/home/owid/covid-19-data/scripts/venv/lib/python3.10/site-packages/urllib3/connectionpool.py"", line 787, in urlopen
    retries = retries.increment(
  File ""/home/owid/covid-19-data/scripts/venv/lib/python3.10/site-packages/urllib3/util/retry.py"", line 592, in increment
    raise MaxRetryError(_pool, url, error or ResponseError(cause))
urllib3.exceptions.MaxRetryError: HTTPSConnectionPool(host='covid19asi.saglik.gov.tr', port=443): Max retries exceeded with url: / (Caused by ConnectTimeoutError(<urllib3.connection.HTTPSConnection object at 0x7f8a9c1ac460>, 'Connection to covid19asi.saglik.gov.tr timed out. (connect timeout=20)'))

During handling of the above exception, another exception occurred:

Traceback (most recent call last):
  File ""/home/owid/covid-19-data/scripts/src/cowidev/cmd/commons/get.py"", line 46, in run
    module.main()
  File ""/home/owid/covid-19-data/scripts/src/cowidev/vax/incremental/turkey.py"", line 60, in main
    data = read(source).pipe(pipeline)
  File ""/home/owid/covid-19-data/scripts/src/cowidev/vax/incremental/turkey.py"", line 19, in read
    soup = get_soup(source)
  File ""/home/owid/covid-19-data/scripts/src/cowidev/utils/web/scraping.py"", line 83, in get_soup
    response = get_response(source, request_method, use_proxy, **kwargs)
  File ""/home/owid/covid-19-data/scripts/src/cowidev/utils/web/scraping.py"", line 49, in get_response
    raise err
  File ""/home/owid/covid-19-data/scripts/src/cowidev/utils/web/scraping.py"", line 43, in get_response
    response = requests.get(source, **kwargs)
  File ""/home/owid/covid-19-data/scripts/venv/lib/python3.10/site-packages/requests/api.py"", line 75, in get
    return request('get', url, params=params, **kwargs)
  File ""/home/owid/covid-19-data/scripts/venv/lib/python3.10/site-packages/requests/api.py"", line 61, in request
    return session.request(method=method, url=url, **kwargs)
  File ""/home/owid/covid-19-data/scripts/venv/lib/python3.10/site-packages/requests/sessions.py"", line 529, in request
    resp = self.send(prep, **send_kwargs)
  File ""/home/owid/covid-19-data/scripts/venv/lib/python3.10/site-packages/requests/sessions.py"", line 645, in send
    r = adapter.send(request, **kwargs)
  File ""/home/owid/covid-19-data/scripts/venv/lib/python3.10/site-packages/requests/adapters.py"", line 507, in send
    raise ConnectTimeout(e, request=request)
requests.exceptions.ConnectTimeout: HTTPSConnectionPool(host='covid19asi.saglik.gov.tr', port=443): Max retries exceeded with url: / (Caused by ConnectTimeoutError(<urllib3.connection.HTTPSConnection object at 0x7f8a9c1ac460>, 'Connection to covid19asi.saglik.gov.tr timed out. (connect timeout=20)'))
","HTTPSConnectionPool(host='covid19asi.saglik.gov.tr', port=443): Max retries exceeded with url: / (Caused by ConnectTimeoutError(<urllib3.connection.HTTPSConnection object at 0x7f8a9c1ac460>, 'Connection to covid19asi.saglik.gov.tr timed out. (connect timeout=20)'))"
cowidev.vax.incremental.united_arab_emirates,,,2022-12-24T07:00:30,,
cowidev.vax.incremental.vietnam,,,2022-12-24T07:00:30,,
cowidev.vax.incremental.who,66.51,True,2022-12-24T07:01:37,,
cowidev.vax.incremental.zambia,2.01,True,2022-12-24T07:00:33,,
