module,execution_time (sec),success,timestamp,error,error_short
cowidev.vax.batch.argentina,14.94,True,2023-02-04T07:00:20,,
cowidev.vax.batch.australia,123.64,True,2023-02-04T07:02:09,,
cowidev.vax.batch.austria,13.64,True,2023-02-04T07:00:19,,
cowidev.vax.batch.belgium,13.17,True,2023-02-04T07:00:18,,
cowidev.vax.batch.bolivia,4.16,True,2023-02-04T07:00:09,,
cowidev.vax.batch.canada,15.77,False,2023-02-04T07:03:58,"Traceback (most recent call last):
  File ""/home/owid/covid-19-data/scripts/src/cowidev/cmd/commons/get.py"", line 46, in run
    module.main()
  File ""/home/owid/covid-19-data/scripts/src/cowidev/vax/batch/canada.py"", line 289, in main
    Canada().export()
  File ""/home/owid/covid-19-data/scripts/src/cowidev/vax/batch/canada.py"", line 277, in export
    df = df.pipe(self.pipeline, df_man)
  File ""/home/owid/covid-19-data/scripts/venv/lib/python3.10/site-packages/pandas/core/generic.py"", line 5430, in pipe
    return com.pipe(self, func, *args, **kwargs)
  File ""/home/owid/covid-19-data/scripts/venv/lib/python3.10/site-packages/pandas/core/common.py"", line 471, in pipe
    return func(obj, *args, **kwargs)
  File ""/home/owid/covid-19-data/scripts/src/cowidev/vax/batch/canada.py"", line 257, in pipeline
    .pipe(self.pipe_make_monotonic)[
  File ""/home/owid/covid-19-data/scripts/venv/lib/python3.10/site-packages/pandas/core/generic.py"", line 5430, in pipe
    return com.pipe(self, func, *args, **kwargs)
  File ""/home/owid/covid-19-data/scripts/venv/lib/python3.10/site-packages/pandas/core/common.py"", line 471, in pipe
    return func(obj, *args, **kwargs)
  File ""/home/owid/covid-19-data/scripts/src/cowidev/vax/batch/canada.py"", line 237, in pipe_make_monotonic
    df = df.pipe(self.make_monotonic, max_removed_rows=self.max_removed_rows)
  File ""/home/owid/covid-19-data/scripts/venv/lib/python3.10/site-packages/pandas/core/generic.py"", line 5430, in pipe
    return com.pipe(self, func, *args, **kwargs)
  File ""/home/owid/covid-19-data/scripts/venv/lib/python3.10/site-packages/pandas/core/common.py"", line 471, in pipe
    return func(obj, *args, **kwargs)
  File ""/home/owid/covid-19-data/scripts/src/cowidev/vax/utils/base.py"", line 120, in make_monotonic
    return mkm(
  File ""/home/owid/covid-19-data/scripts/src/cowidev/utils/utils.py"", line 23, in make_monotonic
    return make_monotonic_new(df, column_date, column_metrics, max_removed_rows)
  File ""/home/owid/covid-19-data/scripts/src/cowidev/utils/utils.py"", line 94, in make_monotonic_new
    raise Exception(
Exception: 1 chunks of lengths 36 have been NaNed for metric people_vaccinated. That is more than maximum allowed (22) by make_monotonic() - check the data. Check dates ['2023-01-26']
",1 chunks of lengths 36 have been NaNed for metric people_vaccinated. That is more than maximum allowed (22) by make_monotonic() - check the data. Check dates ['2023-01-26']
cowidev.vax.batch.chile,0.84,True,2023-02-04T07:00:06,,
cowidev.vax.batch.czechia,38.14,True,2023-02-04T07:00:43,,
cowidev.vax.batch.denmark,125.22,True,2023-02-04T07:02:10,,
cowidev.vax.batch.ecdc,128.36,True,2023-02-04T07:02:13,,
cowidev.vax.batch.ecuador,,,2023-02-04T07:00:05,,
cowidev.vax.batch.estonia,0.68,True,2023-02-04T07:00:06,,
cowidev.vax.batch.france,6.43,True,2023-02-04T07:00:11,,
cowidev.vax.batch.germany,10.69,True,2023-02-04T07:00:16,,
cowidev.vax.batch.greece,18.67,True,2023-02-04T07:00:24,,
cowidev.vax.batch.hong_kong,22.45,True,2023-02-04T07:00:28,,
cowidev.vax.batch.indonesia,,,2023-02-04T07:00:05,,
cowidev.vax.batch.ireland,3.88,True,2023-02-04T07:00:09,,
cowidev.vax.batch.israel,10.6,True,2023-02-04T07:00:16,,
cowidev.vax.batch.italy,9.64,True,2023-02-04T07:00:15,,
cowidev.vax.batch.japan,52.6,True,2023-02-04T07:00:58,,
cowidev.vax.batch.jersey,4.99,True,2023-02-04T07:00:10,,
cowidev.vax.batch.latvia,65.55,True,2023-02-04T07:01:11,,
cowidev.vax.batch.lithuania,5.57,True,2023-02-04T07:00:11,,
cowidev.vax.batch.luxembourg,2.93,True,2023-02-04T07:00:08,,
cowidev.vax.batch.malaysia,0.71,True,2023-02-04T07:00:06,,
cowidev.vax.batch.malta,1.14,True,2023-02-04T07:00:06,,
cowidev.vax.batch.netherlands,,,2023-02-04T07:00:05,,
cowidev.vax.batch.new_zealand,12.45,True,2023-02-04T07:00:18,,
cowidev.vax.batch.norway,0.54,True,2023-02-04T07:00:06,,
cowidev.vax.batch.peru,5.32,True,2023-02-04T07:00:10,,
cowidev.vax.batch.portugal,,,2023-02-04T07:00:05,,
cowidev.vax.batch.romania,67.7,True,2023-02-04T07:01:13,,
cowidev.vax.batch.saudi_arabia,9.37,True,2023-02-04T07:00:14,,
cowidev.vax.batch.singapore,5.07,True,2023-02-04T07:00:10,,
cowidev.vax.batch.slovakia,98.23,True,2023-02-04T07:01:44,,
cowidev.vax.batch.slovenia,2.92,True,2023-02-04T07:00:09,,
cowidev.vax.batch.south_korea,122.13,True,2023-02-04T07:02:08,,
cowidev.vax.batch.spc,33.12,True,2023-02-04T07:00:39,,
cowidev.vax.batch.sweden,18.65,True,2023-02-04T07:00:25,,
cowidev.vax.batch.switzerland,123.91,True,2023-02-04T07:02:12,,
cowidev.vax.batch.trinidad_and_tobago,2.14,True,2023-02-04T07:00:11,,
cowidev.vax.batch.ukraine,,,2023-02-04T07:00:09,,
cowidev.vax.batch.united_kingdom,17.51,True,2023-02-04T07:00:26,,
cowidev.vax.batch.united_states,124.99,True,2023-02-04T07:02:14,,
cowidev.vax.batch.uruguay,9.41,True,2023-02-04T07:00:19,,
cowidev.vax.batch.zimbabwe,2.17,True,2023-02-04T07:00:12,,
cowidev.vax.incremental.africacdc,,,2023-02-04T07:00:10,,
cowidev.vax.incremental.antigua_barbuda,,,2023-02-04T07:00:10,,
cowidev.vax.incremental.aruba,2.21,True,2023-02-04T07:00:13,,
cowidev.vax.incremental.azerbaijan,,,2023-02-04T07:00:11,,
cowidev.vax.incremental.bahrain,,,2023-02-04T07:00:11,,
cowidev.vax.incremental.bangladesh,39.07,True,2023-02-04T07:00:50,,
cowidev.vax.incremental.barbados,,,2023-02-04T07:00:11,,
cowidev.vax.incremental.brazil,2.18,True,2023-02-04T07:00:13,,
cowidev.vax.incremental.bulgaria,12.54,True,2023-02-04T07:00:24,,
cowidev.vax.incremental.china,21.46,True,2023-02-04T07:00:34,,
cowidev.vax.incremental.costa_rica,,,2023-02-04T07:00:13,,
cowidev.vax.incremental.croatia,0.98,True,2023-02-04T07:00:14,,
cowidev.vax.incremental.cuba,13.66,True,2023-02-04T07:00:27,,
cowidev.vax.incremental.curacao,1.27,True,2023-02-04T07:00:15,,
cowidev.vax.incremental.cyprus,3.11,True,2023-02-04T07:00:18,,
cowidev.vax.incremental.dominican_republic,22.67,False,2023-02-04T07:04:21,"Traceback (most recent call last):
  File ""/home/owid/covid-19-data/scripts/src/cowidev/cmd/commons/get.py"", line 46, in run
    module.main()
  File ""/home/owid/covid-19-data/scripts/src/cowidev/vax/incremental/dominican_republic.py"", line 113, in main
    DominicanRepublic().export()
  File ""/home/owid/covid-19-data/scripts/src/cowidev/vax/incremental/dominican_republic.py"", line 68, in export
    data = self.read().pipe(self.pipeline)
  File ""/home/owid/covid-19-data/scripts/src/cowidev/vax/incremental/dominican_republic.py"", line 26, in read
    metrics = self._parse_metrics(driver)
  File ""/home/owid/covid-19-data/scripts/src/cowidev/vax/incremental/dominican_republic.py"", line 35, in _parse_metrics
    metric_candidates = _find_potential_metrics(driver)
  File ""/home/owid/covid-19-data/scripts/src/cowidev/vax/incremental/dominican_republic.py"", line 92, in _find_potential_metrics
    h3 = _find_h3(driver)
  File ""/home/owid/covid-19-data/scripts/src/cowidev/vax/incremental/dominican_republic.py"", line 82, in _find_h3
    raise ValueError(""More than one element found!"")
ValueError: More than one element found!
",More than one element found!
cowidev.vax.incremental.el_salvador,13.76,True,2023-02-04T07:00:29,,
cowidev.vax.incremental.faeroe_islands,1.96,True,2023-02-04T07:00:18,,
cowidev.vax.incremental.fiji,0.0,True,2023-02-04T07:00:16,,
cowidev.vax.incremental.finland,0.97,True,2023-02-04T07:00:17,,
cowidev.vax.incremental.gabon,,,2023-02-04T07:00:17,,
cowidev.vax.incremental.georgia,10.37,True,2023-02-04T07:00:27,,
cowidev.vax.incremental.greenland,0.17,False,2023-02-04T07:04:21,"Traceback (most recent call last):
  File ""/home/owid/covid-19-data/scripts/src/cowidev/cmd/commons/get.py"", line 46, in run
    module.main()
  File ""/home/owid/covid-19-data/scripts/src/cowidev/vax/incremental/greenland.py"", line 76, in main
    Greenland().export()
  File ""/home/owid/covid-19-data/scripts/src/cowidev/vax/incremental/greenland.py"", line 63, in export
    data = self.read().pipe(self.pipeline)
  File ""/home/owid/covid-19-data/scripts/src/cowidev/vax/incremental/greenland.py"", line 17, in read
    data = self._parse_data(soup)
  File ""/home/owid/covid-19-data/scripts/src/cowidev/vax/incremental/greenland.py"", line 21, in _parse_data
    return {**self._parse_data_metrics(soup), **self._parse_data_date(soup)}
  File ""/home/owid/covid-19-data/scripts/src/cowidev/vax/incremental/greenland.py"", line 31, in _parse_data_metrics
    assert len(counter_1) == len(counter_2) == 1
AssertionError
",
cowidev.vax.incremental.guatemala,,,2023-02-04T07:00:18,,
cowidev.vax.incremental.guernsey,10.67,True,2023-02-04T07:00:28,,
cowidev.vax.incremental.hungary,115.49,True,2023-02-04T07:02:13,,
cowidev.vax.incremental.iceland,4.22,True,2023-02-04T07:00:22,,
cowidev.vax.incremental.india,5.57,True,2023-02-04T07:00:24,,
cowidev.vax.incremental.iran,,,2023-02-04T07:00:19,,
cowidev.vax.incremental.isle_of_man,2.82,True,2023-02-04T07:00:22,,
cowidev.vax.incremental.jamaica,9.44,True,2023-02-04T07:00:29,,
cowidev.vax.incremental.kazakhstan,6.92,True,2023-02-04T07:00:29,,
cowidev.vax.incremental.kosovo,5.49,False,2023-02-04T07:04:26,"Traceback (most recent call last):
  File ""/home/owid/covid-19-data/scripts/src/cowidev/cmd/commons/get.py"", line 46, in run
    module.main()
  File ""/home/owid/covid-19-data/scripts/src/cowidev/vax/incremental/kosovo.py"", line 82, in main
    Kosovo().export()
  File ""/home/owid/covid-19-data/scripts/src/cowidev/vax/incremental/kosovo.py"", line 77, in export
    df = self.read().pipe(self.pipeline)
  File ""/home/owid/covid-19-data/scripts/src/cowidev/vax/incremental/kosovo.py"", line 23, in read
    df = self._parse_data(soup)
  File ""/home/owid/covid-19-data/scripts/src/cowidev/vax/incremental/kosovo.py"", line 32, in _parse_data
    soup = get_soup(link, verify=False)
  File ""/home/owid/covid-19-data/scripts/src/cowidev/utils/web/scraping.py"", line 83, in get_soup
    response = get_response(source, request_method, use_proxy, **kwargs)
  File ""/home/owid/covid-19-data/scripts/src/cowidev/utils/web/scraping.py"", line 52, in get_response
    raise ValueError(
ValueError: Source https://msh.rks-gov.net/10.230.0.57+9000/coviddashboard.html not reached! Error code 404 Not Found
",Source https://msh.rks-gov.net/10.230.0.57+9000/coviddashboard.html not reached! Error code 404 Not Found
cowidev.vax.incremental.kyrgyzstan,20.02,False,2023-02-04T07:04:46,"Traceback (most recent call last):
  File ""/home/owid/covid-19-data/scripts/venv/lib/python3.10/site-packages/urllib3/connection.py"", line 174, in _new_conn
    conn = connection.create_connection(
  File ""/home/owid/covid-19-data/scripts/venv/lib/python3.10/site-packages/urllib3/util/connection.py"", line 72, in create_connection
    for res in socket.getaddrinfo(host, port, family, socket.SOCK_STREAM):
  File ""/usr/lib/python3.10/socket.py"", line 955, in getaddrinfo
    for res in _socket.getaddrinfo(host, port, family, type, proto, flags):
socket.gaierror: [Errno -3] Temporary failure in name resolution

During handling of the above exception, another exception occurred:

Traceback (most recent call last):
  File ""/home/owid/covid-19-data/scripts/venv/lib/python3.10/site-packages/urllib3/connectionpool.py"", line 703, in urlopen
    httplib_response = self._make_request(
  File ""/home/owid/covid-19-data/scripts/venv/lib/python3.10/site-packages/urllib3/connectionpool.py"", line 386, in _make_request
    self._validate_conn(conn)
  File ""/home/owid/covid-19-data/scripts/venv/lib/python3.10/site-packages/urllib3/connectionpool.py"", line 1042, in _validate_conn
    conn.connect()
  File ""/home/owid/covid-19-data/scripts/venv/lib/python3.10/site-packages/urllib3/connection.py"", line 358, in connect
    self.sock = conn = self._new_conn()
  File ""/home/owid/covid-19-data/scripts/venv/lib/python3.10/site-packages/urllib3/connection.py"", line 186, in _new_conn
    raise NewConnectionError(
urllib3.exceptions.NewConnectionError: <urllib3.connection.HTTPSConnection object at 0x7f2c240da6b0>: Failed to establish a new connection: [Errno -3] Temporary failure in name resolution

During handling of the above exception, another exception occurred:

Traceback (most recent call last):
  File ""/home/owid/covid-19-data/scripts/venv/lib/python3.10/site-packages/requests/adapters.py"", line 440, in send
    resp = conn.urlopen(
  File ""/home/owid/covid-19-data/scripts/venv/lib/python3.10/site-packages/urllib3/connectionpool.py"", line 787, in urlopen
    retries = retries.increment(
  File ""/home/owid/covid-19-data/scripts/venv/lib/python3.10/site-packages/urllib3/util/retry.py"", line 592, in increment
    raise MaxRetryError(_pool, url, error or ResponseError(cause))
urllib3.exceptions.MaxRetryError: HTTPSConnectionPool(host='vc.emed.gov.kg', port=443): Max retries exceeded with url: / (Caused by NewConnectionError('<urllib3.connection.HTTPSConnection object at 0x7f2c240da6b0>: Failed to establish a new connection: [Errno -3] Temporary failure in name resolution'))

During handling of the above exception, another exception occurred:

Traceback (most recent call last):
  File ""/home/owid/covid-19-data/scripts/src/cowidev/cmd/commons/get.py"", line 46, in run
    module.main()
  File ""/home/owid/covid-19-data/scripts/src/cowidev/vax/incremental/kyrgyzstan.py"", line 61, in main
    Kyrgyzstan().export()
  File ""/home/owid/covid-19-data/scripts/src/cowidev/vax/incremental/kyrgyzstan.py"", line 48, in export
    data = self.read().pipe(self.pipeline)
  File ""/home/owid/covid-19-data/scripts/src/cowidev/vax/incremental/kyrgyzstan.py"", line 14, in read
    soup = get_soup(self.source_url, verify=False)
  File ""/home/owid/covid-19-data/scripts/src/cowidev/utils/web/scraping.py"", line 83, in get_soup
    response = get_response(source, request_method, use_proxy, **kwargs)
  File ""/home/owid/covid-19-data/scripts/src/cowidev/utils/web/scraping.py"", line 49, in get_response
    raise err
  File ""/home/owid/covid-19-data/scripts/src/cowidev/utils/web/scraping.py"", line 43, in get_response
    response = requests.get(source, **kwargs)
  File ""/home/owid/covid-19-data/scripts/venv/lib/python3.10/site-packages/requests/api.py"", line 75, in get
    return request('get', url, params=params, **kwargs)
  File ""/home/owid/covid-19-data/scripts/venv/lib/python3.10/site-packages/requests/api.py"", line 61, in request
    return session.request(method=method, url=url, **kwargs)
  File ""/home/owid/covid-19-data/scripts/venv/lib/python3.10/site-packages/requests/sessions.py"", line 529, in request
    resp = self.send(prep, **send_kwargs)
  File ""/home/owid/covid-19-data/scripts/venv/lib/python3.10/site-packages/requests/sessions.py"", line 645, in send
    r = adapter.send(request, **kwargs)
  File ""/home/owid/covid-19-data/scripts/venv/lib/python3.10/site-packages/requests/adapters.py"", line 519, in send
    raise ConnectionError(e, request=request)
requests.exceptions.ConnectionError: HTTPSConnectionPool(host='vc.emed.gov.kg', port=443): Max retries exceeded with url: / (Caused by NewConnectionError('<urllib3.connection.HTTPSConnection object at 0x7f2c240da6b0>: Failed to establish a new connection: [Errno -3] Temporary failure in name resolution'))
","HTTPSConnectionPool(host='vc.emed.gov.kg', port=443): Max retries exceeded with url: / (Caused by NewConnectionError('<urllib3.connection.HTTPSConnection object at 0x7f2c240da6b0>: Failed to establish a new connection: [Errno -3] Temporary failure in name resolution'))"
cowidev.vax.incremental.laos,27.59,True,2023-02-04T07:00:52,,
cowidev.vax.incremental.macao,13.65,True,2023-02-04T07:00:38,,
cowidev.vax.incremental.moldova,,,2023-02-04T07:00:25,,
cowidev.vax.incremental.monaco,115.28,True,2023-02-04T07:02:20,,
cowidev.vax.incremental.mongolia,1.68,True,2023-02-04T07:00:27,,
cowidev.vax.incremental.montenegro,0.71,True,2023-02-04T07:00:27,,
cowidev.vax.incremental.morocco,,,2023-02-04T07:00:27,,
cowidev.vax.incremental.myanmar,,,2023-02-04T07:00:27,,
cowidev.vax.incremental.nepal,,,2023-02-04T07:00:27,,
cowidev.vax.incremental.north_macedonia,,,2023-02-04T07:00:27,,
cowidev.vax.incremental.northern_cyprus,4.21,True,2023-02-04T07:00:31,,
cowidev.vax.incremental.paho,136.85,False,2023-02-04T07:07:03,"Traceback (most recent call last):
  File ""/home/owid/covid-19-data/scripts/src/cowidev/cmd/commons/get.py"", line 46, in run
    module.main()
  File ""/home/owid/covid-19-data/scripts/src/cowidev/vax/incremental/paho.py"", line 195, in main
    PAHO().export()
  File ""/home/owid/covid-19-data/scripts/src/cowidev/vax/incremental/paho.py"", line 190, in export
    df = self.read().pipe(self.pipeline)
  File ""/home/owid/covid-19-data/scripts/src/cowidev/vax/incremental/paho.py"", line 37, in read
    df = self._parse_data(url)
  File ""/home/owid/covid-19-data/scripts/src/cowidev/vax/incremental/paho.py"", line 64, in _parse_data
    filename = self._get_downloaded_filename()
  File ""/home/owid/covid-19-data/scripts/src/cowidev/vax/incremental/paho.py"", line 116, in _get_downloaded_filename
    return max(files, key=os.path.getctime)
ValueError: max() arg is an empty sequence
",max() arg is an empty sequence
cowidev.vax.incremental.pakistan,,,2023-02-04T07:00:27,,
cowidev.vax.incremental.philippines,,,2023-02-04T07:00:27,,
cowidev.vax.incremental.poland,1.5,True,2023-02-04T07:00:29,,
cowidev.vax.incremental.qatar,,,2023-02-04T07:00:27,,
cowidev.vax.incremental.russia,45.41,True,2023-02-04T07:01:13,,
cowidev.vax.incremental.saint_lucia,,,2023-02-04T07:00:28,,
cowidev.vax.incremental.serbia,12.98,True,2023-02-04T07:00:40,,
cowidev.vax.incremental.south_africa,,,2023-02-04T07:00:28,,
cowidev.vax.incremental.spain,19.78,True,2023-02-04T07:00:48,,
cowidev.vax.incremental.sri_lanka,,,2023-02-04T07:00:29,,
cowidev.vax.incremental.suriname,16.05,True,2023-02-04T07:00:45,,
cowidev.vax.incremental.taiwan,25.92,True,2023-02-04T07:00:55,,
cowidev.vax.incremental.thailand,8.22,True,2023-02-04T07:00:37,,
cowidev.vax.incremental.turkey,40.23,False,2023-02-04T07:07:43,"Traceback (most recent call last):
  File ""/home/owid/covid-19-data/scripts/venv/lib/python3.10/site-packages/urllib3/connectionpool.py"", line 386, in _make_request
    self._validate_conn(conn)
  File ""/home/owid/covid-19-data/scripts/venv/lib/python3.10/site-packages/urllib3/connectionpool.py"", line 1042, in _validate_conn
    conn.connect()
  File ""/home/owid/covid-19-data/scripts/venv/lib/python3.10/site-packages/urllib3/connection.py"", line 414, in connect
    self.sock = ssl_wrap_socket(
  File ""/home/owid/covid-19-data/scripts/venv/lib/python3.10/site-packages/urllib3/util/ssl_.py"", line 449, in ssl_wrap_socket
    ssl_sock = _ssl_wrap_socket_impl(
  File ""/home/owid/covid-19-data/scripts/venv/lib/python3.10/site-packages/urllib3/util/ssl_.py"", line 493, in _ssl_wrap_socket_impl
    return ssl_context.wrap_socket(sock, server_hostname=server_hostname)
  File ""/usr/lib/python3.10/ssl.py"", line 513, in wrap_socket
    return self.sslsocket_class._create(
  File ""/usr/lib/python3.10/ssl.py"", line 1071, in _create
    self.do_handshake()
  File ""/usr/lib/python3.10/ssl.py"", line 1342, in do_handshake
    self._sslobj.do_handshake()
TimeoutError: _ssl.c:980: The handshake operation timed out

During handling of the above exception, another exception occurred:

Traceback (most recent call last):
  File ""/home/owid/covid-19-data/scripts/venv/lib/python3.10/site-packages/requests/adapters.py"", line 440, in send
    resp = conn.urlopen(
  File ""/home/owid/covid-19-data/scripts/venv/lib/python3.10/site-packages/urllib3/connectionpool.py"", line 787, in urlopen
    retries = retries.increment(
  File ""/home/owid/covid-19-data/scripts/venv/lib/python3.10/site-packages/urllib3/util/retry.py"", line 550, in increment
    raise six.reraise(type(error), error, _stacktrace)
  File ""/home/owid/covid-19-data/scripts/venv/lib/python3.10/site-packages/urllib3/packages/six.py"", line 770, in reraise
    raise value
  File ""/home/owid/covid-19-data/scripts/venv/lib/python3.10/site-packages/urllib3/connectionpool.py"", line 703, in urlopen
    httplib_response = self._make_request(
  File ""/home/owid/covid-19-data/scripts/venv/lib/python3.10/site-packages/urllib3/connectionpool.py"", line 389, in _make_request
    self._raise_timeout(err=e, url=url, timeout_value=conn.timeout)
  File ""/home/owid/covid-19-data/scripts/venv/lib/python3.10/site-packages/urllib3/connectionpool.py"", line 340, in _raise_timeout
    raise ReadTimeoutError(
urllib3.exceptions.ReadTimeoutError: HTTPSConnectionPool(host='covid19asi.saglik.gov.tr', port=443): Read timed out. (read timeout=20)

During handling of the above exception, another exception occurred:

Traceback (most recent call last):
  File ""/home/owid/covid-19-data/scripts/src/cowidev/cmd/commons/get.py"", line 46, in run
    module.main()
  File ""/home/owid/covid-19-data/scripts/src/cowidev/vax/incremental/turkey.py"", line 60, in main
    data = read(source).pipe(pipeline)
  File ""/home/owid/covid-19-data/scripts/src/cowidev/vax/incremental/turkey.py"", line 19, in read
    soup = get_soup(source)
  File ""/home/owid/covid-19-data/scripts/src/cowidev/utils/web/scraping.py"", line 83, in get_soup
    response = get_response(source, request_method, use_proxy, **kwargs)
  File ""/home/owid/covid-19-data/scripts/src/cowidev/utils/web/scraping.py"", line 49, in get_response
    raise err
  File ""/home/owid/covid-19-data/scripts/src/cowidev/utils/web/scraping.py"", line 43, in get_response
    response = requests.get(source, **kwargs)
  File ""/home/owid/covid-19-data/scripts/venv/lib/python3.10/site-packages/requests/api.py"", line 75, in get
    return request('get', url, params=params, **kwargs)
  File ""/home/owid/covid-19-data/scripts/venv/lib/python3.10/site-packages/requests/api.py"", line 61, in request
    return session.request(method=method, url=url, **kwargs)
  File ""/home/owid/covid-19-data/scripts/venv/lib/python3.10/site-packages/requests/sessions.py"", line 529, in request
    resp = self.send(prep, **send_kwargs)
  File ""/home/owid/covid-19-data/scripts/venv/lib/python3.10/site-packages/requests/sessions.py"", line 645, in send
    r = adapter.send(request, **kwargs)
  File ""/home/owid/covid-19-data/scripts/venv/lib/python3.10/site-packages/requests/adapters.py"", line 532, in send
    raise ReadTimeout(e, request=request)
requests.exceptions.ReadTimeout: HTTPSConnectionPool(host='covid19asi.saglik.gov.tr', port=443): Read timed out. (read timeout=20)
","HTTPSConnectionPool(host='covid19asi.saglik.gov.tr', port=443): Read timed out. (read timeout=20)"
cowidev.vax.incremental.united_arab_emirates,,,2023-02-04T07:00:31,,
cowidev.vax.incremental.vietnam,,,2023-02-04T07:00:31,,
cowidev.vax.incremental.who,66.52,True,2023-02-04T07:01:37,,
cowidev.vax.incremental.zambia,1.97,True,2023-02-04T07:00:36,,
