module,execution_time (sec),success,timestamp,error,error_short
cowidev.vax.batch.argentina,13.92,True,2022-10-27T07:00:24,,
cowidev.vax.batch.australia,76.19,True,2022-10-27T07:01:26,,
cowidev.vax.batch.austria,18.81,True,2022-10-27T07:00:29,,
cowidev.vax.batch.belgium,20.6,True,2022-10-27T07:00:31,,
cowidev.vax.batch.bolivia,3.82,True,2022-10-27T07:00:14,,
cowidev.vax.batch.canada,33.01,True,2022-10-27T07:00:47,,
cowidev.vax.batch.chile,23.5,True,2022-10-27T07:00:48,,
cowidev.vax.batch.czechia,59.47,True,2022-10-27T07:01:28,,
cowidev.vax.batch.denmark,68.23,True,2022-10-27T07:01:39,,
cowidev.vax.batch.ecdc,60.04,False,2022-10-27T07:04:59,"Traceback (most recent call last):
  File ""/mnt/owid_live_covid/covid-19-data/scripts/venv/lib/python3.9/site-packages/urllib3/connection.py"", line 174, in _new_conn
    conn = connection.create_connection(
  File ""/mnt/owid_live_covid/covid-19-data/scripts/venv/lib/python3.9/site-packages/urllib3/util/connection.py"", line 96, in create_connection
    raise err
  File ""/mnt/owid_live_covid/covid-19-data/scripts/venv/lib/python3.9/site-packages/urllib3/util/connection.py"", line 86, in create_connection
    sock.connect(sa)
socket.timeout: timed out

During handling of the above exception, another exception occurred:

Traceback (most recent call last):
  File ""/mnt/owid_live_covid/covid-19-data/scripts/venv/lib/python3.9/site-packages/urllib3/connectionpool.py"", line 699, in urlopen
    httplib_response = self._make_request(
  File ""/mnt/owid_live_covid/covid-19-data/scripts/venv/lib/python3.9/site-packages/urllib3/connectionpool.py"", line 382, in _make_request
    self._validate_conn(conn)
  File ""/mnt/owid_live_covid/covid-19-data/scripts/venv/lib/python3.9/site-packages/urllib3/connectionpool.py"", line 1010, in _validate_conn
    conn.connect()
  File ""/mnt/owid_live_covid/covid-19-data/scripts/venv/lib/python3.9/site-packages/urllib3/connection.py"", line 358, in connect
    conn = self._new_conn()
  File ""/mnt/owid_live_covid/covid-19-data/scripts/venv/lib/python3.9/site-packages/urllib3/connection.py"", line 179, in _new_conn
    raise ConnectTimeoutError(
urllib3.exceptions.ConnectTimeoutError: (<urllib3.connection.HTTPSConnection object at 0x7fc3cc7a73a0>, 'Connection to opendata.ecdc.europa.eu timed out. (connect timeout=30)')

During handling of the above exception, another exception occurred:

Traceback (most recent call last):
  File ""/mnt/owid_live_covid/covid-19-data/scripts/venv/lib/python3.9/site-packages/requests/adapters.py"", line 440, in send
    resp = conn.urlopen(
  File ""/mnt/owid_live_covid/covid-19-data/scripts/venv/lib/python3.9/site-packages/urllib3/connectionpool.py"", line 755, in urlopen
    retries = retries.increment(
  File ""/mnt/owid_live_covid/covid-19-data/scripts/venv/lib/python3.9/site-packages/urllib3/util/retry.py"", line 574, in increment
    raise MaxRetryError(_pool, url, error or ResponseError(cause))
urllib3.exceptions.MaxRetryError: HTTPSConnectionPool(host='opendata.ecdc.europa.eu', port=443): Max retries exceeded with url: /covid19/vaccine_tracker/csv/data.csv (Caused by ConnectTimeoutError(<urllib3.connection.HTTPSConnection object at 0x7fc3cc7a73a0>, 'Connection to opendata.ecdc.europa.eu timed out. (connect timeout=30)'))

During handling of the above exception, another exception occurred:

Traceback (most recent call last):
  File ""/mnt/owid_live_covid/covid-19-data/scripts/src/cowidev/cmd/commons/get.py"", line 46, in run
    module.main()
  File ""/mnt/owid_live_covid/covid-19-data/scripts/src/cowidev/vax/batch/ecdc.py"", line 498, in main
    ECDC().export()
  File ""/mnt/owid_live_covid/covid-19-data/scripts/src/cowidev/vax/batch/ecdc.py"", line 488, in export
    df = self.read().pipe(self.pipe_base)
  File ""/mnt/owid_live_covid/covid-19-data/scripts/src/cowidev/vax/batch/ecdc.py"", line 117, in read
    df = read_csv_from_url(self.source_url, timeout=30)
  File ""/mnt/owid_live_covid/covid-19-data/scripts/src/cowidev/utils/web/download.py"", line 55, in read_csv_from_url
    download_file_from_url(
  File ""/mnt/owid_live_covid/covid-19-data/scripts/src/cowidev/utils/web/download.py"", line 80, in download_file_from_url
    r = requests.get(url, stream=True, timeout=timeout, verify=verify)
  File ""/mnt/owid_live_covid/covid-19-data/scripts/venv/lib/python3.9/site-packages/requests/api.py"", line 75, in get
    return request('get', url, params=params, **kwargs)
  File ""/mnt/owid_live_covid/covid-19-data/scripts/venv/lib/python3.9/site-packages/requests/api.py"", line 61, in request
    return session.request(method=method, url=url, **kwargs)
  File ""/mnt/owid_live_covid/covid-19-data/scripts/venv/lib/python3.9/site-packages/requests/sessions.py"", line 529, in request
    resp = self.send(prep, **send_kwargs)
  File ""/mnt/owid_live_covid/covid-19-data/scripts/venv/lib/python3.9/site-packages/requests/sessions.py"", line 645, in send
    r = adapter.send(request, **kwargs)
  File ""/mnt/owid_live_covid/covid-19-data/scripts/venv/lib/python3.9/site-packages/requests/adapters.py"", line 507, in send
    raise ConnectTimeout(e, request=request)
requests.exceptions.ConnectTimeout: HTTPSConnectionPool(host='opendata.ecdc.europa.eu', port=443): Max retries exceeded with url: /covid19/vaccine_tracker/csv/data.csv (Caused by ConnectTimeoutError(<urllib3.connection.HTTPSConnection object at 0x7fc3cc7a73a0>, 'Connection to opendata.ecdc.europa.eu timed out. (connect timeout=30)'))
","HTTPSConnectionPool(host='opendata.ecdc.europa.eu', port=443): Max retries exceeded with url: /covid19/vaccine_tracker/csv/data.csv (Caused by ConnectTimeoutError(<urllib3.connection.HTTPSConnection object at 0x7fc3cc7a73a0>, 'Connection to opendata.ecdc.europa.eu timed out. (connect timeout=30)'))"
cowidev.vax.batch.ecuador,8.9,True,2022-10-27T07:00:56,,
cowidev.vax.batch.estonia,4.99,True,2022-10-27T07:01:01,,
cowidev.vax.batch.france,7.09,True,2022-10-27T07:01:09,,
cowidev.vax.batch.germany,8.78,True,2022-10-27T07:01:17,,
cowidev.vax.batch.greece,8.93,True,2022-10-27T07:01:26,,
cowidev.vax.batch.hong_kong,6.15,True,2022-10-27T07:01:32,,
cowidev.vax.batch.indonesia,,,2022-10-27T07:01:26,,
cowidev.vax.batch.ireland,0.3,True,2022-10-27T07:01:27,,
cowidev.vax.batch.israel,5.27,True,2022-10-27T07:01:32,,
cowidev.vax.batch.italy,10.23,True,2022-10-27T07:01:39,,
cowidev.vax.batch.japan,1.34,False,2022-10-27T07:05:00,"Traceback (most recent call last):
  File ""/mnt/owid_live_covid/covid-19-data/scripts/src/cowidev/cmd/commons/get.py"", line 46, in run
    module.main()
  File ""/mnt/owid_live_covid/covid-19-data/scripts/src/cowidev/vax/batch/japan.py"", line 236, in main
    Japan().export()
  File ""/mnt/owid_live_covid/covid-19-data/scripts/src/cowidev/vax/batch/japan.py"", line 220, in export
    df = self.read().pipe(self.pipeline_base)
  File ""/mnt/owid_live_covid/covid-19-data/scripts/src/cowidev/vax/batch/japan.py"", line 156, in read
    df_latest = self.read_latest().pipe(self.pipe_latest)
  File ""/mnt/owid_live_covid/covid-19-data/scripts/src/cowidev/vax/batch/japan.py"", line 88, in read_latest
    dfs.append(self._read_xlsx(self.source_url, self.sheets, self.metrics))
  File ""/mnt/owid_live_covid/covid-19-data/scripts/src/cowidev/vax/batch/japan.py"", line 97, in _read_xlsx
    xlsx = pd.ExcelFile(url)
  File ""/mnt/owid_live_covid/covid-19-data/scripts/venv/lib/python3.9/site-packages/pandas/io/excel/_base.py"", line 1191, in __init__
    ext = inspect_excel_format(
  File ""/mnt/owid_live_covid/covid-19-data/scripts/venv/lib/python3.9/site-packages/pandas/io/excel/_base.py"", line 1070, in inspect_excel_format
    with get_handle(
  File ""/mnt/owid_live_covid/covid-19-data/scripts/venv/lib/python3.9/site-packages/pandas/io/common.py"", line 609, in get_handle
    ioargs = _get_filepath_or_buffer(
  File ""/mnt/owid_live_covid/covid-19-data/scripts/venv/lib/python3.9/site-packages/pandas/io/common.py"", line 312, in _get_filepath_or_buffer
    with urlopen(req_info) as req:
  File ""/mnt/owid_live_covid/covid-19-data/scripts/venv/lib/python3.9/site-packages/pandas/io/common.py"", line 212, in urlopen
    return urllib.request.urlopen(*args, **kwargs)
  File ""/home/owid/.pyenv/versions/3.9.6/lib/python3.9/urllib/request.py"", line 214, in urlopen
    return opener.open(url, data, timeout)
  File ""/home/owid/.pyenv/versions/3.9.6/lib/python3.9/urllib/request.py"", line 523, in open
    response = meth(req, response)
  File ""/home/owid/.pyenv/versions/3.9.6/lib/python3.9/urllib/request.py"", line 632, in http_response
    response = self.parent.error(
  File ""/home/owid/.pyenv/versions/3.9.6/lib/python3.9/urllib/request.py"", line 561, in error
    return self._call_chain(*args)
  File ""/home/owid/.pyenv/versions/3.9.6/lib/python3.9/urllib/request.py"", line 494, in _call_chain
    result = func(*args)
  File ""/home/owid/.pyenv/versions/3.9.6/lib/python3.9/urllib/request.py"", line 641, in http_error_default
    raise HTTPError(req.full_url, code, msg, hdrs, fp)
urllib.error.HTTPError: HTTP Error 404: Not Found
",HTTP Error 404: Not Found
cowidev.vax.batch.jersey,1.11,True,2022-10-27T07:01:33,,
cowidev.vax.batch.latvia,22.65,True,2022-10-27T07:01:56,,
cowidev.vax.batch.lithuania,0.96,True,2022-10-27T07:01:40,,
cowidev.vax.batch.luxembourg,2.19,True,2022-10-27T07:01:41,,
cowidev.vax.batch.malaysia,0.8,True,2022-10-27T07:01:40,,
cowidev.vax.batch.malta,0.81,True,2022-10-27T07:01:40,,
cowidev.vax.batch.netherlands,,,2022-10-27T07:01:40,,
cowidev.vax.batch.new_zealand,16.08,True,2022-10-27T07:01:56,,
cowidev.vax.batch.norway,0.43,True,2022-10-27T07:01:41,,
cowidev.vax.batch.peru,4.63,True,2022-10-27T07:01:45,,
cowidev.vax.batch.portugal,,,2022-10-27T07:01:41,,
cowidev.vax.batch.romania,15.4,True,2022-10-27T07:01:56,,
cowidev.vax.batch.saudi_arabia,10.37,True,2022-10-27T07:01:56,,
cowidev.vax.batch.singapore,4.86,True,2022-10-27T07:01:54,,
cowidev.vax.batch.slovakia,35.69,True,2022-10-27T07:02:29,,
cowidev.vax.batch.slovenia,0.46,True,2022-10-27T07:01:56,,
cowidev.vax.batch.south_korea,35.81,True,2022-10-27T07:02:32,,
cowidev.vax.batch.spc,19.21,True,2022-10-27T07:02:15,,
cowidev.vax.batch.sweden,12.94,True,2022-10-27T07:02:09,,
cowidev.vax.batch.switzerland,36.55,True,2022-10-27T07:02:33,,
cowidev.vax.batch.trinidad_and_tobago,2.05,True,2022-10-27T07:02:11,,
cowidev.vax.batch.ukraine,,,2022-10-27T07:02:11,,
cowidev.vax.batch.united_kingdom,9.9,True,2022-10-27T07:02:21,,
cowidev.vax.batch.united_states,23.91,True,2022-10-27T07:02:39,,
cowidev.vax.batch.uruguay,3.74,True,2022-10-27T07:02:25,,
cowidev.vax.batch.zimbabwe,0.6,True,2022-10-27T07:02:26,,
cowidev.vax.incremental.africacdc,,,2022-10-27T07:02:26,,
cowidev.vax.incremental.antigua_barbuda,,,2022-10-27T07:02:26,,
cowidev.vax.incremental.aruba,1.33,True,2022-10-27T07:02:27,,
cowidev.vax.incremental.azerbaijan,,,2022-10-27T07:02:27,,
cowidev.vax.incremental.bahrain,2.97,True,2022-10-27T07:02:30,,
cowidev.vax.incremental.bangladesh,20.58,True,2022-10-27T07:02:50,,
cowidev.vax.incremental.barbados,,,2022-10-27T07:02:30,,
cowidev.vax.incremental.brazil,0.07,True,2022-10-27T07:02:30,,
cowidev.vax.incremental.bulgaria,1.24,True,2022-10-27T07:02:31,,
cowidev.vax.incremental.china,81.36,True,2022-10-27T07:03:52,,
cowidev.vax.incremental.costa_rica,,,2022-10-27T07:02:32,,
cowidev.vax.incremental.croatia,0.2,True,2022-10-27T07:02:32,,
cowidev.vax.incremental.cuba,2.33,True,2022-10-27T07:02:34,,
cowidev.vax.incremental.curacao,0.36,True,2022-10-27T07:02:33,,
cowidev.vax.incremental.cyprus,0.86,True,2022-10-27T07:02:34,,
cowidev.vax.incremental.dominican_republic,8.96,True,2022-10-27T07:02:43,,
cowidev.vax.incremental.el_salvador,0.79,True,2022-10-27T07:02:35,,
cowidev.vax.incremental.faeroe_islands,0.4,True,2022-10-27T07:02:35,,
cowidev.vax.incremental.fiji,0.0,True,2022-10-27T07:02:35,,
cowidev.vax.incremental.finland,0.21,True,2022-10-27T07:02:36,,
cowidev.vax.incremental.gabon,,,2022-10-27T07:02:36,,
cowidev.vax.incremental.georgia,0.61,True,2022-10-27T07:02:36,,
cowidev.vax.incremental.greenland,0.48,False,2022-10-27T07:05:00,"Traceback (most recent call last):
  File ""/mnt/owid_live_covid/covid-19-data/scripts/src/cowidev/cmd/commons/get.py"", line 46, in run
    module.main()
  File ""/mnt/owid_live_covid/covid-19-data/scripts/src/cowidev/vax/incremental/greenland.py"", line 74, in main
    Greenland().export()
  File ""/mnt/owid_live_covid/covid-19-data/scripts/src/cowidev/vax/incremental/greenland.py"", line 61, in export
    data = self.read().pipe(self.pipeline)
  File ""/mnt/owid_live_covid/covid-19-data/scripts/src/cowidev/vax/incremental/greenland.py"", line 18, in read
    data = self._parse_data(soup)
  File ""/mnt/owid_live_covid/covid-19-data/scripts/src/cowidev/vax/incremental/greenland.py"", line 22, in _parse_data
    return {**self._parse_data_metrics(soup), **self._parse_data_date(soup)}
  File ""/mnt/owid_live_covid/covid-19-data/scripts/src/cowidev/vax/incremental/greenland.py"", line 26, in _parse_data_metrics
    dose_1 = clean_count(re.search(r""Innuttaasut ([\d\.]+)"", counters[1].parent.find_all(""dd"")[-1].text).group(1))
IndexError: list index out of range
",list index out of range
cowidev.vax.incremental.guatemala,,,2022-10-27T07:02:37,,
cowidev.vax.incremental.guernsey,0.19,False,2022-10-27T07:05:01,"Traceback (most recent call last):
  File ""/mnt/owid_live_covid/covid-19-data/scripts/src/cowidev/cmd/commons/get.py"", line 46, in run
    module.main()
  File ""/mnt/owid_live_covid/covid-19-data/scripts/src/cowidev/vax/incremental/guernsey.py"", line 61, in main
    Guernsey().export()
  File ""/mnt/owid_live_covid/covid-19-data/scripts/src/cowidev/vax/incremental/guernsey.py"", line 50, in export
    data = self.read().pipe(self.pipeline)
  File ""/mnt/owid_live_covid/covid-19-data/scripts/src/cowidev/vax/incremental/guernsey.py"", line 15, in read
    df = self.parse_data(soup)
  File ""/mnt/owid_live_covid/covid-19-data/scripts/src/cowidev/vax/incremental/guernsey.py"", line 31, in parse_data
    ds.loc[ds[0] == ""Total doses"", 1].values[0].replace(""*"", """"),
IndexError: index 0 is out of bounds for axis 0 with size 0
",index 0 is out of bounds for axis 0 with size 0
cowidev.vax.incremental.hungary,0.97,True,2022-10-27T07:02:38,,
cowidev.vax.incremental.iceland,0.3,True,2022-10-27T07:02:38,,
cowidev.vax.incremental.india,0.89,True,2022-10-27T07:02:39,,
cowidev.vax.incremental.iran,,,2022-10-27T07:02:39,,
cowidev.vax.incremental.isle_of_man,2.4,True,2022-10-27T07:02:42,,
cowidev.vax.incremental.jamaica,1.93,True,2022-10-27T07:02:41,,
cowidev.vax.incremental.kazakhstan,13.19,True,2022-10-27T07:02:55,,
cowidev.vax.incremental.kosovo,1.82,True,2022-10-27T07:02:43,,
cowidev.vax.incremental.kyrgyzstan,3.2,True,2022-10-27T07:02:46,,
cowidev.vax.incremental.laos,51.73,False,2022-10-27T07:05:52,"Traceback (most recent call last):
  File ""/mnt/owid_live_covid/covid-19-data/scripts/venv/lib/python3.9/site-packages/urllib3/connection.py"", line 174, in _new_conn
    conn = connection.create_connection(
  File ""/mnt/owid_live_covid/covid-19-data/scripts/venv/lib/python3.9/site-packages/urllib3/util/connection.py"", line 96, in create_connection
    raise err
  File ""/mnt/owid_live_covid/covid-19-data/scripts/venv/lib/python3.9/site-packages/urllib3/util/connection.py"", line 86, in create_connection
    sock.connect(sa)
socket.timeout: timed out

During handling of the above exception, another exception occurred:

Traceback (most recent call last):
  File ""/mnt/owid_live_covid/covid-19-data/scripts/venv/lib/python3.9/site-packages/urllib3/connectionpool.py"", line 699, in urlopen
    httplib_response = self._make_request(
  File ""/mnt/owid_live_covid/covid-19-data/scripts/venv/lib/python3.9/site-packages/urllib3/connectionpool.py"", line 382, in _make_request
    self._validate_conn(conn)
  File ""/mnt/owid_live_covid/covid-19-data/scripts/venv/lib/python3.9/site-packages/urllib3/connectionpool.py"", line 1010, in _validate_conn
    conn.connect()
  File ""/mnt/owid_live_covid/covid-19-data/scripts/venv/lib/python3.9/site-packages/urllib3/connection.py"", line 358, in connect
    conn = self._new_conn()
  File ""/mnt/owid_live_covid/covid-19-data/scripts/venv/lib/python3.9/site-packages/urllib3/connection.py"", line 179, in _new_conn
    raise ConnectTimeoutError(
urllib3.exceptions.ConnectTimeoutError: (<urllib3.connection.HTTPSConnection object at 0x7fc37a3abd90>, 'Connection to www.covid19.gov.la timed out. (connect timeout=20)')

During handling of the above exception, another exception occurred:

Traceback (most recent call last):
  File ""/mnt/owid_live_covid/covid-19-data/scripts/venv/lib/python3.9/site-packages/requests/adapters.py"", line 440, in send
    resp = conn.urlopen(
  File ""/mnt/owid_live_covid/covid-19-data/scripts/venv/lib/python3.9/site-packages/urllib3/connectionpool.py"", line 755, in urlopen
    retries = retries.increment(
  File ""/mnt/owid_live_covid/covid-19-data/scripts/venv/lib/python3.9/site-packages/urllib3/util/retry.py"", line 574, in increment
    raise MaxRetryError(_pool, url, error or ResponseError(cause))
urllib3.exceptions.MaxRetryError: HTTPSConnectionPool(host='www.covid19.gov.la', port=443): Max retries exceeded with url: /index.php (Caused by ConnectTimeoutError(<urllib3.connection.HTTPSConnection object at 0x7fc37a3abd90>, 'Connection to www.covid19.gov.la timed out. (connect timeout=20)'))

During handling of the above exception, another exception occurred:

Traceback (most recent call last):
  File ""/mnt/owid_live_covid/covid-19-data/scripts/src/cowidev/cmd/commons/get.py"", line 46, in run
    module.main()
  File ""/mnt/owid_live_covid/covid-19-data/scripts/src/cowidev/vax/incremental/laos.py"", line 101, in main
    Laos().export()
  File ""/mnt/owid_live_covid/covid-19-data/scripts/src/cowidev/vax/incremental/laos.py"", line 88, in export
    data = self.read().pipe(self.pipeline)
  File ""/mnt/owid_live_covid/covid-19-data/scripts/src/cowidev/vax/incremental/laos.py"", line 21, in read
    soup = get_soup(self.source_url)
  File ""/mnt/owid_live_covid/covid-19-data/scripts/src/cowidev/utils/web/scraping.py"", line 83, in get_soup
    response = get_response(source, request_method, use_proxy, **kwargs)
  File ""/mnt/owid_live_covid/covid-19-data/scripts/src/cowidev/utils/web/scraping.py"", line 49, in get_response
    raise err
  File ""/mnt/owid_live_covid/covid-19-data/scripts/src/cowidev/utils/web/scraping.py"", line 43, in get_response
    response = requests.get(source, **kwargs)
  File ""/mnt/owid_live_covid/covid-19-data/scripts/venv/lib/python3.9/site-packages/requests/api.py"", line 75, in get
    return request('get', url, params=params, **kwargs)
  File ""/mnt/owid_live_covid/covid-19-data/scripts/venv/lib/python3.9/site-packages/requests/api.py"", line 61, in request
    return session.request(method=method, url=url, **kwargs)
  File ""/mnt/owid_live_covid/covid-19-data/scripts/venv/lib/python3.9/site-packages/requests/sessions.py"", line 529, in request
    resp = self.send(prep, **send_kwargs)
  File ""/mnt/owid_live_covid/covid-19-data/scripts/venv/lib/python3.9/site-packages/requests/sessions.py"", line 645, in send
    r = adapter.send(request, **kwargs)
  File ""/mnt/owid_live_covid/covid-19-data/scripts/venv/lib/python3.9/site-packages/requests/adapters.py"", line 507, in send
    raise ConnectTimeout(e, request=request)
requests.exceptions.ConnectTimeout: HTTPSConnectionPool(host='www.covid19.gov.la', port=443): Max retries exceeded with url: /index.php (Caused by ConnectTimeoutError(<urllib3.connection.HTTPSConnection object at 0x7fc37a3abd90>, 'Connection to www.covid19.gov.la timed out. (connect timeout=20)'))
","HTTPSConnectionPool(host='www.covid19.gov.la', port=443): Max retries exceeded with url: /index.php (Caused by ConnectTimeoutError(<urllib3.connection.HTTPSConnection object at 0x7fc37a3abd90>, 'Connection to www.covid19.gov.la timed out. (connect timeout=20)'))"
cowidev.vax.incremental.macao,19.86,False,2022-10-27T07:06:12,"Traceback (most recent call last):
  File ""/mnt/owid_live_covid/covid-19-data/scripts/src/cowidev/cmd/commons/get.py"", line 46, in run
    module.main()
  File ""/mnt/owid_live_covid/covid-19-data/scripts/src/cowidev/vax/incremental/macao.py"", line 86, in main
    Macao().export()
  File ""/mnt/owid_live_covid/covid-19-data/scripts/src/cowidev/vax/incremental/macao.py"", line 72, in export
    data = self.read()
  File ""/mnt/owid_live_covid/covid-19-data/scripts/src/cowidev/vax/incremental/macao.py"", line 20, in read
    elem = driver.find_element_by_partial_link_text(""Weekly Bulletin on COVID-19"")
  File ""/mnt/owid_live_covid/covid-19-data/scripts/venv/lib/python3.9/site-packages/selenium/webdriver/remote/webdriver.py"", line 462, in find_element_by_partial_link_text
    return self.find_element(by=By.PARTIAL_LINK_TEXT, value=link_text)
  File ""/mnt/owid_live_covid/covid-19-data/scripts/venv/lib/python3.9/site-packages/selenium/webdriver/remote/webdriver.py"", line 976, in find_element
    return self.execute(Command.FIND_ELEMENT, {
  File ""/mnt/owid_live_covid/covid-19-data/scripts/venv/lib/python3.9/site-packages/selenium/webdriver/remote/webdriver.py"", line 321, in execute
    self.error_handler.check_response(response)
  File ""/mnt/owid_live_covid/covid-19-data/scripts/venv/lib/python3.9/site-packages/selenium/webdriver/remote/errorhandler.py"", line 242, in check_response
    raise exception_class(message, screen, stacktrace)
selenium.common.exceptions.NoSuchElementException: Message: no such element: Unable to locate element: {""method"":""partial link text"",""selector"":""Weekly Bulletin on COVID-19""}
  (Session info: headless chrome=106.0.5249.119)

","Message: no such element: Unable to locate element: {""method"":""partial link text"",""selector"":""Weekly Bulletin on COVID-19""}
  (Session info: headless chrome=106.0.5249.119)
"
cowidev.vax.incremental.moldova,,,2022-10-27T07:02:50,,
cowidev.vax.incremental.monaco,29.9,True,2022-10-27T07:03:20,,
cowidev.vax.incremental.mongolia,0.71,True,2022-10-27T07:02:55,,
cowidev.vax.incremental.montenegro,0.08,True,2022-10-27T07:02:55,,
cowidev.vax.incremental.morocco,,,2022-10-27T07:02:55,,
cowidev.vax.incremental.myanmar,,,2022-10-27T07:02:55,,
cowidev.vax.incremental.nepal,,,2022-10-27T07:02:55,,
cowidev.vax.incremental.north_macedonia,,,2022-10-27T07:02:55,,
cowidev.vax.incremental.northern_cyprus,0.71,True,2022-10-27T07:02:56,,
cowidev.vax.incremental.paho,98.34,False,2022-10-27T07:07:51,"Traceback (most recent call last):
  File ""/mnt/owid_live_covid/covid-19-data/scripts/src/cowidev/cmd/commons/get.py"", line 46, in run
    module.main()
  File ""/mnt/owid_live_covid/covid-19-data/scripts/src/cowidev/vax/incremental/paho.py"", line 191, in main
    PAHO().export()
  File ""/mnt/owid_live_covid/covid-19-data/scripts/src/cowidev/vax/incremental/paho.py"", line 186, in export
    df = self.read().pipe(self.pipeline)
  File ""/mnt/owid_live_covid/covid-19-data/scripts/venv/lib/python3.9/site-packages/pandas/core/generic.py"", line 5430, in pipe
    return com.pipe(self, func, *args, **kwargs)
  File ""/mnt/owid_live_covid/covid-19-data/scripts/venv/lib/python3.9/site-packages/pandas/core/common.py"", line 471, in pipe
    return func(obj, *args, **kwargs)
  File ""/mnt/owid_live_covid/covid-19-data/scripts/src/cowidev/vax/incremental/paho.py"", line 161, in pipeline
    df.pipe(self.pipe_check_columns)
  File ""/mnt/owid_live_covid/covid-19-data/scripts/venv/lib/python3.9/site-packages/pandas/core/generic.py"", line 5430, in pipe
    return com.pipe(self, func, *args, **kwargs)
  File ""/mnt/owid_live_covid/covid-19-data/scripts/venv/lib/python3.9/site-packages/pandas/core/common.py"", line 471, in pipe
    return func(obj, *args, **kwargs)
  File ""/mnt/owid_live_covid/covid-19-data/scripts/src/cowidev/vax/incremental/paho.py"", line 116, in pipe_check_columns
    raise ValueError(f""Missing column fields: {columns_missing}. Present columns are: {df.columns}"")
ValueError: Missing column fields: {'Total doses', 'Single dose', 'Country/ Territory', '2nd additional dose', 'First dose', '1st additional dose', 'Country code', 'Second dose'}. Present columns are: Index(['date,location,total_vaccinations,people_vaccinated,people_fully_vaccinated,total_boosters,new_vaccinations,new_vaccinations_interpolated,new_people_vaccinated_interpolated', 'date'], dtype='object')
","Missing column fields: {'Total doses', 'Single dose', 'Country/ Territory', '2nd additional dose', 'First dose', '1st additional dose', 'Country code', 'Second dose'}. Present columns are: Index(['date,location,total_vaccinations,people_vaccinated,people_fully_vaccinated,total_boosters,new_vaccinations,new_vaccinations_interpolated,new_people_vaccinated_interpolated', 'date'], dtype='object')"
cowidev.vax.incremental.pakistan,1.34,True,2022-10-27T07:03:07,,
cowidev.vax.incremental.philippines,,,2022-10-27T07:03:07,,
cowidev.vax.incremental.playground_mojmir,4.67,True,2022-10-27T07:03:12,,
cowidev.vax.incremental.poland,0.3,True,2022-10-27T07:03:12,,
cowidev.vax.incremental.qatar,,,2022-10-27T07:03:12,,
cowidev.vax.incremental.russia,0.53,False,2022-10-27T07:07:51,"Traceback (most recent call last):
  File ""/mnt/owid_live_covid/covid-19-data/scripts/src/cowidev/cmd/commons/get.py"", line 46, in run
    module.main()
  File ""/mnt/owid_live_covid/covid-19-data/scripts/src/cowidev/vax/incremental/russia.py"", line 80, in main
    Russia().export()
  File ""/mnt/owid_live_covid/covid-19-data/scripts/src/cowidev/vax/incremental/russia.py"", line 66, in export
    data = read(source).pipe(pipeline)
  File ""/mnt/owid_live_covid/covid-19-data/scripts/src/cowidev/vax/incremental/russia.py"", line 11, in read
    soup = get_soup(source)
  File ""/mnt/owid_live_covid/covid-19-data/scripts/src/cowidev/utils/web/scraping.py"", line 83, in get_soup
    response = get_response(source, request_method, use_proxy, **kwargs)
  File ""/mnt/owid_live_covid/covid-19-data/scripts/src/cowidev/utils/web/scraping.py"", line 52, in get_response
    raise ValueError(
ValueError: Source https://gogov.ru/articles/covid-v-stats not reached! Error code 502 Bad Gateway
",Source https://gogov.ru/articles/covid-v-stats not reached! Error code 502 Bad Gateway
cowidev.vax.incremental.saint_lucia,,,2022-10-27T07:03:13,,
cowidev.vax.incremental.serbia,5.38,True,2022-10-27T07:03:19,,
cowidev.vax.incremental.south_africa,7.36,True,2022-10-27T07:03:26,,
cowidev.vax.incremental.spain,8.8,True,2022-10-27T07:03:29,,
cowidev.vax.incremental.sri_lanka,,,2022-10-27T07:03:26,,
cowidev.vax.incremental.suriname,15.02,True,2022-10-27T07:03:41,,
cowidev.vax.incremental.taiwan,5.33,True,2022-10-27T07:03:34,,
cowidev.vax.incremental.thailand,3.65,True,2022-10-27T07:03:38,,
cowidev.vax.incremental.turkey,0.54,True,2022-10-27T07:03:38,,
cowidev.vax.incremental.united_arab_emirates,,,2022-10-27T07:03:38,,
cowidev.vax.incremental.vietnam,,,2022-10-27T07:03:38,,
cowidev.vax.incremental.who,4.69,True,2022-10-27T07:03:43,,
cowidev.vax.incremental.zambia,1.1,True,2022-10-27T07:03:41,,
