module,execution_time (sec),success,timestamp,error,error_short
cowidev.vax.batch.argentina,3.41,True,2022-11-09T07:00:13,,
cowidev.vax.batch.australia,,,2022-11-09T07:00:10,,
cowidev.vax.batch.austria,2.24,True,2022-11-09T07:00:12,,
cowidev.vax.batch.belgium,2.14,True,2022-11-09T07:00:12,,
cowidev.vax.batch.bolivia,1.8,True,2022-11-09T07:00:12,,
cowidev.vax.batch.canada,7.96,True,2022-11-09T07:00:18,,
cowidev.vax.batch.chile,0.69,True,2022-11-09T07:00:12,,
cowidev.vax.batch.czechia,4.2,True,2022-11-09T07:00:16,,
cowidev.vax.batch.denmark,6.16,True,2022-11-09T07:00:18,,
cowidev.vax.batch.ecdc,60.07,False,2022-11-09T07:06:23,"Traceback (most recent call last):
  File ""/mnt/owid_live_covid/covid-19-data/scripts/venv/lib/python3.9/site-packages/urllib3/connection.py"", line 174, in _new_conn
    conn = connection.create_connection(
  File ""/mnt/owid_live_covid/covid-19-data/scripts/venv/lib/python3.9/site-packages/urllib3/util/connection.py"", line 96, in create_connection
    raise err
  File ""/mnt/owid_live_covid/covid-19-data/scripts/venv/lib/python3.9/site-packages/urllib3/util/connection.py"", line 86, in create_connection
    sock.connect(sa)
socket.timeout: timed out

During handling of the above exception, another exception occurred:

Traceback (most recent call last):
  File ""/mnt/owid_live_covid/covid-19-data/scripts/venv/lib/python3.9/site-packages/urllib3/connectionpool.py"", line 699, in urlopen
    httplib_response = self._make_request(
  File ""/mnt/owid_live_covid/covid-19-data/scripts/venv/lib/python3.9/site-packages/urllib3/connectionpool.py"", line 382, in _make_request
    self._validate_conn(conn)
  File ""/mnt/owid_live_covid/covid-19-data/scripts/venv/lib/python3.9/site-packages/urllib3/connectionpool.py"", line 1010, in _validate_conn
    conn.connect()
  File ""/mnt/owid_live_covid/covid-19-data/scripts/venv/lib/python3.9/site-packages/urllib3/connection.py"", line 358, in connect
    conn = self._new_conn()
  File ""/mnt/owid_live_covid/covid-19-data/scripts/venv/lib/python3.9/site-packages/urllib3/connection.py"", line 179, in _new_conn
    raise ConnectTimeoutError(
urllib3.exceptions.ConnectTimeoutError: (<urllib3.connection.HTTPSConnection object at 0x7f1a8f0a9dc0>, 'Connection to opendata.ecdc.europa.eu timed out. (connect timeout=30)')

During handling of the above exception, another exception occurred:

Traceback (most recent call last):
  File ""/mnt/owid_live_covid/covid-19-data/scripts/venv/lib/python3.9/site-packages/requests/adapters.py"", line 440, in send
    resp = conn.urlopen(
  File ""/mnt/owid_live_covid/covid-19-data/scripts/venv/lib/python3.9/site-packages/urllib3/connectionpool.py"", line 755, in urlopen
    retries = retries.increment(
  File ""/mnt/owid_live_covid/covid-19-data/scripts/venv/lib/python3.9/site-packages/urllib3/util/retry.py"", line 574, in increment
    raise MaxRetryError(_pool, url, error or ResponseError(cause))
urllib3.exceptions.MaxRetryError: HTTPSConnectionPool(host='opendata.ecdc.europa.eu', port=443): Max retries exceeded with url: /covid19/vaccine_tracker/csv/data.csv (Caused by ConnectTimeoutError(<urllib3.connection.HTTPSConnection object at 0x7f1a8f0a9dc0>, 'Connection to opendata.ecdc.europa.eu timed out. (connect timeout=30)'))

During handling of the above exception, another exception occurred:

Traceback (most recent call last):
  File ""/mnt/owid_live_covid/covid-19-data/scripts/src/cowidev/cmd/commons/get.py"", line 46, in run
    module.main()
  File ""/mnt/owid_live_covid/covid-19-data/scripts/src/cowidev/vax/batch/ecdc.py"", line 498, in main
    ECDC().export()
  File ""/mnt/owid_live_covid/covid-19-data/scripts/src/cowidev/vax/batch/ecdc.py"", line 488, in export
    df = self.read().pipe(self.pipe_base)
  File ""/mnt/owid_live_covid/covid-19-data/scripts/src/cowidev/vax/batch/ecdc.py"", line 117, in read
    df = read_csv_from_url(self.source_url, timeout=30)
  File ""/mnt/owid_live_covid/covid-19-data/scripts/src/cowidev/utils/web/download.py"", line 55, in read_csv_from_url
    download_file_from_url(
  File ""/mnt/owid_live_covid/covid-19-data/scripts/src/cowidev/utils/web/download.py"", line 80, in download_file_from_url
    r = requests.get(url, stream=True, timeout=timeout, verify=verify)
  File ""/mnt/owid_live_covid/covid-19-data/scripts/venv/lib/python3.9/site-packages/requests/api.py"", line 75, in get
    return request('get', url, params=params, **kwargs)
  File ""/mnt/owid_live_covid/covid-19-data/scripts/venv/lib/python3.9/site-packages/requests/api.py"", line 61, in request
    return session.request(method=method, url=url, **kwargs)
  File ""/mnt/owid_live_covid/covid-19-data/scripts/venv/lib/python3.9/site-packages/requests/sessions.py"", line 529, in request
    resp = self.send(prep, **send_kwargs)
  File ""/mnt/owid_live_covid/covid-19-data/scripts/venv/lib/python3.9/site-packages/requests/sessions.py"", line 645, in send
    r = adapter.send(request, **kwargs)
  File ""/mnt/owid_live_covid/covid-19-data/scripts/venv/lib/python3.9/site-packages/requests/adapters.py"", line 507, in send
    raise ConnectTimeout(e, request=request)
requests.exceptions.ConnectTimeout: HTTPSConnectionPool(host='opendata.ecdc.europa.eu', port=443): Max retries exceeded with url: /covid19/vaccine_tracker/csv/data.csv (Caused by ConnectTimeoutError(<urllib3.connection.HTTPSConnection object at 0x7f1a8f0a9dc0>, 'Connection to opendata.ecdc.europa.eu timed out. (connect timeout=30)'))
","HTTPSConnectionPool(host='opendata.ecdc.europa.eu', port=443): Max retries exceeded with url: /covid19/vaccine_tracker/csv/data.csv (Caused by ConnectTimeoutError(<urllib3.connection.HTTPSConnection object at 0x7f1a8f0a9dc0>, 'Connection to opendata.ecdc.europa.eu timed out. (connect timeout=30)'))"
cowidev.vax.batch.ecuador,1.64,True,2022-11-09T07:00:15,,
cowidev.vax.batch.estonia,3.81,True,2022-11-09T07:00:19,,
cowidev.vax.batch.france,1.6,True,2022-11-09T07:00:18,,
cowidev.vax.batch.germany,1.47,True,2022-11-09T07:00:19,,
cowidev.vax.batch.greece,3.04,True,2022-11-09T07:00:21,,
cowidev.vax.batch.hong_kong,11.41,True,2022-11-09T07:00:30,,
cowidev.vax.batch.indonesia,,,2022-11-09T07:00:19,,
cowidev.vax.batch.ireland,0.38,True,2022-11-09T07:00:19,,
cowidev.vax.batch.israel,10.25,True,2022-11-09T07:00:29,,
cowidev.vax.batch.italy,10.21,True,2022-11-09T07:00:29,,
cowidev.vax.batch.japan,0.78,False,2022-11-09T07:06:24,"Traceback (most recent call last):
  File ""/mnt/owid_live_covid/covid-19-data/scripts/src/cowidev/cmd/commons/get.py"", line 46, in run
    module.main()
  File ""/mnt/owid_live_covid/covid-19-data/scripts/src/cowidev/vax/batch/japan.py"", line 236, in main
    Japan().export()
  File ""/mnt/owid_live_covid/covid-19-data/scripts/src/cowidev/vax/batch/japan.py"", line 220, in export
    df = self.read().pipe(self.pipeline_base)
  File ""/mnt/owid_live_covid/covid-19-data/scripts/src/cowidev/vax/batch/japan.py"", line 156, in read
    df_latest = self.read_latest().pipe(self.pipe_latest)
  File ""/mnt/owid_live_covid/covid-19-data/scripts/src/cowidev/vax/batch/japan.py"", line 88, in read_latest
    dfs.append(self._read_xlsx(self.source_url, self.sheets, self.metrics))
  File ""/mnt/owid_live_covid/covid-19-data/scripts/src/cowidev/vax/batch/japan.py"", line 97, in _read_xlsx
    xlsx = pd.ExcelFile(url)
  File ""/mnt/owid_live_covid/covid-19-data/scripts/venv/lib/python3.9/site-packages/pandas/io/excel/_base.py"", line 1191, in __init__
    ext = inspect_excel_format(
  File ""/mnt/owid_live_covid/covid-19-data/scripts/venv/lib/python3.9/site-packages/pandas/io/excel/_base.py"", line 1070, in inspect_excel_format
    with get_handle(
  File ""/mnt/owid_live_covid/covid-19-data/scripts/venv/lib/python3.9/site-packages/pandas/io/common.py"", line 609, in get_handle
    ioargs = _get_filepath_or_buffer(
  File ""/mnt/owid_live_covid/covid-19-data/scripts/venv/lib/python3.9/site-packages/pandas/io/common.py"", line 312, in _get_filepath_or_buffer
    with urlopen(req_info) as req:
  File ""/mnt/owid_live_covid/covid-19-data/scripts/venv/lib/python3.9/site-packages/pandas/io/common.py"", line 212, in urlopen
    return urllib.request.urlopen(*args, **kwargs)
  File ""/home/owid/.pyenv/versions/3.9.6/lib/python3.9/urllib/request.py"", line 214, in urlopen
    return opener.open(url, data, timeout)
  File ""/home/owid/.pyenv/versions/3.9.6/lib/python3.9/urllib/request.py"", line 523, in open
    response = meth(req, response)
  File ""/home/owid/.pyenv/versions/3.9.6/lib/python3.9/urllib/request.py"", line 632, in http_response
    response = self.parent.error(
  File ""/home/owid/.pyenv/versions/3.9.6/lib/python3.9/urllib/request.py"", line 561, in error
    return self._call_chain(*args)
  File ""/home/owid/.pyenv/versions/3.9.6/lib/python3.9/urllib/request.py"", line 494, in _call_chain
    result = func(*args)
  File ""/home/owid/.pyenv/versions/3.9.6/lib/python3.9/urllib/request.py"", line 641, in http_error_default
    raise HTTPError(req.full_url, code, msg, hdrs, fp)
urllib.error.HTTPError: HTTP Error 404: Not Found
",HTTP Error 404: Not Found
cowidev.vax.batch.jersey,0.63,True,2022-11-09T07:00:30,,
cowidev.vax.batch.latvia,18.47,True,2022-11-09T07:00:48,,
cowidev.vax.batch.lithuania,1.4,True,2022-11-09T07:00:31,,
cowidev.vax.batch.luxembourg,1.93,True,2022-11-09T07:00:32,,
cowidev.vax.batch.malaysia,0.93,True,2022-11-09T07:00:31,,
cowidev.vax.batch.malta,0.93,False,2022-11-09T07:06:25,"Traceback (most recent call last):
  File ""/mnt/owid_live_covid/covid-19-data/scripts/src/cowidev/cmd/commons/get.py"", line 46, in run
    module.main()
  File ""/mnt/owid_live_covid/covid-19-data/scripts/src/cowidev/vax/batch/malta.py"", line 106, in main
    Malta().export()
  File ""/mnt/owid_live_covid/covid-19-data/scripts/src/cowidev/vax/batch/malta.py"", line 101, in export
    df = self.read().pipe(self.pipeline)
  File ""/mnt/owid_live_covid/covid-19-data/scripts/src/cowidev/vax/batch/malta.py"", line 28, in read
    check_known_columns(
  File ""/mnt/owid_live_covid/covid-19-data/scripts/src/cowidev/utils/utils.py"", line 164, in check_known_columns
    raise Exception(f""Unknown column(s) found: {unknown_cols}"")
Exception: Unknown column(s) found: {'Received one dose', 'Total Omicron booster doses', 'Primary Vaccination', 'Omicron booster doses'}
","Unknown column(s) found: {'Received one dose', 'Total Omicron booster doses', 'Primary Vaccination', 'Omicron booster doses'}"
cowidev.vax.batch.netherlands,,,2022-11-09T07:00:31,,
cowidev.vax.batch.new_zealand,11.18,True,2022-11-09T07:00:42,,
cowidev.vax.batch.norway,0.46,True,2022-11-09T07:00:32,,
cowidev.vax.batch.peru,4.24,True,2022-11-09T07:00:36,,
cowidev.vax.batch.portugal,,,2022-11-09T07:00:32,,
cowidev.vax.batch.romania,14.71,True,2022-11-09T07:00:47,,
cowidev.vax.batch.saudi_arabia,10.97,True,2022-11-09T07:00:47,,
cowidev.vax.batch.singapore,3.24,True,2022-11-09T07:00:45,,
cowidev.vax.batch.slovakia,37.45,True,2022-11-09T07:01:23,,
cowidev.vax.batch.slovenia,0.54,True,2022-11-09T07:00:47,,
cowidev.vax.batch.south_korea,37.88,True,2022-11-09T07:01:25,,
cowidev.vax.batch.spc,19.31,True,2022-11-09T07:01:07,,
cowidev.vax.batch.sweden,10.28,False,2022-11-09T07:06:35,"Traceback (most recent call last):
  File ""/mnt/owid_live_covid/covid-19-data/scripts/src/cowidev/cmd/commons/get.py"", line 46, in run
    module.main()
  File ""/mnt/owid_live_covid/covid-19-data/scripts/src/cowidev/vax/batch/sweden.py"", line 244, in main
    Sweden().export()
  File ""/mnt/owid_live_covid/covid-19-data/scripts/src/cowidev/vax/batch/sweden.py"", line 238, in export
    df = self.read().pipe(self.pipeline)
  File ""/mnt/owid_live_covid/covid-19-data/scripts/venv/lib/python3.9/site-packages/pandas/core/generic.py"", line 5430, in pipe
    return com.pipe(self, func, *args, **kwargs)
  File ""/mnt/owid_live_covid/covid-19-data/scripts/venv/lib/python3.9/site-packages/pandas/core/common.py"", line 471, in pipe
    return func(obj, *args, **kwargs)
  File ""/mnt/owid_live_covid/covid-19-data/scripts/src/cowidev/vax/batch/sweden.py"", line 140, in pipeline
    df.pipe(self.pipe_vaccine)
  File ""/mnt/owid_live_covid/covid-19-data/scripts/venv/lib/python3.9/site-packages/pandas/core/generic.py"", line 5430, in pipe
    return com.pipe(self, func, *args, **kwargs)
  File ""/mnt/owid_live_covid/covid-19-data/scripts/venv/lib/python3.9/site-packages/pandas/core/common.py"", line 471, in pipe
    return func(obj, *args, **kwargs)
  File ""/mnt/owid_live_covid/covid-19-data/scripts/src/cowidev/vax/utils/utils.py"", line 44, in make_monotonic
    raise Exception(
Exception: 51 rows have been removed. That is more than maximum allowed (10) by make_monotonic() - check the data. Check 
          date location  ... people_fully_vaccinated total_boosters
46  2021-11-14   Sweden  ...                 6925338           <NA>
47  2021-11-21   Sweden  ...                 6990165           <NA>
48  2021-11-28   Sweden  ...                 7067100           <NA>
49  2021-12-05   Sweden  ...                 7138275           <NA>
50  2021-12-12   Sweden  ...                 7209137           <NA>
51  2021-12-19   Sweden  ...                 7272440           <NA>
52  2021-12-26   Sweden  ...                 7298643           <NA>
53  2022-01-02   Sweden  ...                 7315934           <NA>
54  2022-01-09   Sweden  ...                 7343045           <NA>
55  2022-01-16   Sweden  ...                 7396733           <NA>
56  2022-01-23   Sweden  ...                 7440722           <NA>
57  2022-01-30   Sweden  ...                 7467530           <NA>
58  2022-02-06   Sweden  ...                 7488672           <NA>
59  2022-02-13   Sweden  ...                 7510002           <NA>
60  2022-02-20   Sweden  ...                 7527206           <NA>
61  2022-02-27   Sweden  ...                 7541261           <NA>
62  2022-03-06   Sweden  ...                 7550484           <NA>
63  2022-03-13   Sweden  ...                 7557824           <NA>
64  2022-03-20   Sweden  ...                 7565207           <NA>
65  2022-03-27   Sweden  ...                 7570543           <NA>
66  2022-04-03   Sweden  ...                 7574808           <NA>
67  2022-04-10   Sweden  ...                 7578286           <NA>
68  2022-04-17   Sweden  ...                 7581086           <NA>
69  2022-04-24   Sweden  ...                 7584266           <NA>
70  2022-05-01   Sweden  ...                 7587569           <NA>
71  2022-05-08   Sweden  ...                 7590490           <NA>
72  2022-05-15   Sweden  ...                 7593510           <NA>
73  2022-05-22   Sweden  ...                 7596641           <NA>
74  2022-05-29   Sweden  ...                 7599524           <NA>
75  2022-06-05   Sweden  ...                 7602506           <NA>
76  2022-06-12   Sweden  ...                 7604892           <NA>
77  2022-06-19   Sweden  ...                 7607409           <NA>
78  2022-06-26   Sweden  ...                 7609221           <NA>
79  2022-07-03   Sweden  ...                 7610930           <NA>
80  2022-07-10   Sweden  ...                 7612308           <NA>
81  2022-07-17   Sweden  ...                 7613615           <NA>
82  2022-07-24   Sweden  ...                 7614651           <NA>
83  2022-07-31   Sweden  ...                 7615536           <NA>
84  2022-08-07   Sweden  ...                 7616417           <NA>
85  2022-08-14   Sweden  ...                 7617435           <NA>
86  2022-08-21   Sweden  ...                 7618460           <NA>
87  2022-08-28   Sweden  ...                 7619252           <NA>
88  2022-09-04   Sweden  ...                 7620225           <NA>
89  2022-09-11   Sweden  ...                 7621308           <NA>
90  2022-09-18   Sweden  ...                 7622495           <NA>
91  2022-09-25   Sweden  ...                 7623644           <NA>
92  2022-10-02   Sweden  ...                 7624819           <NA>
93  2022-10-09   Sweden  ...                 7625864           <NA>
94  2022-10-16   Sweden  ...                 7626821           <NA>
95  2022-10-23   Sweden  ...                 7627737           <NA>
96  2022-10-30   Sweden  ...                 7628588           <NA>

[51 rows x 8 columns]
","51 rows have been removed. That is more than maximum allowed (10) by make_monotonic() - check the data. Check 
          date location  ... people_fully_vaccinated total_boosters
46  2021-11-14   Sweden  ...                 6925338           <NA>
47  2021-11-21   Sweden  ...                 6990165           <NA>
48  2021-11-28   Sweden  ...                 7067100           <NA>
49  2021-12-05   Sweden  ...                 7138275           <NA>
50  2021-12-12   Sweden  ...                 7209137           <NA>
51  2021-12-19   Sweden  ...                 7272440           <NA>
52  2021-12-26   Sweden  ...                 7298643           <NA>
53  2022-01-02   Sweden  ...                 7315934           <NA>
54  2022-01-09   Sweden  ...                 7343045           <NA>
55  2022-01-16   Sweden  ...                 7396733           <NA>
56  2022-01-23   Sweden  ...                 7440722           <NA>
57  2022-01-30   Sweden  ...                 7467530           <NA>
58  2022-02-06   Sweden  ...                 7488672           <NA>
59  2022-02-13   Sweden  ...                 7510002           <NA>
60  2022-02-20   Sweden  ...                 7527206           <NA>
61  2022-02-27   Sweden  ...                 7541261           <NA>
62  2022-03-06   Sweden  ...                 7550484           <NA>
63  2022-03-13   Sweden  ...                 7557824           <NA>
64  2022-03-20   Sweden  ...                 7565207           <NA>
65  2022-03-27   Sweden  ...                 7570543           <NA>
66  2022-04-03   Sweden  ...                 7574808           <NA>
67  2022-04-10   Sweden  ...                 7578286           <NA>
68  2022-04-17   Sweden  ...                 7581086           <NA>
69  2022-04-24   Sweden  ...                 7584266           <NA>
70  2022-05-01   Sweden  ...                 7587569           <NA>
71  2022-05-08   Sweden  ...                 7590490           <NA>
72  2022-05-15   Sweden  ...                 7593510           <NA>
73  2022-05-22   Sweden  ...                 7596641           <NA>
74  2022-05-29   Sweden  ...                 7599524           <NA>
75  2022-06-05   Sweden  ...                 7602506           <NA>
76  2022-06-12   Sweden  ...                 7604892           <NA>
77  2022-06-19   Sweden  ...                 7607409           <NA>
78  2022-06-26   Sweden  ...                 7609221           <NA>
79  2022-07-03   Sweden  ...                 7610930           <NA>
80  2022-07-10   Sweden  ...                 7612308           <NA>
81  2022-07-17   Sweden  ...                 7613615           <NA>
82  2022-07-24   Sweden  ...                 7614651           <NA>
83  2022-07-31   Sweden  ...                 7615536           <NA>
84  2022-08-07   Sweden  ...                 7616417           <NA>
85  2022-08-14   Sweden  ...                 7617435           <NA>
86  2022-08-21   Sweden  ...                 7618460           <NA>
87  2022-08-28   Sweden  ...                 7619252           <NA>
88  2022-09-04   Sweden  ...                 7620225           <NA>
89  2022-09-11   Sweden  ...                 7621308           <NA>
90  2022-09-18   Sweden  ...                 7622495           <NA>
91  2022-09-25   Sweden  ...                 7623644           <NA>
92  2022-10-02   Sweden  ...                 7624819           <NA>
93  2022-10-09   Sweden  ...                 7625864           <NA>
94  2022-10-16   Sweden  ...                 7626821           <NA>
95  2022-10-23   Sweden  ...                 7627737           <NA>
96  2022-10-30   Sweden  ...                 7628588           <NA>

[51 rows x 8 columns]"
cowidev.vax.batch.switzerland,256.09,True,2022-11-09T07:05:23,,
cowidev.vax.batch.trinidad_and_tobago,2.69,True,2022-11-09T07:01:15,,
cowidev.vax.batch.ukraine,,,2022-11-09T07:01:15,,
cowidev.vax.batch.united_kingdom,9.01,True,2022-11-09T07:01:24,,
cowidev.vax.batch.united_states,16.34,True,2022-11-09T07:01:32,,
cowidev.vax.batch.uruguay,1.58,True,2022-11-09T07:01:24,,
cowidev.vax.batch.zimbabwe,0.33,True,2022-11-09T07:01:25,,
cowidev.vax.incremental.africacdc,,,2022-11-09T07:01:24,,
cowidev.vax.incremental.antigua_barbuda,,,2022-11-09T07:01:24,,
cowidev.vax.incremental.aruba,1.09,True,2022-11-09T07:01:26,,
cowidev.vax.incremental.azerbaijan,,,2022-11-09T07:01:25,,
cowidev.vax.incremental.bahrain,1.27,True,2022-11-09T07:01:26,,
cowidev.vax.incremental.bangladesh,20.78,True,2022-11-09T07:01:46,,
cowidev.vax.incremental.barbados,,,2022-11-09T07:01:26,,
cowidev.vax.incremental.brazil,0.15,True,2022-11-09T07:01:26,,
cowidev.vax.incremental.bulgaria,1.01,True,2022-11-09T07:01:27,,
cowidev.vax.incremental.china,30.33,True,2022-11-09T07:01:56,,
cowidev.vax.incremental.costa_rica,,,2022-11-09T07:01:27,,
cowidev.vax.incremental.croatia,0.12,True,2022-11-09T07:01:27,,
cowidev.vax.incremental.cuba,2.2,True,2022-11-09T07:01:29,,
cowidev.vax.incremental.curacao,0.39,True,2022-11-09T07:01:29,,
cowidev.vax.incremental.cyprus,0.96,True,2022-11-09T07:01:30,,
cowidev.vax.incremental.dominican_republic,8.6,True,2022-11-09T07:01:39,,
cowidev.vax.incremental.el_salvador,0.58,True,2022-11-09T07:01:32,,
cowidev.vax.incremental.faeroe_islands,0.39,True,2022-11-09T07:01:33,,
cowidev.vax.incremental.fiji,0.0,True,2022-11-09T07:01:33,,
cowidev.vax.incremental.finland,0.22,True,2022-11-09T07:01:33,,
cowidev.vax.incremental.gabon,,,2022-11-09T07:01:33,,
cowidev.vax.incremental.georgia,0.52,True,2022-11-09T07:01:33,,
cowidev.vax.incremental.greenland,0.45,False,2022-11-09T07:06:35,"Traceback (most recent call last):
  File ""/mnt/owid_live_covid/covid-19-data/scripts/src/cowidev/cmd/commons/get.py"", line 46, in run
    module.main()
  File ""/mnt/owid_live_covid/covid-19-data/scripts/src/cowidev/vax/incremental/greenland.py"", line 74, in main
    Greenland().export()
  File ""/mnt/owid_live_covid/covid-19-data/scripts/src/cowidev/vax/incremental/greenland.py"", line 61, in export
    data = self.read().pipe(self.pipeline)
  File ""/mnt/owid_live_covid/covid-19-data/scripts/src/cowidev/vax/incremental/greenland.py"", line 18, in read
    data = self._parse_data(soup)
  File ""/mnt/owid_live_covid/covid-19-data/scripts/src/cowidev/vax/incremental/greenland.py"", line 22, in _parse_data
    return {**self._parse_data_metrics(soup), **self._parse_data_date(soup)}
  File ""/mnt/owid_live_covid/covid-19-data/scripts/src/cowidev/vax/incremental/greenland.py"", line 26, in _parse_data_metrics
    dose_1 = clean_count(re.search(r""Innuttaasut ([\d\.]+)"", counters[1].parent.find_all(""dd"")[-1].text).group(1))
IndexError: list index out of range
",list index out of range
cowidev.vax.incremental.guatemala,,,2022-11-09T07:01:34,,
cowidev.vax.incremental.guernsey,1.87,False,2022-11-09T07:06:37,"Traceback (most recent call last):
  File ""/mnt/owid_live_covid/covid-19-data/scripts/src/cowidev/cmd/commons/get.py"", line 46, in run
    module.main()
  File ""/mnt/owid_live_covid/covid-19-data/scripts/src/cowidev/vax/incremental/guernsey.py"", line 61, in main
    Guernsey().export()
  File ""/mnt/owid_live_covid/covid-19-data/scripts/src/cowidev/vax/incremental/guernsey.py"", line 50, in export
    data = self.read().pipe(self.pipeline)
  File ""/mnt/owid_live_covid/covid-19-data/scripts/src/cowidev/vax/incremental/guernsey.py"", line 15, in read
    df = self.parse_data(soup)
  File ""/mnt/owid_live_covid/covid-19-data/scripts/src/cowidev/vax/incremental/guernsey.py"", line 31, in parse_data
    ds.loc[ds[0] == ""Total doses"", 1].values[0].replace(""*"", """"),
IndexError: index 0 is out of bounds for axis 0 with size 0
",index 0 is out of bounds for axis 0 with size 0
cowidev.vax.incremental.hungary,1.17,True,2022-11-09T07:01:36,,
cowidev.vax.incremental.iceland,0.75,True,2022-11-09T07:01:36,,
cowidev.vax.incremental.india,0.87,True,2022-11-09T07:01:37,,
cowidev.vax.incremental.iran,,,2022-11-09T07:01:37,,
cowidev.vax.incremental.isle_of_man,0.82,True,2022-11-09T07:01:38,,
cowidev.vax.incremental.jamaica,2.51,True,2022-11-09T07:01:41,,
cowidev.vax.incremental.kazakhstan,14.63,True,2022-11-09T07:01:54,,
cowidev.vax.incremental.kosovo,1.87,True,2022-11-09T07:01:42,,
cowidev.vax.incremental.kyrgyzstan,2.94,True,2022-11-09T07:01:45,,
cowidev.vax.incremental.laos,2.23,True,2022-11-09T07:01:48,,
cowidev.vax.incremental.macao,29.23,False,2022-11-09T07:07:06,"Traceback (most recent call last):
  File ""/mnt/owid_live_covid/covid-19-data/scripts/src/cowidev/cmd/commons/get.py"", line 46, in run
    module.main()
  File ""/mnt/owid_live_covid/covid-19-data/scripts/src/cowidev/vax/incremental/macao.py"", line 86, in main
    Macao().export()
  File ""/mnt/owid_live_covid/covid-19-data/scripts/src/cowidev/vax/incremental/macao.py"", line 72, in export
    data = self.read()
  File ""/mnt/owid_live_covid/covid-19-data/scripts/src/cowidev/vax/incremental/macao.py"", line 22, in read
    data = self._parse_data(elem)
  File ""/mnt/owid_live_covid/covid-19-data/scripts/src/cowidev/vax/incremental/macao.py"", line 50, in _parse_data
    df = self._parse_pdf_table(url)
  File ""/mnt/owid_live_covid/covid-19-data/scripts/src/cowidev/vax/incremental/macao.py"", line 33, in _parse_pdf_table
    raise ValueError(""New columns added!"")
ValueError: New columns added!
",New columns added!
cowidev.vax.incremental.moldova,,,2022-11-09T07:01:48,,
cowidev.vax.incremental.monaco,35.81,True,2022-11-09T07:02:23,,
cowidev.vax.incremental.mongolia,0.83,True,2022-11-09T07:01:54,,
cowidev.vax.incremental.montenegro,0.09,True,2022-11-09T07:01:55,,
cowidev.vax.incremental.morocco,,,2022-11-09T07:01:55,,
cowidev.vax.incremental.myanmar,,,2022-11-09T07:01:55,,
cowidev.vax.incremental.nepal,,,2022-11-09T07:01:55,,
cowidev.vax.incremental.north_macedonia,,,2022-11-09T07:01:55,,
cowidev.vax.incremental.northern_cyprus,0.83,True,2022-11-09T07:01:55,,
cowidev.vax.incremental.paho,96.76,False,2022-11-09T07:08:43,"Traceback (most recent call last):
  File ""/mnt/owid_live_covid/covid-19-data/scripts/src/cowidev/cmd/commons/get.py"", line 46, in run
    module.main()
  File ""/mnt/owid_live_covid/covid-19-data/scripts/src/cowidev/vax/incremental/paho.py"", line 191, in main
    PAHO().export()
  File ""/mnt/owid_live_covid/covid-19-data/scripts/src/cowidev/vax/incremental/paho.py"", line 186, in export
    df = self.read().pipe(self.pipeline)
  File ""/mnt/owid_live_covid/covid-19-data/scripts/venv/lib/python3.9/site-packages/pandas/core/generic.py"", line 5430, in pipe
    return com.pipe(self, func, *args, **kwargs)
  File ""/mnt/owid_live_covid/covid-19-data/scripts/venv/lib/python3.9/site-packages/pandas/core/common.py"", line 471, in pipe
    return func(obj, *args, **kwargs)
  File ""/mnt/owid_live_covid/covid-19-data/scripts/src/cowidev/vax/incremental/paho.py"", line 161, in pipeline
    df.pipe(self.pipe_check_columns)
  File ""/mnt/owid_live_covid/covid-19-data/scripts/venv/lib/python3.9/site-packages/pandas/core/generic.py"", line 5430, in pipe
    return com.pipe(self, func, *args, **kwargs)
  File ""/mnt/owid_live_covid/covid-19-data/scripts/venv/lib/python3.9/site-packages/pandas/core/common.py"", line 471, in pipe
    return func(obj, *args, **kwargs)
  File ""/mnt/owid_live_covid/covid-19-data/scripts/src/cowidev/vax/incremental/paho.py"", line 116, in pipe_check_columns
    raise ValueError(f""Missing column fields: {columns_missing}. Present columns are: {df.columns}"")
ValueError: Missing column fields: {'2nd additional dose', 'Country/ Territory', 'First dose', 'Single dose', '1st additional dose', 'Country code', 'Second dose', 'Total doses'}. Present columns are: Index(['date,location,total_vaccinations,people_vaccinated,people_fully_vaccinated,total_boosters,new_vaccinations,new_vaccinations_interpolated,new_people_vaccinated_interpolated', 'date'], dtype='object')
","Missing column fields: {'2nd additional dose', 'Country/ Territory', 'First dose', 'Single dose', '1st additional dose', 'Country code', 'Second dose', 'Total doses'}. Present columns are: Index(['date,location,total_vaccinations,people_vaccinated,people_fully_vaccinated,total_boosters,new_vaccinations,new_vaccinations_interpolated,new_people_vaccinated_interpolated', 'date'], dtype='object')"
cowidev.vax.incremental.pakistan,1.37,True,2022-11-09T07:01:58,,
cowidev.vax.incremental.philippines,,,2022-11-09T07:01:58,,
cowidev.vax.incremental.playground_mojmir,5.08,True,2022-11-09T07:02:03,,
cowidev.vax.incremental.poland,0.31,True,2022-11-09T07:02:03,,
cowidev.vax.incremental.qatar,,,2022-11-09T07:02:03,,
cowidev.vax.incremental.russia,0.5,False,2022-11-09T07:08:44,"Traceback (most recent call last):
  File ""/mnt/owid_live_covid/covid-19-data/scripts/venv/lib/python3.9/site-packages/urllib3/connectionpool.py"", line 699, in urlopen
    httplib_response = self._make_request(
  File ""/mnt/owid_live_covid/covid-19-data/scripts/venv/lib/python3.9/site-packages/urllib3/connectionpool.py"", line 445, in _make_request
    six.raise_from(e, None)
  File ""<string>"", line 3, in raise_from
  File ""/mnt/owid_live_covid/covid-19-data/scripts/venv/lib/python3.9/site-packages/urllib3/connectionpool.py"", line 440, in _make_request
    httplib_response = conn.getresponse()
  File ""/home/owid/.pyenv/versions/3.9.6/lib/python3.9/http/client.py"", line 1349, in getresponse
    response.begin()
  File ""/home/owid/.pyenv/versions/3.9.6/lib/python3.9/http/client.py"", line 316, in begin
    version, status, reason = self._read_status()
  File ""/home/owid/.pyenv/versions/3.9.6/lib/python3.9/http/client.py"", line 285, in _read_status
    raise RemoteDisconnected(""Remote end closed connection without""
http.client.RemoteDisconnected: Remote end closed connection without response

During handling of the above exception, another exception occurred:

Traceback (most recent call last):
  File ""/mnt/owid_live_covid/covid-19-data/scripts/venv/lib/python3.9/site-packages/requests/adapters.py"", line 440, in send
    resp = conn.urlopen(
  File ""/mnt/owid_live_covid/covid-19-data/scripts/venv/lib/python3.9/site-packages/urllib3/connectionpool.py"", line 755, in urlopen
    retries = retries.increment(
  File ""/mnt/owid_live_covid/covid-19-data/scripts/venv/lib/python3.9/site-packages/urllib3/util/retry.py"", line 532, in increment
    raise six.reraise(type(error), error, _stacktrace)
  File ""/mnt/owid_live_covid/covid-19-data/scripts/venv/lib/python3.9/site-packages/urllib3/packages/six.py"", line 769, in reraise
    raise value.with_traceback(tb)
  File ""/mnt/owid_live_covid/covid-19-data/scripts/venv/lib/python3.9/site-packages/urllib3/connectionpool.py"", line 699, in urlopen
    httplib_response = self._make_request(
  File ""/mnt/owid_live_covid/covid-19-data/scripts/venv/lib/python3.9/site-packages/urllib3/connectionpool.py"", line 445, in _make_request
    six.raise_from(e, None)
  File ""<string>"", line 3, in raise_from
  File ""/mnt/owid_live_covid/covid-19-data/scripts/venv/lib/python3.9/site-packages/urllib3/connectionpool.py"", line 440, in _make_request
    httplib_response = conn.getresponse()
  File ""/home/owid/.pyenv/versions/3.9.6/lib/python3.9/http/client.py"", line 1349, in getresponse
    response.begin()
  File ""/home/owid/.pyenv/versions/3.9.6/lib/python3.9/http/client.py"", line 316, in begin
    version, status, reason = self._read_status()
  File ""/home/owid/.pyenv/versions/3.9.6/lib/python3.9/http/client.py"", line 285, in _read_status
    raise RemoteDisconnected(""Remote end closed connection without""
urllib3.exceptions.ProtocolError: ('Connection aborted.', RemoteDisconnected('Remote end closed connection without response'))

During handling of the above exception, another exception occurred:

Traceback (most recent call last):
  File ""/mnt/owid_live_covid/covid-19-data/scripts/src/cowidev/cmd/commons/get.py"", line 46, in run
    module.main()
  File ""/mnt/owid_live_covid/covid-19-data/scripts/src/cowidev/vax/incremental/russia.py"", line 80, in main
    Russia().export()
  File ""/mnt/owid_live_covid/covid-19-data/scripts/src/cowidev/vax/incremental/russia.py"", line 66, in export
    data = read(source).pipe(pipeline)
  File ""/mnt/owid_live_covid/covid-19-data/scripts/src/cowidev/vax/incremental/russia.py"", line 11, in read
    soup = get_soup(source)
  File ""/mnt/owid_live_covid/covid-19-data/scripts/src/cowidev/utils/web/scraping.py"", line 83, in get_soup
    response = get_response(source, request_method, use_proxy, **kwargs)
  File ""/mnt/owid_live_covid/covid-19-data/scripts/src/cowidev/utils/web/scraping.py"", line 49, in get_response
    raise err
  File ""/mnt/owid_live_covid/covid-19-data/scripts/src/cowidev/utils/web/scraping.py"", line 43, in get_response
    response = requests.get(source, **kwargs)
  File ""/mnt/owid_live_covid/covid-19-data/scripts/venv/lib/python3.9/site-packages/requests/api.py"", line 75, in get
    return request('get', url, params=params, **kwargs)
  File ""/mnt/owid_live_covid/covid-19-data/scripts/venv/lib/python3.9/site-packages/requests/api.py"", line 61, in request
    return session.request(method=method, url=url, **kwargs)
  File ""/mnt/owid_live_covid/covid-19-data/scripts/venv/lib/python3.9/site-packages/requests/sessions.py"", line 529, in request
    resp = self.send(prep, **send_kwargs)
  File ""/mnt/owid_live_covid/covid-19-data/scripts/venv/lib/python3.9/site-packages/requests/sessions.py"", line 645, in send
    r = adapter.send(request, **kwargs)
  File ""/mnt/owid_live_covid/covid-19-data/scripts/venv/lib/python3.9/site-packages/requests/adapters.py"", line 501, in send
    raise ConnectionError(err, request=request)
requests.exceptions.ConnectionError: ('Connection aborted.', RemoteDisconnected('Remote end closed connection without response'))
","('Connection aborted.', RemoteDisconnected('Remote end closed connection without response'))"
cowidev.vax.incremental.saint_lucia,,,2022-11-09T07:02:04,,
cowidev.vax.incremental.serbia,5.96,True,2022-11-09T07:02:10,,
cowidev.vax.incremental.south_africa,8.6,True,2022-11-09T07:02:18,,
cowidev.vax.incremental.spain,12.06,True,2022-11-09T07:02:30,,
cowidev.vax.incremental.sri_lanka,,,2022-11-09T07:02:18,,
cowidev.vax.incremental.suriname,14.44,True,2022-11-09T07:02:33,,
cowidev.vax.incremental.taiwan,4.87,True,2022-11-09T07:02:28,,
cowidev.vax.incremental.thailand,3.79,True,2022-11-09T07:02:32,,
cowidev.vax.incremental.turkey,40.05,False,2022-11-09T07:09:24,"Traceback (most recent call last):
  File ""/mnt/owid_live_covid/covid-19-data/scripts/venv/lib/python3.9/site-packages/urllib3/connection.py"", line 174, in _new_conn
    conn = connection.create_connection(
  File ""/mnt/owid_live_covid/covid-19-data/scripts/venv/lib/python3.9/site-packages/urllib3/util/connection.py"", line 96, in create_connection
    raise err
  File ""/mnt/owid_live_covid/covid-19-data/scripts/venv/lib/python3.9/site-packages/urllib3/util/connection.py"", line 86, in create_connection
    sock.connect(sa)
socket.timeout: timed out

During handling of the above exception, another exception occurred:

Traceback (most recent call last):
  File ""/mnt/owid_live_covid/covid-19-data/scripts/venv/lib/python3.9/site-packages/urllib3/connectionpool.py"", line 699, in urlopen
    httplib_response = self._make_request(
  File ""/mnt/owid_live_covid/covid-19-data/scripts/venv/lib/python3.9/site-packages/urllib3/connectionpool.py"", line 382, in _make_request
    self._validate_conn(conn)
  File ""/mnt/owid_live_covid/covid-19-data/scripts/venv/lib/python3.9/site-packages/urllib3/connectionpool.py"", line 1010, in _validate_conn
    conn.connect()
  File ""/mnt/owid_live_covid/covid-19-data/scripts/venv/lib/python3.9/site-packages/urllib3/connection.py"", line 358, in connect
    conn = self._new_conn()
  File ""/mnt/owid_live_covid/covid-19-data/scripts/venv/lib/python3.9/site-packages/urllib3/connection.py"", line 179, in _new_conn
    raise ConnectTimeoutError(
urllib3.exceptions.ConnectTimeoutError: (<urllib3.connection.HTTPSConnection object at 0x7f1a8cb031c0>, 'Connection to covid19asi.saglik.gov.tr timed out. (connect timeout=20)')

During handling of the above exception, another exception occurred:

Traceback (most recent call last):
  File ""/mnt/owid_live_covid/covid-19-data/scripts/venv/lib/python3.9/site-packages/requests/adapters.py"", line 440, in send
    resp = conn.urlopen(
  File ""/mnt/owid_live_covid/covid-19-data/scripts/venv/lib/python3.9/site-packages/urllib3/connectionpool.py"", line 755, in urlopen
    retries = retries.increment(
  File ""/mnt/owid_live_covid/covid-19-data/scripts/venv/lib/python3.9/site-packages/urllib3/util/retry.py"", line 574, in increment
    raise MaxRetryError(_pool, url, error or ResponseError(cause))
urllib3.exceptions.MaxRetryError: HTTPSConnectionPool(host='covid19asi.saglik.gov.tr', port=443): Max retries exceeded with url: / (Caused by ConnectTimeoutError(<urllib3.connection.HTTPSConnection object at 0x7f1a8cb031c0>, 'Connection to covid19asi.saglik.gov.tr timed out. (connect timeout=20)'))

During handling of the above exception, another exception occurred:

Traceback (most recent call last):
  File ""/mnt/owid_live_covid/covid-19-data/scripts/src/cowidev/cmd/commons/get.py"", line 46, in run
    module.main()
  File ""/mnt/owid_live_covid/covid-19-data/scripts/src/cowidev/vax/incremental/turkey.py"", line 60, in main
    data = read(source).pipe(pipeline)
  File ""/mnt/owid_live_covid/covid-19-data/scripts/src/cowidev/vax/incremental/turkey.py"", line 19, in read
    soup = get_soup(source)
  File ""/mnt/owid_live_covid/covid-19-data/scripts/src/cowidev/utils/web/scraping.py"", line 83, in get_soup
    response = get_response(source, request_method, use_proxy, **kwargs)
  File ""/mnt/owid_live_covid/covid-19-data/scripts/src/cowidev/utils/web/scraping.py"", line 49, in get_response
    raise err
  File ""/mnt/owid_live_covid/covid-19-data/scripts/src/cowidev/utils/web/scraping.py"", line 43, in get_response
    response = requests.get(source, **kwargs)
  File ""/mnt/owid_live_covid/covid-19-data/scripts/venv/lib/python3.9/site-packages/requests/api.py"", line 75, in get
    return request('get', url, params=params, **kwargs)
  File ""/mnt/owid_live_covid/covid-19-data/scripts/venv/lib/python3.9/site-packages/requests/api.py"", line 61, in request
    return session.request(method=method, url=url, **kwargs)
  File ""/mnt/owid_live_covid/covid-19-data/scripts/venv/lib/python3.9/site-packages/requests/sessions.py"", line 529, in request
    resp = self.send(prep, **send_kwargs)
  File ""/mnt/owid_live_covid/covid-19-data/scripts/venv/lib/python3.9/site-packages/requests/sessions.py"", line 645, in send
    r = adapter.send(request, **kwargs)
  File ""/mnt/owid_live_covid/covid-19-data/scripts/venv/lib/python3.9/site-packages/requests/adapters.py"", line 507, in send
    raise ConnectTimeout(e, request=request)
requests.exceptions.ConnectTimeout: HTTPSConnectionPool(host='covid19asi.saglik.gov.tr', port=443): Max retries exceeded with url: / (Caused by ConnectTimeoutError(<urllib3.connection.HTTPSConnection object at 0x7f1a8cb031c0>, 'Connection to covid19asi.saglik.gov.tr timed out. (connect timeout=20)'))
","HTTPSConnectionPool(host='covid19asi.saglik.gov.tr', port=443): Max retries exceeded with url: / (Caused by ConnectTimeoutError(<urllib3.connection.HTTPSConnection object at 0x7f1a8cb031c0>, 'Connection to covid19asi.saglik.gov.tr timed out. (connect timeout=20)'))"
cowidev.vax.incremental.united_arab_emirates,,,2022-11-09T07:02:32,,
cowidev.vax.incremental.vietnam,,,2022-11-09T07:02:32,,
cowidev.vax.incremental.who,3.65,True,2022-11-09T07:02:36,,
cowidev.vax.incremental.zambia,1.04,True,2022-11-09T07:02:34,,
