module,execution_time (sec),success,timestamp,error,error_short
cowidev.vax.batch.argentina,16.37,True,2022-12-23T07:00:21,,
cowidev.vax.batch.australia,130.82,True,2022-12-23T07:02:16,,
cowidev.vax.batch.austria,15.25,True,2022-12-23T07:00:20,,
cowidev.vax.batch.belgium,6.23,True,2022-12-23T07:00:11,,
cowidev.vax.batch.bolivia,4.89,True,2022-12-23T07:00:10,,
cowidev.vax.batch.canada,30.7,True,2022-12-23T07:00:36,,
cowidev.vax.batch.chile,1.39,True,2022-12-23T07:00:06,,
cowidev.vax.batch.czechia,39.08,True,2022-12-23T07:00:44,,
cowidev.vax.batch.denmark,127.39,True,2022-12-23T07:02:12,,
cowidev.vax.batch.ecdc,137.84,True,2022-12-23T07:02:23,,
cowidev.vax.batch.ecuador,,,2022-12-23T07:00:05,,
cowidev.vax.batch.estonia,0.61,True,2022-12-23T07:00:06,,
cowidev.vax.batch.france,6.64,True,2022-12-23T07:00:12,,
cowidev.vax.batch.germany,0.13,True,2022-12-23T07:00:05,,
cowidev.vax.batch.greece,17.32,True,2022-12-23T07:00:22,,
cowidev.vax.batch.hong_kong,21.39,True,2022-12-23T07:00:26,,
cowidev.vax.batch.indonesia,,,2022-12-23T07:00:05,,
cowidev.vax.batch.ireland,4.05,True,2022-12-23T07:00:09,,
cowidev.vax.batch.israel,15.24,True,2022-12-23T07:00:20,,
cowidev.vax.batch.italy,10.95,True,2022-12-23T07:00:16,,
cowidev.vax.batch.japan,63.65,True,2022-12-23T07:01:09,,
cowidev.vax.batch.jersey,6.35,True,2022-12-23T07:00:11,,
cowidev.vax.batch.latvia,68.85,True,2022-12-23T07:01:14,,
cowidev.vax.batch.lithuania,5.79,True,2022-12-23T07:00:11,,
cowidev.vax.batch.luxembourg,2.94,True,2022-12-23T07:00:08,,
cowidev.vax.batch.malaysia,0.83,True,2022-12-23T07:00:06,,
cowidev.vax.batch.malta,1.15,True,2022-12-23T07:00:06,,
cowidev.vax.batch.netherlands,,,2022-12-23T07:00:05,,
cowidev.vax.batch.new_zealand,8.43,True,2022-12-23T07:00:13,,
cowidev.vax.batch.norway,0.88,True,2022-12-23T07:00:06,,
cowidev.vax.batch.peru,6.32,True,2022-12-23T07:00:11,,
cowidev.vax.batch.portugal,,,2022-12-23T07:00:05,,
cowidev.vax.batch.romania,62.38,True,2022-12-23T07:01:07,,
cowidev.vax.batch.saudi_arabia,19.82,True,2022-12-23T07:00:25,,
cowidev.vax.batch.singapore,5.46,True,2022-12-23T07:00:10,,
cowidev.vax.batch.slovakia,112.54,True,2022-12-23T07:01:58,,
cowidev.vax.batch.slovenia,3.61,True,2022-12-23T07:00:09,,
cowidev.vax.batch.south_korea,121.77,True,2022-12-23T07:02:08,,
cowidev.vax.batch.spc,26.59,True,2022-12-23T07:00:32,,
cowidev.vax.batch.sweden,20.03,True,2022-12-23T07:00:26,,
cowidev.vax.batch.switzerland,134.69,True,2022-12-23T07:02:21,,
cowidev.vax.batch.trinidad_and_tobago,3.51,True,2022-12-23T07:00:11,,
cowidev.vax.batch.ukraine,,,2022-12-23T07:00:09,,
cowidev.vax.batch.united_kingdom,17.32,True,2022-12-23T07:00:26,,
cowidev.vax.batch.united_states,134.18,True,2022-12-23T07:02:23,,
cowidev.vax.batch.uruguay,7.82,True,2022-12-23T07:00:18,,
cowidev.vax.batch.zimbabwe,2.31,True,2022-12-23T07:00:13,,
cowidev.vax.incremental.africacdc,,,2022-12-23T07:00:11,,
cowidev.vax.incremental.antigua_barbuda,,,2022-12-23T07:00:11,,
cowidev.vax.incremental.aruba,1.49,True,2022-12-23T07:00:12,,
cowidev.vax.incremental.azerbaijan,,,2022-12-23T07:00:11,,
cowidev.vax.incremental.bahrain,2.0,False,2022-12-23T07:03:53,"Traceback (most recent call last):
  File ""/home/owid/covid-19-data/scripts/src/cowidev/cmd/commons/get.py"", line 46, in run
    module.main()
  File ""/home/owid/covid-19-data/scripts/src/cowidev/vax/incremental/bahrain.py"", line 84, in main
    Bahrain().export()
  File ""/home/owid/covid-19-data/scripts/src/cowidev/vax/incremental/bahrain.py"", line 70, in export
    data = self.read().pipe(self.pipeline)
  File ""/home/owid/covid-19-data/scripts/src/cowidev/vax/incremental/bahrain.py"", line 16, in read
    return self._parse_data(soup)
  File ""/home/owid/covid-19-data/scripts/src/cowidev/vax/incremental/bahrain.py"", line 19, in _parse_data
    people_vaccinated = int(soup.find_all(class_=""count"")[0][""data-count""])
IndexError: list index out of range
",list index out of range
cowidev.vax.incremental.bangladesh,37.49,True,2022-12-23T07:00:49,,
cowidev.vax.incremental.barbados,,,2022-12-23T07:00:11,,
cowidev.vax.incremental.brazil,1.12,True,2022-12-23T07:00:12,,
cowidev.vax.incremental.bulgaria,12.25,True,2022-12-23T07:00:24,,
cowidev.vax.incremental.china,30.66,True,2022-12-23T07:00:42,,
cowidev.vax.incremental.costa_rica,,,2022-12-23T07:00:12,,
cowidev.vax.incremental.croatia,0.83,True,2022-12-23T07:00:13,,
cowidev.vax.incremental.cuba,18.67,True,2022-12-23T07:00:31,,
cowidev.vax.incremental.curacao,1.08,True,2022-12-23T07:00:14,,
cowidev.vax.incremental.cyprus,3.7,True,2022-12-23T07:00:17,,
cowidev.vax.incremental.dominican_republic,22.62,False,2022-12-23T07:04:16,"Traceback (most recent call last):
  File ""/home/owid/covid-19-data/scripts/src/cowidev/cmd/commons/get.py"", line 46, in run
    module.main()
  File ""/home/owid/covid-19-data/scripts/src/cowidev/vax/incremental/dominican_republic.py"", line 113, in main
    DominicanRepublic().export()
  File ""/home/owid/covid-19-data/scripts/src/cowidev/vax/incremental/dominican_republic.py"", line 68, in export
    data = self.read().pipe(self.pipeline)
  File ""/home/owid/covid-19-data/scripts/src/cowidev/vax/incremental/dominican_republic.py"", line 26, in read
    metrics = self._parse_metrics(driver)
  File ""/home/owid/covid-19-data/scripts/src/cowidev/vax/incremental/dominican_republic.py"", line 35, in _parse_metrics
    metric_candidates = _find_potential_metrics(driver)
  File ""/home/owid/covid-19-data/scripts/src/cowidev/vax/incremental/dominican_republic.py"", line 92, in _find_potential_metrics
    h3 = _find_h3(driver)
  File ""/home/owid/covid-19-data/scripts/src/cowidev/vax/incremental/dominican_republic.py"", line 82, in _find_h3
    raise ValueError(""More than one element found!"")
ValueError: More than one element found!
",More than one element found!
cowidev.vax.incremental.el_salvador,15.69,True,2022-12-23T07:00:30,,
cowidev.vax.incremental.faeroe_islands,1.56,True,2022-12-23T07:00:18,,
cowidev.vax.incremental.fiji,0.0,True,2022-12-23T07:00:17,,
cowidev.vax.incremental.finland,0.9,True,2022-12-23T07:00:18,,
cowidev.vax.incremental.gabon,,,2022-12-23T07:00:18,,
cowidev.vax.incremental.georgia,10.07,True,2022-12-23T07:00:28,,
cowidev.vax.incremental.greenland,5.63,True,2022-12-23T07:00:23,,
cowidev.vax.incremental.guatemala,,,2022-12-23T07:00:18,,
cowidev.vax.incremental.guernsey,11.85,True,2022-12-23T07:00:30,,
cowidev.vax.incremental.hungary,7.79,True,2022-12-23T07:00:28,,
cowidev.vax.incremental.iceland,5.41,True,2022-12-23T07:00:26,,
cowidev.vax.incremental.india,3.53,True,2022-12-23T07:00:25,,
cowidev.vax.incremental.iran,,,2022-12-23T07:00:22,,
cowidev.vax.incremental.isle_of_man,2.46,True,2022-12-23T07:00:25,,
cowidev.vax.incremental.jamaica,9.39,True,2022-12-23T07:00:33,,
cowidev.vax.incremental.kazakhstan,7.34,True,2022-12-23T07:00:31,,
cowidev.vax.incremental.kosovo,7.07,False,2022-12-23T07:04:23,"Traceback (most recent call last):
  File ""/home/owid/covid-19-data/scripts/src/cowidev/cmd/commons/get.py"", line 46, in run
    module.main()
  File ""/home/owid/covid-19-data/scripts/src/cowidev/vax/incremental/kosovo.py"", line 82, in main
    Kosovo().export()
  File ""/home/owid/covid-19-data/scripts/src/cowidev/vax/incremental/kosovo.py"", line 77, in export
    df = self.read().pipe(self.pipeline)
  File ""/home/owid/covid-19-data/scripts/src/cowidev/vax/incremental/kosovo.py"", line 23, in read
    df = self._parse_data(soup)
  File ""/home/owid/covid-19-data/scripts/src/cowidev/vax/incremental/kosovo.py"", line 32, in _parse_data
    soup = get_soup(link, verify=False)
  File ""/home/owid/covid-19-data/scripts/src/cowidev/utils/web/scraping.py"", line 83, in get_soup
    response = get_response(source, request_method, use_proxy, **kwargs)
  File ""/home/owid/covid-19-data/scripts/src/cowidev/utils/web/scraping.py"", line 52, in get_response
    raise ValueError(
ValueError: Source https://msh.rks-gov.net/10.230.0.57+9000/coviddashboard.html not reached! Error code 404 Not Found
",Source https://msh.rks-gov.net/10.230.0.57+9000/coviddashboard.html not reached! Error code 404 Not Found
cowidev.vax.incremental.kyrgyzstan,5.2,True,2022-12-23T07:00:30,,
cowidev.vax.incremental.laos,8.05,True,2022-12-23T07:00:33,,
cowidev.vax.incremental.macao,10.85,True,2022-12-23T07:00:36,,
cowidev.vax.incremental.moldova,,,2022-12-23T07:00:26,,
cowidev.vax.incremental.monaco,124.19,True,2022-12-23T07:02:30,,
cowidev.vax.incremental.mongolia,1.6,True,2022-12-23T07:00:28,,
cowidev.vax.incremental.montenegro,1.01,True,2022-12-23T07:00:27,,
cowidev.vax.incremental.morocco,,,2022-12-23T07:00:26,,
cowidev.vax.incremental.myanmar,,,2022-12-23T07:00:26,,
cowidev.vax.incremental.nepal,,,2022-12-23T07:00:26,,
cowidev.vax.incremental.north_macedonia,,,2022-12-23T07:00:26,,
cowidev.vax.incremental.northern_cyprus,5.75,True,2022-12-23T07:00:32,,
cowidev.vax.incremental.paho,136.97,False,2022-12-23T07:06:40,"Traceback (most recent call last):
  File ""/home/owid/covid-19-data/scripts/src/cowidev/cmd/commons/get.py"", line 46, in run
    module.main()
  File ""/home/owid/covid-19-data/scripts/src/cowidev/vax/incremental/paho.py"", line 195, in main
    PAHO().export()
  File ""/home/owid/covid-19-data/scripts/src/cowidev/vax/incremental/paho.py"", line 190, in export
    df = self.read().pipe(self.pipeline)
  File ""/home/owid/covid-19-data/scripts/src/cowidev/vax/incremental/paho.py"", line 37, in read
    df = self._parse_data(url)
  File ""/home/owid/covid-19-data/scripts/src/cowidev/vax/incremental/paho.py"", line 64, in _parse_data
    filename = self._get_downloaded_filename()
  File ""/home/owid/covid-19-data/scripts/src/cowidev/vax/incremental/paho.py"", line 116, in _get_downloaded_filename
    return max(files, key=os.path.getctime)
ValueError: max() arg is an empty sequence
",max() arg is an empty sequence
cowidev.vax.incremental.pakistan,0.93,False,2022-12-23T07:06:41,"Traceback (most recent call last):
  File ""/home/owid/covid-19-data/scripts/venv/lib/python3.10/site-packages/urllib3/connectionpool.py"", line 703, in urlopen
    httplib_response = self._make_request(
  File ""/home/owid/covid-19-data/scripts/venv/lib/python3.10/site-packages/urllib3/connectionpool.py"", line 386, in _make_request
    self._validate_conn(conn)
  File ""/home/owid/covid-19-data/scripts/venv/lib/python3.10/site-packages/urllib3/connectionpool.py"", line 1042, in _validate_conn
    conn.connect()
  File ""/home/owid/covid-19-data/scripts/venv/lib/python3.10/site-packages/urllib3/connection.py"", line 414, in connect
    self.sock = ssl_wrap_socket(
  File ""/home/owid/covid-19-data/scripts/venv/lib/python3.10/site-packages/urllib3/util/ssl_.py"", line 449, in ssl_wrap_socket
    ssl_sock = _ssl_wrap_socket_impl(
  File ""/home/owid/covid-19-data/scripts/venv/lib/python3.10/site-packages/urllib3/util/ssl_.py"", line 493, in _ssl_wrap_socket_impl
    return ssl_context.wrap_socket(sock, server_hostname=server_hostname)
  File ""/usr/lib/python3.10/ssl.py"", line 513, in wrap_socket
    return self.sslsocket_class._create(
  File ""/usr/lib/python3.10/ssl.py"", line 1071, in _create
    self.do_handshake()
  File ""/usr/lib/python3.10/ssl.py"", line 1342, in do_handshake
    self._sslobj.do_handshake()
ssl.SSLCertVerificationError: [SSL: CERTIFICATE_VERIFY_FAILED] certificate verify failed: certificate has expired (_ssl.c:997)

During handling of the above exception, another exception occurred:

Traceback (most recent call last):
  File ""/home/owid/covid-19-data/scripts/venv/lib/python3.10/site-packages/requests/adapters.py"", line 440, in send
    resp = conn.urlopen(
  File ""/home/owid/covid-19-data/scripts/venv/lib/python3.10/site-packages/urllib3/connectionpool.py"", line 787, in urlopen
    retries = retries.increment(
  File ""/home/owid/covid-19-data/scripts/venv/lib/python3.10/site-packages/urllib3/util/retry.py"", line 592, in increment
    raise MaxRetryError(_pool, url, error or ResponseError(cause))
urllib3.exceptions.MaxRetryError: HTTPSConnectionPool(host='covid.gov.pk', port=443): Max retries exceeded with url: /vaccine-details (Caused by SSLError(SSLCertVerificationError(1, '[SSL: CERTIFICATE_VERIFY_FAILED] certificate verify failed: certificate has expired (_ssl.c:997)')))

During handling of the above exception, another exception occurred:

Traceback (most recent call last):
  File ""/home/owid/covid-19-data/scripts/src/cowidev/cmd/commons/get.py"", line 46, in run
    module.main()
  File ""/home/owid/covid-19-data/scripts/src/cowidev/vax/incremental/pakistan.py"", line 58, in main
    Pakistan().export()
  File ""/home/owid/covid-19-data/scripts/src/cowidev/vax/incremental/pakistan.py"", line 53, in export
    data = self.read().pipe(self.pipeline)
  File ""/home/owid/covid-19-data/scripts/src/cowidev/vax/incremental/pakistan.py"", line 17, in read
    soup = get_soup(self.source_url)
  File ""/home/owid/covid-19-data/scripts/src/cowidev/utils/web/scraping.py"", line 83, in get_soup
    response = get_response(source, request_method, use_proxy, **kwargs)
  File ""/home/owid/covid-19-data/scripts/src/cowidev/utils/web/scraping.py"", line 49, in get_response
    raise err
  File ""/home/owid/covid-19-data/scripts/src/cowidev/utils/web/scraping.py"", line 43, in get_response
    response = requests.get(source, **kwargs)
  File ""/home/owid/covid-19-data/scripts/venv/lib/python3.10/site-packages/requests/api.py"", line 75, in get
    return request('get', url, params=params, **kwargs)
  File ""/home/owid/covid-19-data/scripts/venv/lib/python3.10/site-packages/requests/api.py"", line 61, in request
    return session.request(method=method, url=url, **kwargs)
  File ""/home/owid/covid-19-data/scripts/venv/lib/python3.10/site-packages/requests/sessions.py"", line 529, in request
    resp = self.send(prep, **send_kwargs)
  File ""/home/owid/covid-19-data/scripts/venv/lib/python3.10/site-packages/requests/sessions.py"", line 645, in send
    r = adapter.send(request, **kwargs)
  File ""/home/owid/covid-19-data/scripts/venv/lib/python3.10/site-packages/requests/adapters.py"", line 517, in send
    raise SSLError(e, request=request)
requests.exceptions.SSLError: HTTPSConnectionPool(host='covid.gov.pk', port=443): Max retries exceeded with url: /vaccine-details (Caused by SSLError(SSLCertVerificationError(1, '[SSL: CERTIFICATE_VERIFY_FAILED] certificate verify failed: certificate has expired (_ssl.c:997)')))
","HTTPSConnectionPool(host='covid.gov.pk', port=443): Max retries exceeded with url: /vaccine-details (Caused by SSLError(SSLCertVerificationError(1, '[SSL: CERTIFICATE_VERIFY_FAILED] certificate verify failed: certificate has expired (_ssl.c:997)')))"
cowidev.vax.incremental.philippines,,,2022-12-23T07:00:28,,
cowidev.vax.incremental.poland,1.56,True,2022-12-23T07:00:29,,
cowidev.vax.incremental.qatar,,,2022-12-23T07:00:28,,
cowidev.vax.incremental.russia,50.02,True,2022-12-23T07:01:18,,
cowidev.vax.incremental.saint_lucia,,,2022-12-23T07:00:29,,
cowidev.vax.incremental.serbia,0.43,False,2022-12-23T07:06:41,"Traceback (most recent call last):
  File ""/home/owid/covid-19-data/scripts/src/cowidev/cmd/commons/get.py"", line 46, in run
    module.main()
  File ""/home/owid/covid-19-data/scripts/src/cowidev/vax/incremental/serbia.py"", line 88, in main
    Serbia().export()
  File ""/home/owid/covid-19-data/scripts/src/cowidev/vax/incremental/serbia.py"", line 74, in export
    data = self.read().pipe(self.pipeline)
  File ""/home/owid/covid-19-data/scripts/src/cowidev/vax/incremental/serbia.py"", line 23, in read
    soup = get_soup(self.source_url)
  File ""/home/owid/covid-19-data/scripts/src/cowidev/utils/web/scraping.py"", line 83, in get_soup
    response = get_response(source, request_method, use_proxy, **kwargs)
  File ""/home/owid/covid-19-data/scripts/src/cowidev/utils/web/scraping.py"", line 52, in get_response
    raise ValueError(
ValueError: Source https://vakcinacija.gov.rs/ not reached! Error code 503 Service Unavailable
",Source https://vakcinacija.gov.rs/ not reached! Error code 503 Service Unavailable
cowidev.vax.incremental.south_africa,11.28,True,2022-12-23T07:00:41,,
cowidev.vax.incremental.spain,24.26,True,2022-12-23T07:00:54,,
cowidev.vax.incremental.sri_lanka,,,2022-12-23T07:00:30,,
cowidev.vax.incremental.suriname,15.17,True,2022-12-23T07:00:45,,
cowidev.vax.incremental.taiwan,20.45,True,2022-12-23T07:00:50,,
cowidev.vax.incremental.thailand,8.04,True,2022-12-23T07:00:38,,
cowidev.vax.incremental.turkey,40.05,False,2022-12-23T07:07:21,"Traceback (most recent call last):
  File ""/home/owid/covid-19-data/scripts/venv/lib/python3.10/site-packages/urllib3/connection.py"", line 174, in _new_conn
    conn = connection.create_connection(
  File ""/home/owid/covid-19-data/scripts/venv/lib/python3.10/site-packages/urllib3/util/connection.py"", line 95, in create_connection
    raise err
  File ""/home/owid/covid-19-data/scripts/venv/lib/python3.10/site-packages/urllib3/util/connection.py"", line 85, in create_connection
    sock.connect(sa)
TimeoutError: timed out

During handling of the above exception, another exception occurred:

Traceback (most recent call last):
  File ""/home/owid/covid-19-data/scripts/venv/lib/python3.10/site-packages/urllib3/connectionpool.py"", line 703, in urlopen
    httplib_response = self._make_request(
  File ""/home/owid/covid-19-data/scripts/venv/lib/python3.10/site-packages/urllib3/connectionpool.py"", line 386, in _make_request
    self._validate_conn(conn)
  File ""/home/owid/covid-19-data/scripts/venv/lib/python3.10/site-packages/urllib3/connectionpool.py"", line 1042, in _validate_conn
    conn.connect()
  File ""/home/owid/covid-19-data/scripts/venv/lib/python3.10/site-packages/urllib3/connection.py"", line 358, in connect
    self.sock = conn = self._new_conn()
  File ""/home/owid/covid-19-data/scripts/venv/lib/python3.10/site-packages/urllib3/connection.py"", line 179, in _new_conn
    raise ConnectTimeoutError(
urllib3.exceptions.ConnectTimeoutError: (<urllib3.connection.HTTPSConnection object at 0x7f092cd3d420>, 'Connection to covid19asi.saglik.gov.tr timed out. (connect timeout=20)')

During handling of the above exception, another exception occurred:

Traceback (most recent call last):
  File ""/home/owid/covid-19-data/scripts/venv/lib/python3.10/site-packages/requests/adapters.py"", line 440, in send
    resp = conn.urlopen(
  File ""/home/owid/covid-19-data/scripts/venv/lib/python3.10/site-packages/urllib3/connectionpool.py"", line 787, in urlopen
    retries = retries.increment(
  File ""/home/owid/covid-19-data/scripts/venv/lib/python3.10/site-packages/urllib3/util/retry.py"", line 592, in increment
    raise MaxRetryError(_pool, url, error or ResponseError(cause))
urllib3.exceptions.MaxRetryError: HTTPSConnectionPool(host='covid19asi.saglik.gov.tr', port=443): Max retries exceeded with url: / (Caused by ConnectTimeoutError(<urllib3.connection.HTTPSConnection object at 0x7f092cd3d420>, 'Connection to covid19asi.saglik.gov.tr timed out. (connect timeout=20)'))

During handling of the above exception, another exception occurred:

Traceback (most recent call last):
  File ""/home/owid/covid-19-data/scripts/src/cowidev/cmd/commons/get.py"", line 46, in run
    module.main()
  File ""/home/owid/covid-19-data/scripts/src/cowidev/vax/incremental/turkey.py"", line 60, in main
    data = read(source).pipe(pipeline)
  File ""/home/owid/covid-19-data/scripts/src/cowidev/vax/incremental/turkey.py"", line 19, in read
    soup = get_soup(source)
  File ""/home/owid/covid-19-data/scripts/src/cowidev/utils/web/scraping.py"", line 83, in get_soup
    response = get_response(source, request_method, use_proxy, **kwargs)
  File ""/home/owid/covid-19-data/scripts/src/cowidev/utils/web/scraping.py"", line 49, in get_response
    raise err
  File ""/home/owid/covid-19-data/scripts/src/cowidev/utils/web/scraping.py"", line 43, in get_response
    response = requests.get(source, **kwargs)
  File ""/home/owid/covid-19-data/scripts/venv/lib/python3.10/site-packages/requests/api.py"", line 75, in get
    return request('get', url, params=params, **kwargs)
  File ""/home/owid/covid-19-data/scripts/venv/lib/python3.10/site-packages/requests/api.py"", line 61, in request
    return session.request(method=method, url=url, **kwargs)
  File ""/home/owid/covid-19-data/scripts/venv/lib/python3.10/site-packages/requests/sessions.py"", line 529, in request
    resp = self.send(prep, **send_kwargs)
  File ""/home/owid/covid-19-data/scripts/venv/lib/python3.10/site-packages/requests/sessions.py"", line 645, in send
    r = adapter.send(request, **kwargs)
  File ""/home/owid/covid-19-data/scripts/venv/lib/python3.10/site-packages/requests/adapters.py"", line 507, in send
    raise ConnectTimeout(e, request=request)
requests.exceptions.ConnectTimeout: HTTPSConnectionPool(host='covid19asi.saglik.gov.tr', port=443): Max retries exceeded with url: / (Caused by ConnectTimeoutError(<urllib3.connection.HTTPSConnection object at 0x7f092cd3d420>, 'Connection to covid19asi.saglik.gov.tr timed out. (connect timeout=20)'))
","HTTPSConnectionPool(host='covid19asi.saglik.gov.tr', port=443): Max retries exceeded with url: / (Caused by ConnectTimeoutError(<urllib3.connection.HTTPSConnection object at 0x7f092cd3d420>, 'Connection to covid19asi.saglik.gov.tr timed out. (connect timeout=20)'))"
cowidev.vax.incremental.united_arab_emirates,,,2022-12-23T07:00:31,,
cowidev.vax.incremental.vietnam,,,2022-12-23T07:00:31,,
cowidev.vax.incremental.who,71.62,True,2022-12-23T07:01:43,,
cowidev.vax.incremental.zambia,1.1,False,2022-12-23T07:07:22,"Traceback (most recent call last):
  File ""/home/owid/covid-19-data/scripts/src/cowidev/cmd/commons/get.py"", line 46, in run
    module.main()
  File ""/home/owid/covid-19-data/scripts/src/cowidev/vax/incremental/zambia.py"", line 75, in main
    Zambia().export()
  File ""/home/owid/covid-19-data/scripts/src/cowidev/vax/incremental/zambia.py"", line 70, in export
    df = self.read().pipe(self.pipeline)
  File ""/home/owid/covid-19-data/scripts/venv/lib/python3.10/site-packages/pandas/core/generic.py"", line 5430, in pipe
    return com.pipe(self, func, *args, **kwargs)
  File ""/home/owid/covid-19-data/scripts/venv/lib/python3.10/site-packages/pandas/core/common.py"", line 471, in pipe
    return func(obj, *args, **kwargs)
  File ""/home/owid/covid-19-data/scripts/src/cowidev/vax/incremental/zambia.py"", line 66, in pipeline
    .pipe(self.pipe_filter_dp)
  File ""/home/owid/covid-19-data/scripts/venv/lib/python3.10/site-packages/pandas/core/generic.py"", line 5430, in pipe
    return com.pipe(self, func, *args, **kwargs)
  File ""/home/owid/covid-19-data/scripts/venv/lib/python3.10/site-packages/pandas/core/common.py"", line 471, in pipe
    return func(obj, *args, **kwargs)
  File ""/home/owid/covid-19-data/scripts/src/cowidev/vax/incremental/zambia.py"", line 50, in pipe_filter_dp
    if df.loc[msk, ""total_vaccinations""].item() > 80e6:
  File ""/home/owid/covid-19-data/scripts/venv/lib/python3.10/site-packages/pandas/core/base.py"", line 331, in item
    raise ValueError(""can only convert an array of size 1 to a Python scalar"")
ValueError: can only convert an array of size 1 to a Python scalar
",can only convert an array of size 1 to a Python scalar
