module,execution_time (sec),success,timestamp,error,error_short
cowidev.vax.batch.argentina,16.4,True,2023-01-29T07:00:22,,
cowidev.vax.batch.australia,110.29,True,2023-01-29T07:01:55,,
cowidev.vax.batch.austria,12.89,True,2023-01-29T07:00:18,,
cowidev.vax.batch.belgium,15.82,True,2023-01-29T07:00:21,,
cowidev.vax.batch.bolivia,4.38,True,2023-01-29T07:00:09,,
cowidev.vax.batch.canada,6.93,False,2023-01-29T07:03:38,"Traceback (most recent call last):
  File ""/home/owid/covid-19-data/scripts/src/cowidev/cmd/commons/get.py"", line 46, in run
    module.main()
  File ""/home/owid/covid-19-data/scripts/src/cowidev/vax/batch/canada.py"", line 282, in main
    Canada().export()
  File ""/home/owid/covid-19-data/scripts/src/cowidev/vax/batch/canada.py"", line 266, in export
    df, df_age, df_man = self.read(), self.read_age(), self.read_manufacturer()
  File ""/home/owid/covid-19-data/scripts/src/cowidev/vax/batch/canada.py"", line 103, in read_age
    check_known_columns(
  File ""/home/owid/covid-19-data/scripts/src/cowidev/utils/utils.py"", line 164, in check_known_columns
    raise Exception(f""Unknown column(s) found: {unknown_cols}"")
Exception: Unknown column(s) found: {'Unnamed: 19', 'Unnamed: 22', 'Unnamed: 21', 'Unnamed: 24', 'Unnamed: 18', 'Unnamed: 20', 'Unnamed: 23'}
","Unknown column(s) found: {'Unnamed: 19', 'Unnamed: 22', 'Unnamed: 21', 'Unnamed: 24', 'Unnamed: 18', 'Unnamed: 20', 'Unnamed: 23'}"
cowidev.vax.batch.chile,0.87,True,2023-01-29T07:00:06,,
cowidev.vax.batch.czechia,43.94,True,2023-01-29T07:00:49,,
cowidev.vax.batch.denmark,108.67,True,2023-01-29T07:01:54,,
cowidev.vax.batch.ecdc,117.66,True,2023-01-29T07:02:03,,
cowidev.vax.batch.ecuador,,,2023-01-29T07:00:05,,
cowidev.vax.batch.estonia,0.74,True,2023-01-29T07:00:06,,
cowidev.vax.batch.france,7.4,True,2023-01-29T07:00:13,,
cowidev.vax.batch.germany,0.21,True,2023-01-29T07:00:05,,
cowidev.vax.batch.greece,19.14,True,2023-01-29T07:00:24,,
cowidev.vax.batch.hong_kong,2.58,False,2023-01-29T07:03:41,"Traceback (most recent call last):
  File ""/home/owid/covid-19-data/scripts/src/cowidev/cmd/commons/get.py"", line 46, in run
    module.main()
  File ""/home/owid/covid-19-data/scripts/src/cowidev/vax/batch/hong_kong.py"", line 214, in main
    HongKong().export()
  File ""/home/owid/covid-19-data/scripts/src/cowidev/vax/batch/hong_kong.py"", line 196, in export
    self.check_number_age_groups_latest(df_base)
  File ""/home/owid/covid-19-data/scripts/src/cowidev/vax/batch/hong_kong.py"", line 191, in check_number_age_groups_latest
    raise ValueError(f""Missing age groups! Check dates {wrong_rows.index.tolist()}"")
ValueError: Missing age groups! Check dates ['2023-01-22']
",Missing age groups! Check dates ['2023-01-22']
cowidev.vax.batch.indonesia,,,2023-01-29T07:00:05,,
cowidev.vax.batch.ireland,3.89,True,2023-01-29T07:00:09,,
cowidev.vax.batch.israel,9.94,True,2023-01-29T07:00:15,,
cowidev.vax.batch.italy,9.19,True,2023-01-29T07:00:14,,
cowidev.vax.batch.japan,47.73,True,2023-01-29T07:00:53,,
cowidev.vax.batch.jersey,5.15,True,2023-01-29T07:00:10,,
cowidev.vax.batch.latvia,13.5,False,2023-01-29T07:03:54,"Traceback (most recent call last):
  File ""/home/owid/covid-19-data/scripts/src/cowidev/cmd/commons/get.py"", line 46, in run
    module.main()
  File ""/home/owid/covid-19-data/scripts/src/cowidev/vax/batch/latvia.py"", line 180, in main
    Latvia().export()
  File ""/home/owid/covid-19-data/scripts/src/cowidev/vax/batch/latvia.py"", line 164, in export
    df = self.from_ice()  # temporary
  File ""/home/owid/covid-19-data/scripts/src/cowidev/vax/utils/base.py"", line 63, in from_ice
    _check_last_update(path, self.location)
  File ""/home/owid/covid-19-data/scripts/src/cowidev/vax/utils/base.py"", line 386, in _check_last_update
    metadata = S3().get_metadata(path)
  File ""/home/owid/covid-19-data/scripts/src/cowidev/utils/s3.py"", line 168, in get_metadata
    response = self.client.head_object(Bucket=bucket_name, Key=s3_file)
  File ""/home/owid/covid-19-data/scripts/venv/lib/python3.10/site-packages/botocore/client.py"", line 388, in _api_call
    return self._make_api_call(operation_name, kwargs)
  File ""/home/owid/covid-19-data/scripts/venv/lib/python3.10/site-packages/botocore/client.py"", line 708, in _make_api_call
    raise error_class(parsed_response, operation_name)
botocore.exceptions.ClientError: An error occurred (503) when calling the HeadObject operation (reached max retries: 4): Service Unavailable
",An error occurred (503) when calling the HeadObject operation (reached max retries: 4): Service Unavailable
cowidev.vax.batch.lithuania,5.32,True,2023-01-29T07:00:10,,
cowidev.vax.batch.luxembourg,2.65,True,2023-01-29T07:00:08,,
cowidev.vax.batch.malaysia,0.77,True,2023-01-29T07:00:06,,
cowidev.vax.batch.malta,1.21,True,2023-01-29T07:00:06,,
cowidev.vax.batch.netherlands,,,2023-01-29T07:00:05,,
cowidev.vax.batch.new_zealand,13.57,True,2023-01-29T07:00:19,,
cowidev.vax.batch.norway,0.54,True,2023-01-29T07:00:06,,
cowidev.vax.batch.peru,5.58,True,2023-01-29T07:00:11,,
cowidev.vax.batch.portugal,,,2023-01-29T07:00:05,,
cowidev.vax.batch.romania,52.85,True,2023-01-29T07:00:58,,
cowidev.vax.batch.saudi_arabia,17.0,True,2023-01-29T07:00:22,,
cowidev.vax.batch.singapore,5.13,True,2023-01-29T07:00:10,,
cowidev.vax.batch.slovakia,84.69,True,2023-01-29T07:01:30,,
cowidev.vax.batch.slovenia,2.7,True,2023-01-29T07:00:08,,
cowidev.vax.batch.south_korea,106.75,True,2023-01-29T07:01:53,,
cowidev.vax.batch.spc,33.51,True,2023-01-29T07:00:39,,
cowidev.vax.batch.sweden,18.67,True,2023-01-29T07:00:25,,
cowidev.vax.batch.switzerland,114.74,True,2023-01-29T07:02:01,,
cowidev.vax.batch.trinidad_and_tobago,2.73,True,2023-01-29T07:00:10,,
cowidev.vax.batch.ukraine,,,2023-01-29T07:00:08,,
cowidev.vax.batch.united_kingdom,18.44,True,2023-01-29T07:00:27,,
cowidev.vax.batch.united_states,114.53,True,2023-01-29T07:02:04,,
cowidev.vax.batch.uruguay,9.15,True,2023-01-29T07:00:19,,
cowidev.vax.batch.zimbabwe,2.53,True,2023-01-29T07:00:13,,
cowidev.vax.incremental.africacdc,,,2023-01-29T07:00:10,,
cowidev.vax.incremental.antigua_barbuda,,,2023-01-29T07:00:10,,
cowidev.vax.incremental.aruba,2.02,True,2023-01-29T07:00:12,,
cowidev.vax.incremental.azerbaijan,,,2023-01-29T07:00:10,,
cowidev.vax.incremental.bahrain,,,2023-01-29T07:00:10,,
cowidev.vax.incremental.bangladesh,54.96,True,2023-01-29T07:01:05,,
cowidev.vax.incremental.barbados,,,2023-01-29T07:00:10,,
cowidev.vax.incremental.brazil,2.11,True,2023-01-29T07:00:13,,
cowidev.vax.incremental.bulgaria,11.14,True,2023-01-29T07:00:22,,
cowidev.vax.incremental.china,58.37,False,2023-01-29T07:04:53,"Traceback (most recent call last):
  File ""/home/owid/covid-19-data/scripts/src/cowidev/cmd/commons/get.py"", line 46, in run
    module.main()
  File ""/home/owid/covid-19-data/scripts/src/cowidev/vax/incremental/china.py"", line 186, in main
    China().export()
  File ""/home/owid/covid-19-data/scripts/src/cowidev/vax/incremental/china.py"", line 174, in export
    df_complete = self.read_complete()
  File ""/home/owid/covid-19-data/scripts/src/cowidev/vax/incremental/china.py"", line 90, in read_complete
    data_ = self._parse_data_complete(driver, link)
  File ""/home/owid/covid-19-data/scripts/src/cowidev/vax/incremental/china.py"", line 128, in _parse_data_complete
    raise ValueError(""No date could be found!"")
ValueError: No date could be found!
",No date could be found!
cowidev.vax.incremental.costa_rica,,,2023-01-29T07:00:13,,
cowidev.vax.incremental.croatia,0.89,True,2023-01-29T07:00:13,,
cowidev.vax.incremental.cuba,12.52,True,2023-01-29T07:00:25,,
cowidev.vax.incremental.curacao,1.48,True,2023-01-29T07:00:14,,
cowidev.vax.incremental.cyprus,3.51,True,2023-01-29T07:00:17,,
cowidev.vax.incremental.dominican_republic,22.65,False,2023-01-29T07:05:15,"Traceback (most recent call last):
  File ""/home/owid/covid-19-data/scripts/src/cowidev/cmd/commons/get.py"", line 46, in run
    module.main()
  File ""/home/owid/covid-19-data/scripts/src/cowidev/vax/incremental/dominican_republic.py"", line 113, in main
    DominicanRepublic().export()
  File ""/home/owid/covid-19-data/scripts/src/cowidev/vax/incremental/dominican_republic.py"", line 68, in export
    data = self.read().pipe(self.pipeline)
  File ""/home/owid/covid-19-data/scripts/src/cowidev/vax/incremental/dominican_republic.py"", line 26, in read
    metrics = self._parse_metrics(driver)
  File ""/home/owid/covid-19-data/scripts/src/cowidev/vax/incremental/dominican_republic.py"", line 35, in _parse_metrics
    metric_candidates = _find_potential_metrics(driver)
  File ""/home/owid/covid-19-data/scripts/src/cowidev/vax/incremental/dominican_republic.py"", line 92, in _find_potential_metrics
    h3 = _find_h3(driver)
  File ""/home/owid/covid-19-data/scripts/src/cowidev/vax/incremental/dominican_republic.py"", line 82, in _find_h3
    raise ValueError(""More than one element found!"")
ValueError: More than one element found!
",More than one element found!
cowidev.vax.incremental.el_salvador,13.26,True,2023-01-29T07:00:28,,
cowidev.vax.incremental.faeroe_islands,1.52,True,2023-01-29T07:00:17,,
cowidev.vax.incremental.fiji,0.0,True,2023-01-29T07:00:17,,
cowidev.vax.incremental.finland,1.11,True,2023-01-29T07:00:18,,
cowidev.vax.incremental.gabon,,,2023-01-29T07:00:17,,
cowidev.vax.incremental.georgia,9.05,True,2023-01-29T07:00:26,,
cowidev.vax.incremental.greenland,0.16,False,2023-01-29T07:05:16,"Traceback (most recent call last):
  File ""/home/owid/covid-19-data/scripts/src/cowidev/cmd/commons/get.py"", line 46, in run
    module.main()
  File ""/home/owid/covid-19-data/scripts/src/cowidev/vax/incremental/greenland.py"", line 76, in main
    Greenland().export()
  File ""/home/owid/covid-19-data/scripts/src/cowidev/vax/incremental/greenland.py"", line 63, in export
    data = self.read().pipe(self.pipeline)
  File ""/home/owid/covid-19-data/scripts/src/cowidev/vax/incremental/greenland.py"", line 17, in read
    data = self._parse_data(soup)
  File ""/home/owid/covid-19-data/scripts/src/cowidev/vax/incremental/greenland.py"", line 21, in _parse_data
    return {**self._parse_data_metrics(soup), **self._parse_data_date(soup)}
  File ""/home/owid/covid-19-data/scripts/src/cowidev/vax/incremental/greenland.py"", line 31, in _parse_data_metrics
    assert len(counter_1) == len(counter_2) == 1
AssertionError
",
cowidev.vax.incremental.guatemala,,,2023-01-29T07:00:18,,
cowidev.vax.incremental.guernsey,11.16,True,2023-01-29T07:00:29,,
cowidev.vax.incremental.hungary,103.81,True,2023-01-29T07:02:02,,
cowidev.vax.incremental.iceland,5.12,True,2023-01-29T07:00:24,,
cowidev.vax.incremental.india,5.3,True,2023-01-29T07:00:26,,
cowidev.vax.incremental.iran,,,2023-01-29T07:00:22,,
cowidev.vax.incremental.isle_of_man,2.54,True,2023-01-29T07:00:24,,
cowidev.vax.incremental.jamaica,7.88,True,2023-01-29T07:00:30,,
cowidev.vax.incremental.kazakhstan,7.13,True,2023-01-29T07:00:29,,
cowidev.vax.incremental.kosovo,8.25,False,2023-01-29T07:05:24,"Traceback (most recent call last):
  File ""/home/owid/covid-19-data/scripts/src/cowidev/cmd/commons/get.py"", line 46, in run
    module.main()
  File ""/home/owid/covid-19-data/scripts/src/cowidev/vax/incremental/kosovo.py"", line 82, in main
    Kosovo().export()
  File ""/home/owid/covid-19-data/scripts/src/cowidev/vax/incremental/kosovo.py"", line 77, in export
    df = self.read().pipe(self.pipeline)
  File ""/home/owid/covid-19-data/scripts/src/cowidev/vax/incremental/kosovo.py"", line 23, in read
    df = self._parse_data(soup)
  File ""/home/owid/covid-19-data/scripts/src/cowidev/vax/incremental/kosovo.py"", line 32, in _parse_data
    soup = get_soup(link, verify=False)
  File ""/home/owid/covid-19-data/scripts/src/cowidev/utils/web/scraping.py"", line 83, in get_soup
    response = get_response(source, request_method, use_proxy, **kwargs)
  File ""/home/owid/covid-19-data/scripts/src/cowidev/utils/web/scraping.py"", line 52, in get_response
    raise ValueError(
ValueError: Source https://msh.rks-gov.net/10.230.0.57+9000/coviddashboard.html not reached! Error code 404 Not Found
",Source https://msh.rks-gov.net/10.230.0.57+9000/coviddashboard.html not reached! Error code 404 Not Found
cowidev.vax.incremental.kyrgyzstan,4.04,True,2023-01-29T07:00:28,,
cowidev.vax.incremental.laos,6.7,True,2023-01-29T07:00:31,,
cowidev.vax.incremental.macao,17.55,True,2023-01-29T07:00:42,,
cowidev.vax.incremental.moldova,,,2023-01-29T07:00:25,,
cowidev.vax.incremental.monaco,106.43,True,2023-01-29T07:02:11,,
cowidev.vax.incremental.mongolia,1.44,True,2023-01-29T07:00:27,,
cowidev.vax.incremental.montenegro,0.82,True,2023-01-29T07:00:27,,
cowidev.vax.incremental.morocco,,,2023-01-29T07:00:26,,
cowidev.vax.incremental.myanmar,,,2023-01-29T07:00:26,,
cowidev.vax.incremental.nepal,,,2023-01-29T07:00:26,,
cowidev.vax.incremental.north_macedonia,,,2023-01-29T07:00:26,,
cowidev.vax.incremental.northern_cyprus,3.31,True,2023-01-29T07:00:29,,
cowidev.vax.incremental.paho,137.08,False,2023-01-29T07:07:41,"Traceback (most recent call last):
  File ""/home/owid/covid-19-data/scripts/src/cowidev/cmd/commons/get.py"", line 46, in run
    module.main()
  File ""/home/owid/covid-19-data/scripts/src/cowidev/vax/incremental/paho.py"", line 195, in main
    PAHO().export()
  File ""/home/owid/covid-19-data/scripts/src/cowidev/vax/incremental/paho.py"", line 190, in export
    df = self.read().pipe(self.pipeline)
  File ""/home/owid/covid-19-data/scripts/src/cowidev/vax/incremental/paho.py"", line 37, in read
    df = self._parse_data(url)
  File ""/home/owid/covid-19-data/scripts/src/cowidev/vax/incremental/paho.py"", line 64, in _parse_data
    filename = self._get_downloaded_filename()
  File ""/home/owid/covid-19-data/scripts/src/cowidev/vax/incremental/paho.py"", line 116, in _get_downloaded_filename
    return max(files, key=os.path.getctime)
ValueError: max() arg is an empty sequence
",max() arg is an empty sequence
cowidev.vax.incremental.pakistan,,,2023-01-29T07:00:27,,
cowidev.vax.incremental.philippines,,,2023-01-29T07:00:27,,
cowidev.vax.incremental.poland,1.09,True,2023-01-29T07:00:28,,
cowidev.vax.incremental.qatar,,,2023-01-29T07:00:27,,
cowidev.vax.incremental.russia,23.59,True,2023-01-29T07:00:50,,
cowidev.vax.incremental.saint_lucia,,,2023-01-29T07:00:27,,
cowidev.vax.incremental.serbia,13.77,True,2023-01-29T07:00:41,,
cowidev.vax.incremental.south_africa,,,2023-01-29T07:00:28,,
cowidev.vax.incremental.spain,10.84,True,2023-01-29T07:00:38,,
cowidev.vax.incremental.sri_lanka,,,2023-01-29T07:00:28,,
cowidev.vax.incremental.suriname,15.61,True,2023-01-29T07:00:43,,
cowidev.vax.incremental.taiwan,24.52,True,2023-01-29T07:00:52,,
cowidev.vax.incremental.thailand,8.43,True,2023-01-29T07:00:38,,
cowidev.vax.incremental.turkey,40.21,False,2023-01-29T07:08:21,"Traceback (most recent call last):
  File ""/home/owid/covid-19-data/scripts/venv/lib/python3.10/site-packages/urllib3/connectionpool.py"", line 386, in _make_request
    self._validate_conn(conn)
  File ""/home/owid/covid-19-data/scripts/venv/lib/python3.10/site-packages/urllib3/connectionpool.py"", line 1042, in _validate_conn
    conn.connect()
  File ""/home/owid/covid-19-data/scripts/venv/lib/python3.10/site-packages/urllib3/connection.py"", line 414, in connect
    self.sock = ssl_wrap_socket(
  File ""/home/owid/covid-19-data/scripts/venv/lib/python3.10/site-packages/urllib3/util/ssl_.py"", line 449, in ssl_wrap_socket
    ssl_sock = _ssl_wrap_socket_impl(
  File ""/home/owid/covid-19-data/scripts/venv/lib/python3.10/site-packages/urllib3/util/ssl_.py"", line 493, in _ssl_wrap_socket_impl
    return ssl_context.wrap_socket(sock, server_hostname=server_hostname)
  File ""/usr/lib/python3.10/ssl.py"", line 513, in wrap_socket
    return self.sslsocket_class._create(
  File ""/usr/lib/python3.10/ssl.py"", line 1071, in _create
    self.do_handshake()
  File ""/usr/lib/python3.10/ssl.py"", line 1342, in do_handshake
    self._sslobj.do_handshake()
TimeoutError: _ssl.c:980: The handshake operation timed out

During handling of the above exception, another exception occurred:

Traceback (most recent call last):
  File ""/home/owid/covid-19-data/scripts/venv/lib/python3.10/site-packages/requests/adapters.py"", line 440, in send
    resp = conn.urlopen(
  File ""/home/owid/covid-19-data/scripts/venv/lib/python3.10/site-packages/urllib3/connectionpool.py"", line 787, in urlopen
    retries = retries.increment(
  File ""/home/owid/covid-19-data/scripts/venv/lib/python3.10/site-packages/urllib3/util/retry.py"", line 550, in increment
    raise six.reraise(type(error), error, _stacktrace)
  File ""/home/owid/covid-19-data/scripts/venv/lib/python3.10/site-packages/urllib3/packages/six.py"", line 770, in reraise
    raise value
  File ""/home/owid/covid-19-data/scripts/venv/lib/python3.10/site-packages/urllib3/connectionpool.py"", line 703, in urlopen
    httplib_response = self._make_request(
  File ""/home/owid/covid-19-data/scripts/venv/lib/python3.10/site-packages/urllib3/connectionpool.py"", line 389, in _make_request
    self._raise_timeout(err=e, url=url, timeout_value=conn.timeout)
  File ""/home/owid/covid-19-data/scripts/venv/lib/python3.10/site-packages/urllib3/connectionpool.py"", line 340, in _raise_timeout
    raise ReadTimeoutError(
urllib3.exceptions.ReadTimeoutError: HTTPSConnectionPool(host='covid19asi.saglik.gov.tr', port=443): Read timed out. (read timeout=20)

During handling of the above exception, another exception occurred:

Traceback (most recent call last):
  File ""/home/owid/covid-19-data/scripts/src/cowidev/cmd/commons/get.py"", line 46, in run
    module.main()
  File ""/home/owid/covid-19-data/scripts/src/cowidev/vax/incremental/turkey.py"", line 60, in main
    data = read(source).pipe(pipeline)
  File ""/home/owid/covid-19-data/scripts/src/cowidev/vax/incremental/turkey.py"", line 19, in read
    soup = get_soup(source)
  File ""/home/owid/covid-19-data/scripts/src/cowidev/utils/web/scraping.py"", line 83, in get_soup
    response = get_response(source, request_method, use_proxy, **kwargs)
  File ""/home/owid/covid-19-data/scripts/src/cowidev/utils/web/scraping.py"", line 49, in get_response
    raise err
  File ""/home/owid/covid-19-data/scripts/src/cowidev/utils/web/scraping.py"", line 43, in get_response
    response = requests.get(source, **kwargs)
  File ""/home/owid/covid-19-data/scripts/venv/lib/python3.10/site-packages/requests/api.py"", line 75, in get
    return request('get', url, params=params, **kwargs)
  File ""/home/owid/covid-19-data/scripts/venv/lib/python3.10/site-packages/requests/api.py"", line 61, in request
    return session.request(method=method, url=url, **kwargs)
  File ""/home/owid/covid-19-data/scripts/venv/lib/python3.10/site-packages/requests/sessions.py"", line 529, in request
    resp = self.send(prep, **send_kwargs)
  File ""/home/owid/covid-19-data/scripts/venv/lib/python3.10/site-packages/requests/sessions.py"", line 645, in send
    r = adapter.send(request, **kwargs)
  File ""/home/owid/covid-19-data/scripts/venv/lib/python3.10/site-packages/requests/adapters.py"", line 532, in send
    raise ReadTimeout(e, request=request)
requests.exceptions.ReadTimeout: HTTPSConnectionPool(host='covid19asi.saglik.gov.tr', port=443): Read timed out. (read timeout=20)
","HTTPSConnectionPool(host='covid19asi.saglik.gov.tr', port=443): Read timed out. (read timeout=20)"
cowidev.vax.incremental.united_arab_emirates,,,2023-01-29T07:00:29,,
cowidev.vax.incremental.vietnam,,,2023-01-29T07:00:29,,
cowidev.vax.incremental.who,56.98,True,2023-01-29T07:01:26,,
cowidev.vax.incremental.zambia,1.07,True,2023-01-29T07:00:31,,
