module,execution_time (sec),success,timestamp,error,error_short
cowidev.vax.batch.argentina,14.35,True,2023-01-22T07:00:20,,
cowidev.vax.batch.australia,124.01,True,2023-01-22T07:02:10,,
cowidev.vax.batch.austria,6.5,True,2023-01-22T07:00:12,,
cowidev.vax.batch.belgium,2.93,True,2023-01-22T07:00:09,,
cowidev.vax.batch.bolivia,3.01,True,2023-01-22T07:00:09,,
cowidev.vax.batch.canada,36.97,True,2023-01-22T07:00:43,,
cowidev.vax.batch.chile,0.97,True,2023-01-22T07:00:07,,
cowidev.vax.batch.czechia,38.58,True,2023-01-22T07:00:44,,
cowidev.vax.batch.denmark,128.35,True,2023-01-22T07:02:14,,
cowidev.vax.batch.ecdc,132.98,True,2023-01-22T07:02:19,,
cowidev.vax.batch.ecuador,,,2023-01-22T07:00:06,,
cowidev.vax.batch.estonia,0.8,True,2023-01-22T07:00:06,,
cowidev.vax.batch.france,3.84,True,2023-01-22T07:00:09,,
cowidev.vax.batch.germany,0.24,True,2023-01-22T07:00:06,,
cowidev.vax.batch.greece,20.52,True,2023-01-22T07:00:26,,
cowidev.vax.batch.hong_kong,21.97,True,2023-01-22T07:00:28,,
cowidev.vax.batch.indonesia,,,2023-01-22T07:00:06,,
cowidev.vax.batch.ireland,3.17,True,2023-01-22T07:00:09,,
cowidev.vax.batch.israel,14.74,True,2023-01-22T07:00:20,,
cowidev.vax.batch.italy,0.89,False,2023-01-22T07:02:31,"Traceback (most recent call last):
  File ""/home/owid/covid-19-data/scripts/src/cowidev/cmd/commons/get.py"", line 46, in run
    module.main()
  File ""/home/owid/covid-19-data/scripts/src/cowidev/vax/batch/italy.py"", line 162, in main
    Italy().export()
  File ""/home/owid/covid-19-data/scripts/src/cowidev/vax/batch/italy.py"", line 144, in export
    df_base = self.read().pipe(self.pipeline_base)
  File ""/home/owid/covid-19-data/scripts/src/cowidev/vax/batch/italy.py"", line 41, in read
    check_known_columns(
  File ""/home/owid/covid-19-data/scripts/src/cowidev/utils/utils.py"", line 164, in check_known_columns
    raise Exception(f""Unknown column(s) found: {unknown_cols}"")
Exception: Unknown column(s) found: {'db3'}
",Unknown column(s) found: {'db3'}
cowidev.vax.batch.japan,54.07,True,2023-01-22T07:01:00,,
cowidev.vax.batch.jersey,4.29,True,2023-01-22T07:00:10,,
cowidev.vax.batch.latvia,79.38,True,2023-01-22T07:01:25,,
cowidev.vax.batch.lithuania,4.32,True,2023-01-22T07:00:10,,
cowidev.vax.batch.luxembourg,2.46,True,2023-01-22T07:00:08,,
cowidev.vax.batch.malaysia,0.86,True,2023-01-22T07:00:06,,
cowidev.vax.batch.malta,1.06,True,2023-01-22T07:00:07,,
cowidev.vax.batch.netherlands,,,2023-01-22T07:00:06,,
cowidev.vax.batch.new_zealand,14.74,True,2023-01-22T07:00:20,,
cowidev.vax.batch.norway,0.33,True,2023-01-22T07:00:06,,
cowidev.vax.batch.peru,2.97,True,2023-01-22T07:00:09,,
cowidev.vax.batch.portugal,,,2023-01-22T07:00:06,,
cowidev.vax.batch.romania,46.76,True,2023-01-22T07:00:52,,
cowidev.vax.batch.saudi_arabia,8.3,True,2023-01-22T07:00:14,,
cowidev.vax.batch.singapore,3.16,True,2023-01-22T07:00:09,,
cowidev.vax.batch.slovakia,94.73,True,2023-01-22T07:01:41,,
cowidev.vax.batch.slovenia,2.51,True,2023-01-22T07:00:08,,
cowidev.vax.batch.south_korea,11.51,True,2023-01-22T07:02:42,,
cowidev.vax.batch.spc,37.31,True,2023-01-22T07:00:44,,
cowidev.vax.batch.sweden,17.83,True,2023-01-22T07:00:24,,
cowidev.vax.batch.switzerland,130.43,True,2023-01-22T07:02:17,,
cowidev.vax.batch.trinidad_and_tobago,1.5,True,2023-01-22T07:00:10,,
cowidev.vax.batch.ukraine,,,2023-01-22T07:00:08,,
cowidev.vax.batch.united_kingdom,18.21,True,2023-01-22T07:00:27,,
cowidev.vax.batch.united_states,130.78,True,2023-01-22T07:02:19,,
cowidev.vax.batch.uruguay,4.21,True,2023-01-22T07:00:13,,
cowidev.vax.batch.zimbabwe,0.9,True,2023-01-22T07:00:09,,
cowidev.vax.incremental.africacdc,,,2023-01-22T07:00:09,,
cowidev.vax.incremental.antigua_barbuda,,,2023-01-22T07:00:09,,
cowidev.vax.incremental.aruba,0.97,True,2023-01-22T07:00:10,,
cowidev.vax.incremental.azerbaijan,,,2023-01-22T07:00:09,,
cowidev.vax.incremental.bahrain,,,2023-01-22T07:00:09,,
cowidev.vax.incremental.bangladesh,44.21,True,2023-01-22T07:00:53,,
cowidev.vax.incremental.barbados,,,2023-01-22T07:00:09,,
cowidev.vax.incremental.brazil,0.64,True,2023-01-22T07:00:09,,
cowidev.vax.incremental.bulgaria,10.87,True,2023-01-22T07:00:20,,
cowidev.vax.incremental.china,24.14,False,2023-01-22T07:03:06,"Traceback (most recent call last):
  File ""/home/owid/covid-19-data/scripts/src/cowidev/cmd/commons/get.py"", line 46, in run
    module.main()
  File ""/home/owid/covid-19-data/scripts/src/cowidev/vax/incremental/china.py"", line 180, in main
    China().export()
  File ""/home/owid/covid-19-data/scripts/src/cowidev/vax/incremental/china.py"", line 168, in export
    df_complete = self.read_complete()
  File ""/home/owid/covid-19-data/scripts/src/cowidev/vax/incremental/china.py"", line 89, in read_complete
    data_ = self._parse_data_complete(driver, link)
  File ""/home/owid/covid-19-data/scripts/src/cowidev/vax/incremental/china.py"", line 120, in _parse_data_complete
    raise ValueError(""No date could be found!"")
ValueError: No date could be found!
",No date could be found!
cowidev.vax.incremental.costa_rica,,,2023-01-22T07:00:09,,
cowidev.vax.incremental.croatia,0.44,True,2023-01-22T07:00:10,,
cowidev.vax.incremental.cuba,3.46,False,2023-01-22T07:03:10,"Traceback (most recent call last):
  File ""/home/owid/covid-19-data/scripts/src/cowidev/vax/incremental/cuba.py"", line 54, in _parse_metrics
    data[metric] = clean_count(match.group(1).replace("" "", """"))
AttributeError: 'NoneType' object has no attribute 'group'

During handling of the above exception, another exception occurred:

Traceback (most recent call last):
  File ""/home/owid/covid-19-data/scripts/src/cowidev/cmd/commons/get.py"", line 46, in run
    module.main()
  File ""/home/owid/covid-19-data/scripts/src/cowidev/vax/incremental/cuba.py"", line 82, in main
    Cuba().export()
  File ""/home/owid/covid-19-data/scripts/src/cowidev/vax/incremental/cuba.py"", line 68, in export
    data = self.read().pipe(self.pipeline)
  File ""/home/owid/covid-19-data/scripts/src/cowidev/vax/incremental/cuba.py"", line 29, in read
    return self._parse_data(soup)
  File ""/home/owid/covid-19-data/scripts/src/cowidev/vax/incremental/cuba.py"", line 35, in _parse_data
    **self._parse_metrics(soup),
  File ""/home/owid/covid-19-data/scripts/src/cowidev/vax/incremental/cuba.py"", line 56, in _parse_metrics
    raise ValueError(
ValueError: Could not parse `people_vaccinated` using regex 'al menos una dosis de una de las vacunas cubanas SOBERANA 02, SOBERANA Plus y ABDALA, ([\d ]+) personas' from website https://salud.msp.gob.cu/actualizacion-de-la-vacunacion-en-el-marco-de-los-estudios-de-los-candidatos-vacunales-cubanos-y-la-intervencion-sanitaria/
","Could not parse `people_vaccinated` using regex 'al menos una dosis de una de las vacunas cubanas SOBERANA 02, SOBERANA Plus y ABDALA, ([\d ]+) personas' from website https://salud.msp.gob.cu/actualizacion-de-la-vacunacion-en-el-marco-de-los-estudios-de-los-candidatos-vacunales-cubanos-y-la-intervencion-sanitaria/"
cowidev.vax.incremental.curacao,1.11,True,2023-01-22T07:00:11,,
cowidev.vax.incremental.cyprus,2.51,True,2023-01-22T07:00:12,,
cowidev.vax.incremental.dominican_republic,22.78,False,2023-01-22T07:03:33,"Traceback (most recent call last):
  File ""/home/owid/covid-19-data/scripts/src/cowidev/cmd/commons/get.py"", line 46, in run
    module.main()
  File ""/home/owid/covid-19-data/scripts/src/cowidev/vax/incremental/dominican_republic.py"", line 113, in main
    DominicanRepublic().export()
  File ""/home/owid/covid-19-data/scripts/src/cowidev/vax/incremental/dominican_republic.py"", line 68, in export
    data = self.read().pipe(self.pipeline)
  File ""/home/owid/covid-19-data/scripts/src/cowidev/vax/incremental/dominican_republic.py"", line 26, in read
    metrics = self._parse_metrics(driver)
  File ""/home/owid/covid-19-data/scripts/src/cowidev/vax/incremental/dominican_republic.py"", line 35, in _parse_metrics
    metric_candidates = _find_potential_metrics(driver)
  File ""/home/owid/covid-19-data/scripts/src/cowidev/vax/incremental/dominican_republic.py"", line 92, in _find_potential_metrics
    h3 = _find_h3(driver)
  File ""/home/owid/covid-19-data/scripts/src/cowidev/vax/incremental/dominican_republic.py"", line 82, in _find_h3
    raise ValueError(""More than one element found!"")
ValueError: More than one element found!
",More than one element found!
cowidev.vax.incremental.el_salvador,15.88,True,2023-01-22T07:00:26,,
cowidev.vax.incremental.faeroe_islands,1.19,True,2023-01-22T07:00:12,,
cowidev.vax.incremental.fiji,0.0,True,2023-01-22T07:00:12,,
cowidev.vax.incremental.finland,0.76,True,2023-01-22T07:00:13,,
cowidev.vax.incremental.gabon,,,2023-01-22T07:00:12,,
cowidev.vax.incremental.georgia,11.11,True,2023-01-22T07:00:23,,
cowidev.vax.incremental.greenland,1.22,False,2023-01-22T07:03:34,"Traceback (most recent call last):
  File ""/home/owid/covid-19-data/scripts/src/cowidev/cmd/commons/get.py"", line 46, in run
    module.main()
  File ""/home/owid/covid-19-data/scripts/src/cowidev/vax/incremental/greenland.py"", line 76, in main
    Greenland().export()
  File ""/home/owid/covid-19-data/scripts/src/cowidev/vax/incremental/greenland.py"", line 63, in export
    data = self.read().pipe(self.pipeline)
  File ""/home/owid/covid-19-data/scripts/src/cowidev/vax/incremental/greenland.py"", line 17, in read
    data = self._parse_data(soup)
  File ""/home/owid/covid-19-data/scripts/src/cowidev/vax/incremental/greenland.py"", line 21, in _parse_data
    return {**self._parse_data_metrics(soup), **self._parse_data_date(soup)}
  File ""/home/owid/covid-19-data/scripts/src/cowidev/vax/incremental/greenland.py"", line 31, in _parse_data_metrics
    assert len(counter_1) == len(counter_2) == 1
AssertionError
",
cowidev.vax.incremental.guatemala,,,2023-01-22T07:00:13,,
cowidev.vax.incremental.guernsey,15.08,True,2023-01-22T07:00:28,,
cowidev.vax.incremental.hungary,125.51,True,2023-01-22T07:02:18,,
cowidev.vax.incremental.iceland,4.78,True,2023-01-22T07:00:19,,
cowidev.vax.incremental.india,5.53,True,2023-01-22T07:00:24,,
cowidev.vax.incremental.iran,,,2023-01-22T07:00:20,,
cowidev.vax.incremental.isle_of_man,3.07,True,2023-01-22T07:00:23,,
cowidev.vax.incremental.jamaica,9.61,True,2023-01-22T07:00:30,,
cowidev.vax.incremental.kazakhstan,7.55,True,2023-01-22T07:00:28,,
cowidev.vax.incremental.kosovo,8.65,False,2023-01-22T07:03:42,"Traceback (most recent call last):
  File ""/home/owid/covid-19-data/scripts/src/cowidev/cmd/commons/get.py"", line 46, in run
    module.main()
  File ""/home/owid/covid-19-data/scripts/src/cowidev/vax/incremental/kosovo.py"", line 82, in main
    Kosovo().export()
  File ""/home/owid/covid-19-data/scripts/src/cowidev/vax/incremental/kosovo.py"", line 77, in export
    df = self.read().pipe(self.pipeline)
  File ""/home/owid/covid-19-data/scripts/src/cowidev/vax/incremental/kosovo.py"", line 23, in read
    df = self._parse_data(soup)
  File ""/home/owid/covid-19-data/scripts/src/cowidev/vax/incremental/kosovo.py"", line 32, in _parse_data
    soup = get_soup(link, verify=False)
  File ""/home/owid/covid-19-data/scripts/src/cowidev/utils/web/scraping.py"", line 83, in get_soup
    response = get_response(source, request_method, use_proxy, **kwargs)
  File ""/home/owid/covid-19-data/scripts/src/cowidev/utils/web/scraping.py"", line 52, in get_response
    raise ValueError(
ValueError: Source https://msh.rks-gov.net/10.230.0.57+9000/coviddashboard.html not reached! Error code 404 Not Found
",Source https://msh.rks-gov.net/10.230.0.57+9000/coviddashboard.html not reached! Error code 404 Not Found
cowidev.vax.incremental.kyrgyzstan,5.6,True,2023-01-22T07:00:27,,
cowidev.vax.incremental.laos,7.53,True,2023-01-22T07:00:31,,
cowidev.vax.incremental.macao,12.15,True,2023-01-22T07:00:35,,
cowidev.vax.incremental.moldova,,,2023-01-22T07:00:24,,
cowidev.vax.incremental.monaco,125.54,True,2023-01-22T07:02:30,,
cowidev.vax.incremental.mongolia,1.41,True,2023-01-22T07:00:26,,
cowidev.vax.incremental.montenegro,6.25,True,2023-01-22T07:00:32,,
cowidev.vax.incremental.morocco,,,2023-01-22T07:00:26,,
cowidev.vax.incremental.myanmar,,,2023-01-22T07:00:26,,
cowidev.vax.incremental.nepal,,,2023-01-22T07:00:26,,
cowidev.vax.incremental.north_macedonia,,,2023-01-22T07:00:26,,
cowidev.vax.incremental.northern_cyprus,3.4,True,2023-01-22T07:00:29,,
cowidev.vax.incremental.paho,161.44,False,2023-01-22T07:06:24,"Traceback (most recent call last):
  File ""/home/owid/covid-19-data/scripts/src/cowidev/cmd/commons/get.py"", line 46, in run
    module.main()
  File ""/home/owid/covid-19-data/scripts/src/cowidev/vax/incremental/paho.py"", line 195, in main
    PAHO().export()
  File ""/home/owid/covid-19-data/scripts/src/cowidev/vax/incremental/paho.py"", line 190, in export
    df = self.read().pipe(self.pipeline)
  File ""/home/owid/covid-19-data/scripts/venv/lib/python3.10/site-packages/pandas/core/generic.py"", line 5430, in pipe
    return com.pipe(self, func, *args, **kwargs)
  File ""/home/owid/covid-19-data/scripts/venv/lib/python3.10/site-packages/pandas/core/common.py"", line 471, in pipe
    return func(obj, *args, **kwargs)
  File ""/home/owid/covid-19-data/scripts/src/cowidev/vax/incremental/paho.py"", line 167, in pipeline
    df.pipe(self.pipe_check_columns)
  File ""/home/owid/covid-19-data/scripts/venv/lib/python3.10/site-packages/pandas/core/generic.py"", line 5430, in pipe
    return com.pipe(self, func, *args, **kwargs)
  File ""/home/owid/covid-19-data/scripts/venv/lib/python3.10/site-packages/pandas/core/common.py"", line 471, in pipe
    return func(obj, *args, **kwargs)
  File ""/home/owid/covid-19-data/scripts/src/cowidev/vax/incremental/paho.py"", line 122, in pipe_check_columns
    raise ValueError(f""Missing column fields: {columns_missing}. Present columns are: {df.columns}"")
ValueError: Missing column fields: {'First dose', 'Country/ Territory', '2nd additional dose', 'Second dose', 'Country code', 'Total doses', '1st additional dose', 'Single dose'}. Present columns are: Index(['date,location,total_vaccinations,people_vaccinated,people_fully_vaccinated,total_boosters,new_vaccinations,new_vaccinations_interpolated,new_people_vaccinated_interpolated', 'date'], dtype='object')
","Missing column fields: {'First dose', 'Country/ Territory', '2nd additional dose', 'Second dose', 'Country code', 'Total doses', '1st additional dose', 'Single dose'}. Present columns are: Index(['date,location,total_vaccinations,people_vaccinated,people_fully_vaccinated,total_boosters,new_vaccinations,new_vaccinations_interpolated,new_people_vaccinated_interpolated', 'date'], dtype='object')"
cowidev.vax.incremental.pakistan,,,2023-01-22T07:00:27,,
cowidev.vax.incremental.philippines,,,2023-01-22T07:00:27,,
cowidev.vax.incremental.poland,1.13,True,2023-01-22T07:00:28,,
cowidev.vax.incremental.qatar,,,2023-01-22T07:00:27,,
cowidev.vax.incremental.russia,9.07,True,2023-01-22T07:06:33,,
cowidev.vax.incremental.saint_lucia,,,2023-01-22T07:00:28,,
cowidev.vax.incremental.serbia,12.63,True,2023-01-22T07:00:40,,
cowidev.vax.incremental.south_africa,,,2023-01-22T07:00:28,,
cowidev.vax.incremental.spain,14.51,True,2023-01-22T07:00:42,,
cowidev.vax.incremental.sri_lanka,,,2023-01-22T07:00:28,,
cowidev.vax.incremental.suriname,15.16,True,2023-01-22T07:00:43,,
cowidev.vax.incremental.taiwan,29.18,True,2023-01-22T07:00:57,,
cowidev.vax.incremental.thailand,9.56,True,2023-01-22T07:00:39,,
cowidev.vax.incremental.turkey,40.04,False,2023-01-22T07:07:13,"Traceback (most recent call last):
  File ""/home/owid/covid-19-data/scripts/venv/lib/python3.10/site-packages/urllib3/connection.py"", line 174, in _new_conn
    conn = connection.create_connection(
  File ""/home/owid/covid-19-data/scripts/venv/lib/python3.10/site-packages/urllib3/util/connection.py"", line 95, in create_connection
    raise err
  File ""/home/owid/covid-19-data/scripts/venv/lib/python3.10/site-packages/urllib3/util/connection.py"", line 85, in create_connection
    sock.connect(sa)
TimeoutError: timed out

During handling of the above exception, another exception occurred:

Traceback (most recent call last):
  File ""/home/owid/covid-19-data/scripts/venv/lib/python3.10/site-packages/urllib3/connectionpool.py"", line 703, in urlopen
    httplib_response = self._make_request(
  File ""/home/owid/covid-19-data/scripts/venv/lib/python3.10/site-packages/urllib3/connectionpool.py"", line 386, in _make_request
    self._validate_conn(conn)
  File ""/home/owid/covid-19-data/scripts/venv/lib/python3.10/site-packages/urllib3/connectionpool.py"", line 1042, in _validate_conn
    conn.connect()
  File ""/home/owid/covid-19-data/scripts/venv/lib/python3.10/site-packages/urllib3/connection.py"", line 358, in connect
    self.sock = conn = self._new_conn()
  File ""/home/owid/covid-19-data/scripts/venv/lib/python3.10/site-packages/urllib3/connection.py"", line 179, in _new_conn
    raise ConnectTimeoutError(
urllib3.exceptions.ConnectTimeoutError: (<urllib3.connection.HTTPSConnection object at 0x7fa5e3bfa680>, 'Connection to covid19asi.saglik.gov.tr timed out. (connect timeout=20)')

During handling of the above exception, another exception occurred:

Traceback (most recent call last):
  File ""/home/owid/covid-19-data/scripts/venv/lib/python3.10/site-packages/requests/adapters.py"", line 440, in send
    resp = conn.urlopen(
  File ""/home/owid/covid-19-data/scripts/venv/lib/python3.10/site-packages/urllib3/connectionpool.py"", line 787, in urlopen
    retries = retries.increment(
  File ""/home/owid/covid-19-data/scripts/venv/lib/python3.10/site-packages/urllib3/util/retry.py"", line 592, in increment
    raise MaxRetryError(_pool, url, error or ResponseError(cause))
urllib3.exceptions.MaxRetryError: HTTPSConnectionPool(host='covid19asi.saglik.gov.tr', port=443): Max retries exceeded with url: / (Caused by ConnectTimeoutError(<urllib3.connection.HTTPSConnection object at 0x7fa5e3bfa680>, 'Connection to covid19asi.saglik.gov.tr timed out. (connect timeout=20)'))

During handling of the above exception, another exception occurred:

Traceback (most recent call last):
  File ""/home/owid/covid-19-data/scripts/src/cowidev/cmd/commons/get.py"", line 46, in run
    module.main()
  File ""/home/owid/covid-19-data/scripts/src/cowidev/vax/incremental/turkey.py"", line 60, in main
    data = read(source).pipe(pipeline)
  File ""/home/owid/covid-19-data/scripts/src/cowidev/vax/incremental/turkey.py"", line 19, in read
    soup = get_soup(source)
  File ""/home/owid/covid-19-data/scripts/src/cowidev/utils/web/scraping.py"", line 83, in get_soup
    response = get_response(source, request_method, use_proxy, **kwargs)
  File ""/home/owid/covid-19-data/scripts/src/cowidev/utils/web/scraping.py"", line 49, in get_response
    raise err
  File ""/home/owid/covid-19-data/scripts/src/cowidev/utils/web/scraping.py"", line 43, in get_response
    response = requests.get(source, **kwargs)
  File ""/home/owid/covid-19-data/scripts/venv/lib/python3.10/site-packages/requests/api.py"", line 75, in get
    return request('get', url, params=params, **kwargs)
  File ""/home/owid/covid-19-data/scripts/venv/lib/python3.10/site-packages/requests/api.py"", line 61, in request
    return session.request(method=method, url=url, **kwargs)
  File ""/home/owid/covid-19-data/scripts/venv/lib/python3.10/site-packages/requests/sessions.py"", line 529, in request
    resp = self.send(prep, **send_kwargs)
  File ""/home/owid/covid-19-data/scripts/venv/lib/python3.10/site-packages/requests/sessions.py"", line 645, in send
    r = adapter.send(request, **kwargs)
  File ""/home/owid/covid-19-data/scripts/venv/lib/python3.10/site-packages/requests/adapters.py"", line 507, in send
    raise ConnectTimeout(e, request=request)
requests.exceptions.ConnectTimeout: HTTPSConnectionPool(host='covid19asi.saglik.gov.tr', port=443): Max retries exceeded with url: / (Caused by ConnectTimeoutError(<urllib3.connection.HTTPSConnection object at 0x7fa5e3bfa680>, 'Connection to covid19asi.saglik.gov.tr timed out. (connect timeout=20)'))
","HTTPSConnectionPool(host='covid19asi.saglik.gov.tr', port=443): Max retries exceeded with url: / (Caused by ConnectTimeoutError(<urllib3.connection.HTTPSConnection object at 0x7fa5e3bfa680>, 'Connection to covid19asi.saglik.gov.tr timed out. (connect timeout=20)'))"
cowidev.vax.incremental.united_arab_emirates,,,2023-01-22T07:00:31,,
cowidev.vax.incremental.vietnam,,,2023-01-22T07:00:31,,
cowidev.vax.incremental.who,74.25,True,2023-01-22T07:01:45,,
cowidev.vax.incremental.zambia,2.22,True,2023-01-22T07:00:34,,
