module,execution_time (sec),success,timestamp,error,error_short
cowidev.vax.batch.argentina,3.59,True,2022-11-15T07:00:15,,
cowidev.vax.batch.australia,,,2022-11-15T07:00:11,,
cowidev.vax.batch.austria,2.25,True,2022-11-15T07:00:13,,
cowidev.vax.batch.belgium,1.9,True,2022-11-15T07:00:13,,
cowidev.vax.batch.bolivia,1.98,True,2022-11-15T07:00:13,,
cowidev.vax.batch.canada,8.4,False,2022-11-15T17:41:34,"Traceback (most recent call last):
  File ""/home/lucas/repos/covid-19-data/scripts/src/cowidev/cmd/commons/get.py"", line 46, in run
    module.main()
  File ""/home/lucas/repos/covid-19-data/scripts/src/cowidev/vax/batch/canada.py"", line 284, in main
    Canada().export()
  File ""/home/lucas/repos/covid-19-data/scripts/src/cowidev/vax/batch/canada.py"", line 268, in export
    df, df_age, df_man = self.read(), self.read_age(), self.read_manufacturer()
  File ""/home/lucas/repos/covid-19-data/scripts/src/cowidev/vax/batch/canada.py"", line 99, in read_age
    check_known_columns(
  File ""/home/lucas/repos/covid-19-data/scripts/src/cowidev/utils/utils.py"", line 168, in check_known_columns
    raise Exception(f""Previous column(s) missing: {missing_cols}"")
Exception: Previous column(s) missing: {'Unnamed: 20', 'Unnamed: 18', 'Unnamed: 19', 'Unnamed: 21', 'Unnamed: 23', 'Unnamed: 22'}
","Previous column(s) missing: {'Unnamed: 20', 'Unnamed: 18', 'Unnamed: 19', 'Unnamed: 21', 'Unnamed: 23', 'Unnamed: 22'}"
cowidev.vax.batch.chile,0.84,True,2022-11-15T07:00:14,,
cowidev.vax.batch.czechia,3.55,True,2022-11-15T07:00:17,,
cowidev.vax.batch.denmark,4.39,True,2022-11-15T07:00:18,,
cowidev.vax.batch.ecdc,33.37,True,2022-11-15T17:41:09,,
cowidev.vax.batch.ecuador,2.45,True,2022-11-15T07:00:17,,
cowidev.vax.batch.estonia,0.63,True,2022-11-15T07:00:17,,
cowidev.vax.batch.france,0.38,True,2022-11-15T07:00:17,,
cowidev.vax.batch.germany,1.73,True,2022-11-15T07:00:19,,
cowidev.vax.batch.greece,3.31,True,2022-11-15T07:00:21,,
cowidev.vax.batch.hong_kong,12.55,True,2022-11-15T07:00:30,,
cowidev.vax.batch.indonesia,,,2022-11-15T07:00:18,,
cowidev.vax.batch.ireland,0.58,True,2022-11-15T07:00:19,,
cowidev.vax.batch.israel,11.48,True,2022-11-15T07:00:30,,
cowidev.vax.batch.italy,11.37,True,2022-11-15T07:00:30,,
cowidev.vax.batch.japan,30.68,True,2022-11-15T17:41:06,,
cowidev.vax.batch.jersey,0.48,True,2022-11-15T07:00:31,,
cowidev.vax.batch.latvia,18.2,True,2022-11-15T07:00:48,,
cowidev.vax.batch.lithuania,1.76,True,2022-11-15T07:00:32,,
cowidev.vax.batch.luxembourg,1.95,True,2022-11-15T07:00:33,,
cowidev.vax.batch.malaysia,1.01,True,2022-11-15T07:00:32,,
cowidev.vax.batch.malta,0.77,True,2022-11-15T07:00:33,,
cowidev.vax.batch.netherlands,,,2022-11-15T07:00:32,,
cowidev.vax.batch.new_zealand,8.87,True,2022-11-15T07:00:41,,
cowidev.vax.batch.norway,0.45,True,2022-11-15T07:00:33,,
cowidev.vax.batch.peru,3.33,True,2022-11-15T07:00:36,,
cowidev.vax.batch.portugal,,,2022-11-15T07:00:33,,
cowidev.vax.batch.romania,16.05,True,2022-11-15T07:00:49,,
cowidev.vax.batch.saudi_arabia,10.64,True,2022-11-15T07:00:47,,
cowidev.vax.batch.singapore,3.54,False,2022-11-15T17:41:38,"Traceback (most recent call last):
  File ""/home/lucas/repos/covid-19-data/scripts/src/cowidev/cmd/commons/get.py"", line 46, in run
    module.main()
  File ""/home/lucas/repos/covid-19-data/scripts/src/cowidev/vax/batch/singapore.py"", line 120, in main
    Singapore().export()
  File ""/home/lucas/repos/covid-19-data/scripts/src/cowidev/vax/batch/singapore.py"", line 115, in export
    df = self.read().pipe(self.pipeline)
  File ""/home/lucas/repos/covid-19-data/scripts/src/cowidev/vax/batch/singapore.py"", line 46, in read
    df_boosters = pd.read_csv(os.path.join(tf, ""progress-of-vaccine-booster-programme.csv""))
  File ""/home/lucas/repos/covid-19-data/venv/lib/python3.10/site-packages/pandas/util/_decorators.py"", line 311, in wrapper
    return func(*args, **kwargs)
  File ""/home/lucas/repos/covid-19-data/venv/lib/python3.10/site-packages/pandas/io/parsers/readers.py"", line 586, in read_csv
    return _read(filepath_or_buffer, kwds)
  File ""/home/lucas/repos/covid-19-data/venv/lib/python3.10/site-packages/pandas/io/parsers/readers.py"", line 482, in _read
    parser = TextFileReader(filepath_or_buffer, **kwds)
  File ""/home/lucas/repos/covid-19-data/venv/lib/python3.10/site-packages/pandas/io/parsers/readers.py"", line 811, in __init__
    self._engine = self._make_engine(self.engine)
  File ""/home/lucas/repos/covid-19-data/venv/lib/python3.10/site-packages/pandas/io/parsers/readers.py"", line 1040, in _make_engine
    return mapping[engine](self.f, **self.options)  # type: ignore[call-arg]
  File ""/home/lucas/repos/covid-19-data/venv/lib/python3.10/site-packages/pandas/io/parsers/c_parser_wrapper.py"", line 51, in __init__
    self._open_handles(src, kwds)
  File ""/home/lucas/repos/covid-19-data/venv/lib/python3.10/site-packages/pandas/io/parsers/base_parser.py"", line 222, in _open_handles
    self.handles = get_handle(
  File ""/home/lucas/repos/covid-19-data/venv/lib/python3.10/site-packages/pandas/io/common.py"", line 702, in get_handle
    handle = open(
FileNotFoundError: [Errno 2] No such file or directory: '/tmp/tmpjhw6wr1e/progress-of-vaccine-booster-programme.csv'
",[Errno 2] No such file or directory: '/tmp/tmpjhw6wr1e/progress-of-vaccine-booster-programme.csv'
cowidev.vax.batch.slovakia,38.68,True,2022-11-15T07:01:25,,
cowidev.vax.batch.slovenia,1.53,True,2022-11-15T07:00:48,,
cowidev.vax.batch.south_korea,38.77,True,2022-11-15T07:01:27,,
cowidev.vax.batch.spc,16.21,True,2022-11-15T07:01:05,,
cowidev.vax.batch.sweden,,,2022-11-15T17:40:35,,
cowidev.vax.batch.switzerland,26.5,True,2022-11-15T07:01:31,,
cowidev.vax.batch.trinidad_and_tobago,2.49,True,2022-11-15T07:01:17,,
cowidev.vax.batch.ukraine,,,2022-11-15T07:01:17,,
cowidev.vax.batch.united_kingdom,9.54,True,2022-11-15T07:01:26,,
cowidev.vax.batch.united_states,18.82,True,2022-11-15T07:01:36,,
cowidev.vax.batch.uruguay,2.07,True,2022-11-15T07:01:27,,
cowidev.vax.batch.zimbabwe,0.36,True,2022-11-15T07:01:27,,
cowidev.vax.incremental.africacdc,,,2022-11-15T07:01:27,,
cowidev.vax.incremental.antigua_barbuda,,,2022-11-15T07:01:27,,
cowidev.vax.incremental.aruba,1.04,True,2022-11-15T07:01:28,,
cowidev.vax.incremental.azerbaijan,,,2022-11-15T07:01:27,,
cowidev.vax.incremental.bahrain,1.41,True,2022-11-15T07:01:28,,
cowidev.vax.incremental.bangladesh,21.97,True,2022-11-15T07:01:49,,
cowidev.vax.incremental.barbados,,,2022-11-15T07:01:28,,
cowidev.vax.incremental.brazil,0.08,True,2022-11-15T07:01:28,,
cowidev.vax.incremental.bulgaria,1.48,True,2022-11-15T07:01:29,,
cowidev.vax.incremental.china,42.14,True,2022-11-15T07:02:11,,
cowidev.vax.incremental.costa_rica,,,2022-11-15T07:01:29,,
cowidev.vax.incremental.croatia,0.15,True,2022-11-15T07:01:29,,
cowidev.vax.incremental.cuba,2.1,True,2022-11-15T07:01:31,,
cowidev.vax.incremental.curacao,0.39,True,2022-11-15T07:01:31,,
cowidev.vax.incremental.cyprus,5.37,True,2022-11-15T07:01:37,,
cowidev.vax.incremental.dominican_republic,8.83,True,2022-11-15T07:01:40,,
cowidev.vax.incremental.el_salvador,3.03,True,2022-11-15T07:01:39,,
cowidev.vax.incremental.faeroe_islands,0.4,True,2022-11-15T07:01:37,,
cowidev.vax.incremental.fiji,0.0,True,2022-11-15T07:01:37,,
cowidev.vax.incremental.finland,0.21,True,2022-11-15T07:01:37,,
cowidev.vax.incremental.gabon,,,2022-11-15T07:01:37,,
cowidev.vax.incremental.georgia,0.43,True,2022-11-15T07:01:38,,
cowidev.vax.incremental.greenland,1.13,False,2022-11-15T07:04:49,"Traceback (most recent call last):
  File ""/mnt/owid_live_covid/covid-19-data/scripts/src/cowidev/cmd/commons/get.py"", line 46, in run
    module.main()
  File ""/mnt/owid_live_covid/covid-19-data/scripts/src/cowidev/vax/incremental/greenland.py"", line 74, in main
    Greenland().export()
  File ""/mnt/owid_live_covid/covid-19-data/scripts/src/cowidev/vax/incremental/greenland.py"", line 61, in export
    data = self.read().pipe(self.pipeline)
  File ""/mnt/owid_live_covid/covid-19-data/scripts/src/cowidev/vax/incremental/greenland.py"", line 18, in read
    data = self._parse_data(soup)
  File ""/mnt/owid_live_covid/covid-19-data/scripts/src/cowidev/vax/incremental/greenland.py"", line 22, in _parse_data
    return {**self._parse_data_metrics(soup), **self._parse_data_date(soup)}
  File ""/mnt/owid_live_covid/covid-19-data/scripts/src/cowidev/vax/incremental/greenland.py"", line 26, in _parse_data_metrics
    dose_1 = clean_count(re.search(r""Innuttaasut ([\d\.]+)"", counters[1].parent.find_all(""dd"")[-1].text).group(1))
IndexError: list index out of range
",list index out of range
cowidev.vax.incremental.guatemala,,,2022-11-15T07:01:39,,
cowidev.vax.incremental.guernsey,0.21,False,2022-11-15T07:04:49,"Traceback (most recent call last):
  File ""/mnt/owid_live_covid/covid-19-data/scripts/src/cowidev/cmd/commons/get.py"", line 46, in run
    module.main()
  File ""/mnt/owid_live_covid/covid-19-data/scripts/src/cowidev/vax/incremental/guernsey.py"", line 61, in main
    Guernsey().export()
  File ""/mnt/owid_live_covid/covid-19-data/scripts/src/cowidev/vax/incremental/guernsey.py"", line 50, in export
    data = self.read().pipe(self.pipeline)
  File ""/mnt/owid_live_covid/covid-19-data/scripts/src/cowidev/vax/incremental/guernsey.py"", line 15, in read
    df = self.parse_data(soup)
  File ""/mnt/owid_live_covid/covid-19-data/scripts/src/cowidev/vax/incremental/guernsey.py"", line 31, in parse_data
    ds.loc[ds[0] == ""Total doses"", 1].values[0].replace(""*"", """"),
IndexError: index 0 is out of bounds for axis 0 with size 0
",index 0 is out of bounds for axis 0 with size 0
cowidev.vax.incremental.hungary,0.96,True,2022-11-15T07:01:40,,
cowidev.vax.incremental.iceland,0.8,True,2022-11-15T07:01:40,,
cowidev.vax.incremental.india,0.91,True,2022-11-15T07:01:41,,
cowidev.vax.incremental.iran,,,2022-11-15T07:01:40,,
cowidev.vax.incremental.isle_of_man,0.89,True,2022-11-15T07:01:41,,
cowidev.vax.incremental.jamaica,1.9,True,2022-11-15T07:01:42,,
cowidev.vax.incremental.kazakhstan,13.1,True,2022-11-15T07:01:54,,
cowidev.vax.incremental.kosovo,1.91,True,2022-11-15T07:01:43,,
cowidev.vax.incremental.kyrgyzstan,1.64,True,2022-11-15T07:01:44,,
cowidev.vax.incremental.laos,2.14,True,2022-11-15T07:01:45,,
cowidev.vax.incremental.macao,31.43,False,2022-11-15T07:05:20,"Traceback (most recent call last):
  File ""/mnt/owid_live_covid/covid-19-data/scripts/src/cowidev/cmd/commons/get.py"", line 46, in run
    module.main()
  File ""/mnt/owid_live_covid/covid-19-data/scripts/src/cowidev/vax/incremental/macao.py"", line 86, in main
    Macao().export()
  File ""/mnt/owid_live_covid/covid-19-data/scripts/src/cowidev/vax/incremental/macao.py"", line 72, in export
    data = self.read()
  File ""/mnt/owid_live_covid/covid-19-data/scripts/src/cowidev/vax/incremental/macao.py"", line 22, in read
    data = self._parse_data(elem)
  File ""/mnt/owid_live_covid/covid-19-data/scripts/src/cowidev/vax/incremental/macao.py"", line 50, in _parse_data
    df = self._parse_pdf_table(url)
  File ""/mnt/owid_live_covid/covid-19-data/scripts/src/cowidev/vax/incremental/macao.py"", line 33, in _parse_pdf_table
    raise ValueError(""New columns added!"")
ValueError: New columns added!
",New columns added!
cowidev.vax.incremental.moldova,,,2022-11-15T07:01:45,,
cowidev.vax.incremental.monaco,34.44,True,2022-11-15T07:02:20,,
cowidev.vax.incremental.mongolia,0.87,True,2022-11-15T07:01:50,,
cowidev.vax.incremental.montenegro,0.09,True,2022-11-15T07:01:50,,
cowidev.vax.incremental.morocco,,,2022-11-15T07:01:50,,
cowidev.vax.incremental.myanmar,,,2022-11-15T07:01:50,,
cowidev.vax.incremental.nepal,,,2022-11-15T07:01:50,,
cowidev.vax.incremental.north_macedonia,,,2022-11-15T07:01:50,,
cowidev.vax.incremental.northern_cyprus,0.61,True,2022-11-15T07:01:51,,
cowidev.vax.incremental.paho,49.16,True,2022-11-15T17:41:24,,
cowidev.vax.incremental.pakistan,1.37,True,2022-11-15T07:01:55,,
cowidev.vax.incremental.philippines,,,2022-11-15T07:01:55,,
cowidev.vax.incremental.playground_mojmir,4.85,True,2022-11-15T07:02:00,,
cowidev.vax.incremental.poland,0.37,True,2022-11-15T07:02:01,,
cowidev.vax.incremental.qatar,,,2022-11-15T07:02:01,,
cowidev.vax.incremental.russia,1.02,True,2022-11-15T17:40:36,,
cowidev.vax.incremental.saint_lucia,,,2022-11-15T07:02:01,,
cowidev.vax.incremental.serbia,6.27,True,2022-11-15T07:02:08,,
cowidev.vax.incremental.south_africa,7.08,True,2022-11-15T07:02:15,,
cowidev.vax.incremental.spain,12.48,True,2022-11-15T07:02:23,,
cowidev.vax.incremental.sri_lanka,,,2022-11-15T07:02:12,,
cowidev.vax.incremental.suriname,14.33,True,2022-11-15T07:02:26,,
cowidev.vax.incremental.taiwan,5.42,True,2022-11-15T07:02:20,,
cowidev.vax.incremental.thailand,4.63,True,2022-11-15T07:02:24,,
cowidev.vax.incremental.turkey,40.33,False,2022-11-15T17:42:18,"Traceback (most recent call last):
  File ""/home/lucas/repos/covid-19-data/venv/lib/python3.10/site-packages/urllib3/connection.py"", line 174, in _new_conn
    conn = connection.create_connection(
  File ""/home/lucas/repos/covid-19-data/venv/lib/python3.10/site-packages/urllib3/util/connection.py"", line 95, in create_connection
    raise err
  File ""/home/lucas/repos/covid-19-data/venv/lib/python3.10/site-packages/urllib3/util/connection.py"", line 85, in create_connection
    sock.connect(sa)
TimeoutError: timed out

During handling of the above exception, another exception occurred:

Traceback (most recent call last):
  File ""/home/lucas/repos/covid-19-data/venv/lib/python3.10/site-packages/urllib3/connectionpool.py"", line 703, in urlopen
    httplib_response = self._make_request(
  File ""/home/lucas/repos/covid-19-data/venv/lib/python3.10/site-packages/urllib3/connectionpool.py"", line 386, in _make_request
    self._validate_conn(conn)
  File ""/home/lucas/repos/covid-19-data/venv/lib/python3.10/site-packages/urllib3/connectionpool.py"", line 1040, in _validate_conn
    conn.connect()
  File ""/home/lucas/repos/covid-19-data/venv/lib/python3.10/site-packages/urllib3/connection.py"", line 358, in connect
    conn = self._new_conn()
  File ""/home/lucas/repos/covid-19-data/venv/lib/python3.10/site-packages/urllib3/connection.py"", line 179, in _new_conn
    raise ConnectTimeoutError(
urllib3.exceptions.ConnectTimeoutError: (<urllib3.connection.HTTPSConnection object at 0x7f4f22a64970>, 'Connection to covid19asi.saglik.gov.tr timed out. (connect timeout=20)')

During handling of the above exception, another exception occurred:

Traceback (most recent call last):
  File ""/home/lucas/repos/covid-19-data/venv/lib/python3.10/site-packages/requests/adapters.py"", line 440, in send
    resp = conn.urlopen(
  File ""/home/lucas/repos/covid-19-data/venv/lib/python3.10/site-packages/urllib3/connectionpool.py"", line 785, in urlopen
    retries = retries.increment(
  File ""/home/lucas/repos/covid-19-data/venv/lib/python3.10/site-packages/urllib3/util/retry.py"", line 592, in increment
    raise MaxRetryError(_pool, url, error or ResponseError(cause))
urllib3.exceptions.MaxRetryError: HTTPSConnectionPool(host='covid19asi.saglik.gov.tr', port=443): Max retries exceeded with url: / (Caused by ConnectTimeoutError(<urllib3.connection.HTTPSConnection object at 0x7f4f22a64970>, 'Connection to covid19asi.saglik.gov.tr timed out. (connect timeout=20)'))

During handling of the above exception, another exception occurred:

Traceback (most recent call last):
  File ""/home/lucas/repos/covid-19-data/scripts/src/cowidev/cmd/commons/get.py"", line 46, in run
    module.main()
  File ""/home/lucas/repos/covid-19-data/scripts/src/cowidev/vax/incremental/turkey.py"", line 60, in main
    data = read(source).pipe(pipeline)
  File ""/home/lucas/repos/covid-19-data/scripts/src/cowidev/vax/incremental/turkey.py"", line 19, in read
    soup = get_soup(source)
  File ""/home/lucas/repos/covid-19-data/scripts/src/cowidev/utils/web/scraping.py"", line 83, in get_soup
    response = get_response(source, request_method, use_proxy, **kwargs)
  File ""/home/lucas/repos/covid-19-data/scripts/src/cowidev/utils/web/scraping.py"", line 49, in get_response
    raise err
  File ""/home/lucas/repos/covid-19-data/scripts/src/cowidev/utils/web/scraping.py"", line 43, in get_response
    response = requests.get(source, **kwargs)
  File ""/home/lucas/repos/covid-19-data/venv/lib/python3.10/site-packages/requests/api.py"", line 75, in get
    return request('get', url, params=params, **kwargs)
  File ""/home/lucas/repos/covid-19-data/venv/lib/python3.10/site-packages/requests/api.py"", line 61, in request
    return session.request(method=method, url=url, **kwargs)
  File ""/home/lucas/repos/covid-19-data/venv/lib/python3.10/site-packages/requests/sessions.py"", line 529, in request
    resp = self.send(prep, **send_kwargs)
  File ""/home/lucas/repos/covid-19-data/venv/lib/python3.10/site-packages/requests/sessions.py"", line 645, in send
    r = adapter.send(request, **kwargs)
  File ""/home/lucas/repos/covid-19-data/venv/lib/python3.10/site-packages/requests/adapters.py"", line 507, in send
    raise ConnectTimeout(e, request=request)
requests.exceptions.ConnectTimeout: HTTPSConnectionPool(host='covid19asi.saglik.gov.tr', port=443): Max retries exceeded with url: / (Caused by ConnectTimeoutError(<urllib3.connection.HTTPSConnection object at 0x7f4f22a64970>, 'Connection to covid19asi.saglik.gov.tr timed out. (connect timeout=20)'))
","HTTPSConnectionPool(host='covid19asi.saglik.gov.tr', port=443): Max retries exceeded with url: / (Caused by ConnectTimeoutError(<urllib3.connection.HTTPSConnection object at 0x7f4f22a64970>, 'Connection to covid19asi.saglik.gov.tr timed out. (connect timeout=20)'))"
cowidev.vax.incremental.united_arab_emirates,,,2022-11-15T07:02:23,,
cowidev.vax.incremental.vietnam,,,2022-11-15T07:02:23,,
cowidev.vax.incremental.who,4.29,True,2022-11-15T07:02:27,,
cowidev.vax.incremental.zambia,1.21,True,2022-11-15T07:02:25,,
