module,execution_time (sec),success,timestamp,error,error_short
cowidev.vax.batch.argentina,1.85,False,2023-01-15T07:03:17,"Traceback (most recent call last):
  File ""/home/owid/covid-19-data/scripts/src/cowidev/cmd/commons/get.py"", line 46, in run
    module.main()
  File ""/home/owid/covid-19-data/scripts/src/cowidev/vax/batch/argentina.py"", line 228, in main
    Argentina().export()
  File ""/home/owid/covid-19-data/scripts/src/cowidev/vax/batch/argentina.py"", line 204, in export
    df_base = self.read().pipe(self.pipeline_base)
  File ""/home/owid/covid-19-data/scripts/venv/lib/python3.10/site-packages/pandas/core/generic.py"", line 5430, in pipe
    return com.pipe(self, func, *args, **kwargs)
  File ""/home/owid/covid-19-data/scripts/venv/lib/python3.10/site-packages/pandas/core/common.py"", line 471, in pipe
    return func(obj, *args, **kwargs)
  File ""/home/owid/covid-19-data/scripts/src/cowidev/vax/batch/argentina.py"", line 190, in pipeline_base
    return df.pipe(self.pipe_base_vaccines).pipe(self.pipe_base_cumsum).pipe(self.pipe_base_metrics)
  File ""/home/owid/covid-19-data/scripts/venv/lib/python3.10/site-packages/pandas/core/generic.py"", line 5430, in pipe
    return com.pipe(self, func, *args, **kwargs)
  File ""/home/owid/covid-19-data/scripts/venv/lib/python3.10/site-packages/pandas/core/common.py"", line 471, in pipe
    return func(obj, *args, **kwargs)
  File ""/home/owid/covid-19-data/scripts/src/cowidev/vax/batch/argentina.py"", line 88, in pipe_base_vaccines
    raise ValueError(f""Unknown vaccines detected! {vaccines_wrong}"")
ValueError: Unknown vaccines detected! {'Moderna 010 mg mL', 'Moderna ARNm 020 mg mL'}
","Unknown vaccines detected! {'Moderna 010 mg mL', 'Moderna ARNm 020 mg mL'}"
cowidev.vax.batch.australia,89.87,True,2023-01-15T07:01:35,,
cowidev.vax.batch.austria,18.41,True,2023-01-15T07:00:24,,
cowidev.vax.batch.belgium,3.78,True,2023-01-15T07:00:09,,
cowidev.vax.batch.bolivia,3.75,True,2023-01-15T07:00:09,,
cowidev.vax.batch.canada,5.85,False,2023-01-15T07:03:23,"Traceback (most recent call last):
  File ""/home/owid/covid-19-data/scripts/src/cowidev/cmd/commons/get.py"", line 46, in run
    module.main()
  File ""/home/owid/covid-19-data/scripts/src/cowidev/vax/batch/canada.py"", line 289, in main
    Canada().export()
  File ""/home/owid/covid-19-data/scripts/src/cowidev/vax/batch/canada.py"", line 273, in export
    df, df_age, df_man = self.read(), self.read_age(), self.read_manufacturer()
  File ""/home/owid/covid-19-data/scripts/src/cowidev/vax/batch/canada.py"", line 103, in read_age
    check_known_columns(
  File ""/home/owid/covid-19-data/scripts/src/cowidev/utils/utils.py"", line 168, in check_known_columns
    raise Exception(f""Previous column(s) missing: {missing_cols}"")
Exception: Previous column(s) missing: {'Unnamed: 20', 'Unnamed: 22', 'Unnamed: 21', 'Unnamed: 23', 'Unnamed: 19', 'Unnamed: 18', 'Unnamed: 24'}
","Previous column(s) missing: {'Unnamed: 20', 'Unnamed: 22', 'Unnamed: 21', 'Unnamed: 23', 'Unnamed: 19', 'Unnamed: 18', 'Unnamed: 24'}"
cowidev.vax.batch.chile,1.2,True,2023-01-15T07:00:07,,
cowidev.vax.batch.czechia,47.67,True,2023-01-15T07:00:53,,
cowidev.vax.batch.denmark,76.86,True,2023-01-15T07:01:22,,
cowidev.vax.batch.ecdc,3.62,False,2023-01-15T07:03:26,"Traceback (most recent call last):
  File ""/home/owid/covid-19-data/scripts/src/cowidev/cmd/commons/get.py"", line 46, in run
    module.main()
  File ""/home/owid/covid-19-data/scripts/src/cowidev/vax/batch/ecdc.py"", line 507, in main
    ECDC().export()
  File ""/home/owid/covid-19-data/scripts/src/cowidev/vax/batch/ecdc.py"", line 497, in export
    df = self.read().pipe(self.pipe_base)
  File ""/home/owid/covid-19-data/scripts/venv/lib/python3.10/site-packages/pandas/core/generic.py"", line 5430, in pipe
    return com.pipe(self, func, *args, **kwargs)
  File ""/home/owid/covid-19-data/scripts/venv/lib/python3.10/site-packages/pandas/core/common.py"", line 471, in pipe
    return func(obj, *args, **kwargs)
  File ""/home/owid/covid-19-data/scripts/src/cowidev/vax/batch/ecdc.py"", line 148, in pipe_base
    df = df.pipe(self.pipe_initial_check)
  File ""/home/owid/covid-19-data/scripts/venv/lib/python3.10/site-packages/pandas/core/generic.py"", line 5430, in pipe
    return com.pipe(self, func, *args, **kwargs)
  File ""/home/owid/covid-19-data/scripts/venv/lib/python3.10/site-packages/pandas/core/common.py"", line 471, in pipe
    return func(obj, *args, **kwargs)
  File ""/home/owid/covid-19-data/scripts/src/cowidev/vax/batch/ecdc.py"", line 143, in pipe_initial_check
    raise ValueError(f""Unknown vaccines found. Check {vaccines_wrong}"")
ValueError: Unknown vaccines found. Check {'SGSK'}
",Unknown vaccines found. Check {'SGSK'}
cowidev.vax.batch.ecuador,,,2023-01-15T07:00:05,,
cowidev.vax.batch.estonia,0.6,True,2023-01-15T07:00:06,,
cowidev.vax.batch.france,3.87,True,2023-01-15T07:00:09,,
cowidev.vax.batch.germany,0.16,True,2023-01-15T07:00:06,,
cowidev.vax.batch.greece,22.33,True,2023-01-15T07:00:28,,
cowidev.vax.batch.hong_kong,22.88,True,2023-01-15T07:00:28,,
cowidev.vax.batch.indonesia,,,2023-01-15T07:00:05,,
cowidev.vax.batch.ireland,3.51,True,2023-01-15T07:00:09,,
cowidev.vax.batch.israel,16.06,True,2023-01-15T07:00:21,,
cowidev.vax.batch.italy,41.45,True,2023-01-15T07:00:47,,
cowidev.vax.batch.japan,55.52,True,2023-01-15T07:01:01,,
cowidev.vax.batch.jersey,3.39,True,2023-01-15T07:00:09,,
cowidev.vax.batch.latvia,62.04,True,2023-01-15T07:01:07,,
cowidev.vax.batch.lithuania,6.12,True,2023-01-15T07:00:11,,
cowidev.vax.batch.luxembourg,1.85,True,2023-01-15T07:00:07,,
cowidev.vax.batch.malaysia,0.96,True,2023-01-15T07:00:06,,
cowidev.vax.batch.malta,1.11,True,2023-01-15T07:00:06,,
cowidev.vax.batch.netherlands,,,2023-01-15T07:00:05,,
cowidev.vax.batch.new_zealand,17.19,True,2023-01-15T07:00:23,,
cowidev.vax.batch.norway,0.94,True,2023-01-15T07:00:06,,
cowidev.vax.batch.peru,3.2,True,2023-01-15T07:00:09,,
cowidev.vax.batch.portugal,,,2023-01-15T07:00:05,,
cowidev.vax.batch.romania,59.43,True,2023-01-15T07:01:05,,
cowidev.vax.batch.saudi_arabia,3.06,True,2023-01-15T07:00:08,,
cowidev.vax.batch.singapore,3.77,True,2023-01-15T07:00:09,,
cowidev.vax.batch.slovakia,74.73,True,2023-01-15T07:01:20,,
cowidev.vax.batch.slovenia,2.05,True,2023-01-15T07:00:08,,
cowidev.vax.batch.south_korea,87.26,True,2023-01-15T07:01:34,,
cowidev.vax.batch.spc,35.13,True,2023-01-15T07:00:41,,
cowidev.vax.batch.sweden,20.64,True,2023-01-15T07:00:27,,
cowidev.vax.batch.switzerland,90.2,True,2023-01-15T07:01:37,,
cowidev.vax.batch.trinidad_and_tobago,3.96,True,2023-01-15T07:00:11,,
cowidev.vax.batch.ukraine,,,2023-01-15T07:00:08,,
cowidev.vax.batch.united_kingdom,18.7,True,2023-01-15T07:00:27,,
cowidev.vax.batch.united_states,89.23,True,2023-01-15T07:01:38,,
cowidev.vax.batch.uruguay,1.52,False,2023-01-15T07:03:28,"Traceback (most recent call last):
  File ""/home/owid/covid-19-data/scripts/src/cowidev/cmd/commons/get.py"", line 46, in run
    module.main()
  File ""/home/owid/covid-19-data/scripts/src/cowidev/vax/batch/uruguay.py"", line 147, in main
    Uruguay().export()
  File ""/home/owid/covid-19-data/scripts/src/cowidev/vax/batch/uruguay.py"", line 125, in export
    df = df_base.pipe(self.pipeline)
  File ""/home/owid/covid-19-data/scripts/venv/lib/python3.10/site-packages/pandas/core/generic.py"", line 5430, in pipe
    return com.pipe(self, func, *args, **kwargs)
  File ""/home/owid/covid-19-data/scripts/venv/lib/python3.10/site-packages/pandas/core/common.py"", line 471, in pipe
    return func(obj, *args, **kwargs)
  File ""/home/owid/covid-19-data/scripts/src/cowidev/vax/batch/uruguay.py"", line 47, in pipeline
    df = df.pipe(self.make_monotonic)
  File ""/home/owid/covid-19-data/scripts/venv/lib/python3.10/site-packages/pandas/core/generic.py"", line 5430, in pipe
    return com.pipe(self, func, *args, **kwargs)
  File ""/home/owid/covid-19-data/scripts/venv/lib/python3.10/site-packages/pandas/core/common.py"", line 471, in pipe
    return func(obj, *args, **kwargs)
  File ""/home/owid/covid-19-data/scripts/src/cowidev/vax/utils/base.py"", line 120, in make_monotonic
    return mkm(
  File ""/home/owid/covid-19-data/scripts/src/cowidev/utils/utils.py"", line 23, in make_monotonic
    return make_monotonic_new(df, column_date, column_metrics, max_removed_rows)
  File ""/home/owid/covid-19-data/scripts/src/cowidev/utils/utils.py"", line 94, in make_monotonic_new
    raise Exception(
Exception: 1 chunks of lengths 487 have been NaNed for metric total_vaccinations. That is more than maximum allowed (10) by make_monotonic() - check the data. Check dates ['2023-01-08']
",1 chunks of lengths 487 have been NaNed for metric total_vaccinations. That is more than maximum allowed (10) by make_monotonic() - check the data. Check dates ['2023-01-08']
cowidev.vax.batch.zimbabwe,2.84,True,2023-01-15T07:00:12,,
cowidev.vax.incremental.africacdc,,,2023-01-15T07:00:09,,
cowidev.vax.incremental.antigua_barbuda,,,2023-01-15T07:00:09,,
cowidev.vax.incremental.aruba,1.1,True,2023-01-15T07:00:10,,
cowidev.vax.incremental.azerbaijan,,,2023-01-15T07:00:09,,
cowidev.vax.incremental.bahrain,,,2023-01-15T07:00:09,,
cowidev.vax.incremental.bangladesh,41.84,True,2023-01-15T07:00:51,,
cowidev.vax.incremental.barbados,,,2023-01-15T07:00:09,,
cowidev.vax.incremental.brazil,0.66,True,2023-01-15T07:00:10,,
cowidev.vax.incremental.bulgaria,15.02,True,2023-01-15T07:00:24,,
cowidev.vax.incremental.china,26.23,True,2023-01-15T07:00:35,,
cowidev.vax.incremental.costa_rica,,,2023-01-15T07:00:10,,
cowidev.vax.incremental.croatia,1.63,True,2023-01-15T07:00:11,,
cowidev.vax.incremental.cuba,15.95,True,2023-01-15T07:00:26,,
cowidev.vax.incremental.curacao,1.14,True,2023-01-15T07:00:12,,
cowidev.vax.incremental.cyprus,4.64,True,2023-01-15T07:00:16,,
cowidev.vax.incremental.dominican_republic,22.6,False,2023-01-15T07:03:51,"Traceback (most recent call last):
  File ""/home/owid/covid-19-data/scripts/src/cowidev/cmd/commons/get.py"", line 46, in run
    module.main()
  File ""/home/owid/covid-19-data/scripts/src/cowidev/vax/incremental/dominican_republic.py"", line 113, in main
    DominicanRepublic().export()
  File ""/home/owid/covid-19-data/scripts/src/cowidev/vax/incremental/dominican_republic.py"", line 68, in export
    data = self.read().pipe(self.pipeline)
  File ""/home/owid/covid-19-data/scripts/src/cowidev/vax/incremental/dominican_republic.py"", line 26, in read
    metrics = self._parse_metrics(driver)
  File ""/home/owid/covid-19-data/scripts/src/cowidev/vax/incremental/dominican_republic.py"", line 35, in _parse_metrics
    metric_candidates = _find_potential_metrics(driver)
  File ""/home/owid/covid-19-data/scripts/src/cowidev/vax/incremental/dominican_republic.py"", line 92, in _find_potential_metrics
    h3 = _find_h3(driver)
  File ""/home/owid/covid-19-data/scripts/src/cowidev/vax/incremental/dominican_republic.py"", line 82, in _find_h3
    raise ValueError(""More than one element found!"")
ValueError: More than one element found!
",More than one element found!
cowidev.vax.incremental.el_salvador,15.96,True,2023-01-15T07:00:27,,
cowidev.vax.incremental.faeroe_islands,1.55,True,2023-01-15T07:00:13,,
cowidev.vax.incremental.fiji,0.0,True,2023-01-15T07:00:12,,
cowidev.vax.incremental.finland,0.93,True,2023-01-15T07:00:13,,
cowidev.vax.incremental.gabon,,,2023-01-15T07:00:13,,
cowidev.vax.incremental.georgia,10.74,True,2023-01-15T07:00:24,,
cowidev.vax.incremental.greenland,0.17,False,2023-01-15T07:03:51,"Traceback (most recent call last):
  File ""/home/owid/covid-19-data/scripts/src/cowidev/cmd/commons/get.py"", line 46, in run
    module.main()
  File ""/home/owid/covid-19-data/scripts/src/cowidev/vax/incremental/greenland.py"", line 76, in main
    Greenland().export()
  File ""/home/owid/covid-19-data/scripts/src/cowidev/vax/incremental/greenland.py"", line 63, in export
    data = self.read().pipe(self.pipeline)
  File ""/home/owid/covid-19-data/scripts/src/cowidev/vax/incremental/greenland.py"", line 17, in read
    data = self._parse_data(soup)
  File ""/home/owid/covid-19-data/scripts/src/cowidev/vax/incremental/greenland.py"", line 21, in _parse_data
    return {**self._parse_data_metrics(soup), **self._parse_data_date(soup)}
  File ""/home/owid/covid-19-data/scripts/src/cowidev/vax/incremental/greenland.py"", line 31, in _parse_data_metrics
    assert len(counter_1) == len(counter_2) == 1
AssertionError
",
cowidev.vax.incremental.guatemala,,,2023-01-15T07:00:16,,
cowidev.vax.incremental.guernsey,11.33,True,2023-01-15T07:00:27,,
cowidev.vax.incremental.hungary,77.26,True,2023-01-15T07:01:38,,
cowidev.vax.incremental.iceland,3.91,True,2023-01-15T07:00:25,,
cowidev.vax.incremental.india,3.18,True,2023-01-15T07:00:25,,
cowidev.vax.incremental.iran,,,2023-01-15T07:00:23,,
cowidev.vax.incremental.isle_of_man,2.12,True,2023-01-15T07:00:25,,
cowidev.vax.incremental.jamaica,9.56,True,2023-01-15T07:00:33,,
cowidev.vax.incremental.kazakhstan,6.73,True,2023-01-15T07:00:31,,
cowidev.vax.incremental.kosovo,5.82,True,2023-01-15T07:00:30,,
cowidev.vax.incremental.kyrgyzstan,4.08,True,2023-01-15T07:00:29,,
cowidev.vax.incremental.laos,10.91,True,2023-01-15T07:00:36,,
cowidev.vax.incremental.macao,13.16,True,2023-01-15T07:00:39,,
cowidev.vax.incremental.moldova,,,2023-01-15T07:00:26,,
cowidev.vax.incremental.monaco,83.26,True,2023-01-15T07:01:49,,
cowidev.vax.incremental.mongolia,2.45,True,2023-01-15T07:00:29,,
cowidev.vax.incremental.montenegro,1.77,True,2023-01-15T07:00:29,,
cowidev.vax.incremental.morocco,,,2023-01-15T07:00:27,,
cowidev.vax.incremental.myanmar,,,2023-01-15T07:00:27,,
cowidev.vax.incremental.nepal,,,2023-01-15T07:00:27,,
cowidev.vax.incremental.north_macedonia,,,2023-01-15T07:00:27,,
cowidev.vax.incremental.northern_cyprus,17.92,False,2023-01-15T07:04:09,"Traceback (most recent call last):
  File ""/home/owid/covid-19-data/scripts/src/cowidev/cmd/commons/get.py"", line 46, in run
    module.main()
  File ""/home/owid/covid-19-data/scripts/src/cowidev/vax/incremental/northern_cyprus.py"", line 72, in main
    data = read(source).pipe(pipeline, source)
  File ""/home/owid/covid-19-data/scripts/src/cowidev/vax/incremental/northern_cyprus.py"", line 14, in read
    return parse_data(soup)
  File ""/home/owid/covid-19-data/scripts/src/cowidev/vax/incremental/northern_cyprus.py"", line 21, in parse_data
    date = re.search(r""[\d\.]{10}"", soup.find(class_=""counter"").text).group(0)
AttributeError: 'NoneType' object has no attribute 'text'
",'NoneType' object has no attribute 'text'
cowidev.vax.incremental.paho,137.17,False,2023-01-15T07:06:26,"Traceback (most recent call last):
  File ""/home/owid/covid-19-data/scripts/src/cowidev/cmd/commons/get.py"", line 46, in run
    module.main()
  File ""/home/owid/covid-19-data/scripts/src/cowidev/vax/incremental/paho.py"", line 195, in main
    PAHO().export()
  File ""/home/owid/covid-19-data/scripts/src/cowidev/vax/incremental/paho.py"", line 190, in export
    df = self.read().pipe(self.pipeline)
  File ""/home/owid/covid-19-data/scripts/src/cowidev/vax/incremental/paho.py"", line 37, in read
    df = self._parse_data(url)
  File ""/home/owid/covid-19-data/scripts/src/cowidev/vax/incremental/paho.py"", line 64, in _parse_data
    filename = self._get_downloaded_filename()
  File ""/home/owid/covid-19-data/scripts/src/cowidev/vax/incremental/paho.py"", line 116, in _get_downloaded_filename
    return max(files, key=os.path.getctime)
ValueError: max() arg is an empty sequence
",max() arg is an empty sequence
cowidev.vax.incremental.pakistan,,,2023-01-15T07:00:28,,
cowidev.vax.incremental.philippines,,,2023-01-15T07:00:28,,
cowidev.vax.incremental.poland,1.87,True,2023-01-15T07:00:30,,
cowidev.vax.incremental.qatar,,,2023-01-15T07:00:28,,
cowidev.vax.incremental.russia,44.96,True,2023-01-15T07:01:13,,
cowidev.vax.incremental.saint_lucia,,,2023-01-15T07:00:29,,
cowidev.vax.incremental.serbia,15.77,True,2023-01-15T07:00:45,,
cowidev.vax.incremental.south_africa,,,2023-01-15T07:00:29,,
cowidev.vax.incremental.spain,15.3,True,2023-01-15T07:00:44,,
cowidev.vax.incremental.sri_lanka,,,2023-01-15T07:00:29,,
cowidev.vax.incremental.suriname,15.99,True,2023-01-15T07:00:45,,
cowidev.vax.incremental.taiwan,26.66,True,2023-01-15T07:00:56,,
cowidev.vax.incremental.thailand,8.94,True,2023-01-15T07:00:39,,
cowidev.vax.incremental.turkey,40.07,False,2023-01-15T07:07:06,"Traceback (most recent call last):
  File ""/home/owid/covid-19-data/scripts/venv/lib/python3.10/site-packages/urllib3/connection.py"", line 174, in _new_conn
    conn = connection.create_connection(
  File ""/home/owid/covid-19-data/scripts/venv/lib/python3.10/site-packages/urllib3/util/connection.py"", line 95, in create_connection
    raise err
  File ""/home/owid/covid-19-data/scripts/venv/lib/python3.10/site-packages/urllib3/util/connection.py"", line 85, in create_connection
    sock.connect(sa)
TimeoutError: timed out

During handling of the above exception, another exception occurred:

Traceback (most recent call last):
  File ""/home/owid/covid-19-data/scripts/venv/lib/python3.10/site-packages/urllib3/connectionpool.py"", line 703, in urlopen
    httplib_response = self._make_request(
  File ""/home/owid/covid-19-data/scripts/venv/lib/python3.10/site-packages/urllib3/connectionpool.py"", line 386, in _make_request
    self._validate_conn(conn)
  File ""/home/owid/covid-19-data/scripts/venv/lib/python3.10/site-packages/urllib3/connectionpool.py"", line 1042, in _validate_conn
    conn.connect()
  File ""/home/owid/covid-19-data/scripts/venv/lib/python3.10/site-packages/urllib3/connection.py"", line 358, in connect
    self.sock = conn = self._new_conn()
  File ""/home/owid/covid-19-data/scripts/venv/lib/python3.10/site-packages/urllib3/connection.py"", line 179, in _new_conn
    raise ConnectTimeoutError(
urllib3.exceptions.ConnectTimeoutError: (<urllib3.connection.HTTPSConnection object at 0x7fb07be8ded0>, 'Connection to covid19asi.saglik.gov.tr timed out. (connect timeout=20)')

During handling of the above exception, another exception occurred:

Traceback (most recent call last):
  File ""/home/owid/covid-19-data/scripts/venv/lib/python3.10/site-packages/requests/adapters.py"", line 440, in send
    resp = conn.urlopen(
  File ""/home/owid/covid-19-data/scripts/venv/lib/python3.10/site-packages/urllib3/connectionpool.py"", line 787, in urlopen
    retries = retries.increment(
  File ""/home/owid/covid-19-data/scripts/venv/lib/python3.10/site-packages/urllib3/util/retry.py"", line 592, in increment
    raise MaxRetryError(_pool, url, error or ResponseError(cause))
urllib3.exceptions.MaxRetryError: HTTPSConnectionPool(host='covid19asi.saglik.gov.tr', port=443): Max retries exceeded with url: / (Caused by ConnectTimeoutError(<urllib3.connection.HTTPSConnection object at 0x7fb07be8ded0>, 'Connection to covid19asi.saglik.gov.tr timed out. (connect timeout=20)'))

During handling of the above exception, another exception occurred:

Traceback (most recent call last):
  File ""/home/owid/covid-19-data/scripts/src/cowidev/cmd/commons/get.py"", line 46, in run
    module.main()
  File ""/home/owid/covid-19-data/scripts/src/cowidev/vax/incremental/turkey.py"", line 60, in main
    data = read(source).pipe(pipeline)
  File ""/home/owid/covid-19-data/scripts/src/cowidev/vax/incremental/turkey.py"", line 19, in read
    soup = get_soup(source)
  File ""/home/owid/covid-19-data/scripts/src/cowidev/utils/web/scraping.py"", line 83, in get_soup
    response = get_response(source, request_method, use_proxy, **kwargs)
  File ""/home/owid/covid-19-data/scripts/src/cowidev/utils/web/scraping.py"", line 49, in get_response
    raise err
  File ""/home/owid/covid-19-data/scripts/src/cowidev/utils/web/scraping.py"", line 43, in get_response
    response = requests.get(source, **kwargs)
  File ""/home/owid/covid-19-data/scripts/venv/lib/python3.10/site-packages/requests/api.py"", line 75, in get
    return request('get', url, params=params, **kwargs)
  File ""/home/owid/covid-19-data/scripts/venv/lib/python3.10/site-packages/requests/api.py"", line 61, in request
    return session.request(method=method, url=url, **kwargs)
  File ""/home/owid/covid-19-data/scripts/venv/lib/python3.10/site-packages/requests/sessions.py"", line 529, in request
    resp = self.send(prep, **send_kwargs)
  File ""/home/owid/covid-19-data/scripts/venv/lib/python3.10/site-packages/requests/sessions.py"", line 645, in send
    r = adapter.send(request, **kwargs)
  File ""/home/owid/covid-19-data/scripts/venv/lib/python3.10/site-packages/requests/adapters.py"", line 507, in send
    raise ConnectTimeout(e, request=request)
requests.exceptions.ConnectTimeout: HTTPSConnectionPool(host='covid19asi.saglik.gov.tr', port=443): Max retries exceeded with url: / (Caused by ConnectTimeoutError(<urllib3.connection.HTTPSConnection object at 0x7fb07be8ded0>, 'Connection to covid19asi.saglik.gov.tr timed out. (connect timeout=20)'))
","HTTPSConnectionPool(host='covid19asi.saglik.gov.tr', port=443): Max retries exceeded with url: / (Caused by ConnectTimeoutError(<urllib3.connection.HTTPSConnection object at 0x7fb07be8ded0>, 'Connection to covid19asi.saglik.gov.tr timed out. (connect timeout=20)'))"
cowidev.vax.incremental.united_arab_emirates,,,2023-01-15T07:00:33,,
cowidev.vax.incremental.vietnam,,,2023-01-15T07:00:33,,
cowidev.vax.incremental.who,51.81,True,2023-01-15T07:01:25,,
cowidev.vax.incremental.zambia,2.17,True,2023-01-15T07:00:36,,
